{
  "version": 8,
  "blockIdVersion": 11,
  "anchorX": 0,
  "anchorY": 0,
  "anchorZ": 0,
  "blocks": [
    {
      "x": -7,
      "y": 7,
      "z": -3,
      "name": "Rock_Stone_Cobble_Roof_Shallow",
      "rotation": 3
    },
    {
      "x": -7,
      "y": 7,
      "z": -2,
      "name": "Rock_Stone_Cobble_Roof_Shallow",
      "rotation": 3
    },
    {
      "x": -7,
      "y": 7,
      "z": -1,
      "name": "Rock_Stone_Cobble_Roof_Shallow",
      "rotation": 3
    },
    {
      "x": -7,
      "y": 7,
      "z": 0,
      "name": "Rock_Stone_Cobble_Roof_Shallow",
      "rotation": 3
    },
    {
      "x": -7,
      "y": 7,
      "z": 1,
      "name": "Rock_Stone_Cobble_Roof_Shallow",
      "rotation": 3
    },
    {
      "x": -7,
      "y": 7,
      "z": 2,
      "name": "Rock_Stone_Cobble_Roof_Shallow",
      "rotation": 3
    },
    {
      "x": -7,
      "y": 7,
      "z": 3,
      "name": "Rock_Stone_Cobble_Roof_Shallow",
      "rotation": 3
    },
    {
      "x": -6,
      "y": 0,
      "z": -3,
      "name": "Rock_Stone_Brick",
      "rotation": 3
    },
    {
      "x": -6,
      "y": 1,
      "z": -3,
      "name": "Rock_Stone_Brick",
      "rotation": 3
    },
    {
      "x": -6,
      "y": 2,
      "z": -3,
      "name": "Rock_Stone_Cobble_Beam",
      "rotation": 3
    },
    {
      "x": -6,
      "y": 3,
      "z": -3,
      "name": "Wood_Softwood_Beam",
      "rotation": 3
    },
    {
      "x": -6,
      "y": 4,
      "z": -3,
      "name": "Wood_Softwood_Beam",
      "rotation": 3
    },
    {
      "x": -6,
      "y": 5,
      "z": -3,
      "name": "Wood_Softwood_Beam",
      "rotation": 3
    },
    {
      "x": -6,
      "y": 6,
      "z": -3,
      "name": "Wood_Beech_Trunk",
      "support": 15,
      "rotation": 3
    },
    {
      "x": -6,
      "y": 7,
      "z": -3,
      "name": "Rock_Stone_Cobble_Roof_Shallow",
      "filler": 1,
      "rotation": 3
    },
    {
      "x": -6,
      "y": 0,
      "z": -2,
      "name": "Rock_Stone_Brick",
      "rotation": 3
    },
    {
      "x": -6,
      "y": 1,
      "z": -2,
      "name": "Rock_Stone_Brick",
      "rotation": 3
    },
    {
      "x": -6,
      "y": 2,
      "z": -2,
      "name": "Rubble_Stone_Medium",
      "support": 15,
      "rotation": 3
    },
    {
      "x": -6,
      "y": 6,
      "z": -2,
      "name": "Wood_Beech_Branch_Long",
      "support": 15,
      "rotation": 4
    },
    {
      "x": -6,
      "y": 7,
      "z": -2,
      "name": "Rock_Stone_Cobble_Roof_Shallow",
      "filler": 1,
      "rotation": 3
    },
    {
      "x": -6,
      "y": 0,
      "z": -1,
      "name": "Rock_Stone_Brick",
      "rotation": 3
    },
    {
      "x": -6,
      "y": 1,
      "z": -1,
      "name": "Rock_Stone_Brick",
      "rotation": 3
    },
    {
      "x": -6,
      "y": 2,
      "z": -1,
      "name": "Rock_Stone_Brick",
      "rotation": 3
    },
    {
      "x": -6,
      "y": 3,
      "z": -1,
      "name": "Deco_Lantern"
    },
    {
      "x": -6,
      "y": 6,
      "z": -1,
      "name": "Wood_Beech_Branch_Long",
      "support": 15,
      "rotation": 4
    },
    {
      "x": -6,
      "y": 7,
      "z": -1,
      "name": "Rock_Stone_Cobble_Roof_Shallow",
      "filler": 1,
      "rotation": 3
    },
    {
      "x": -6,
      "y": 0,
      "z": 0,
      "name": "Rock_Stone_Brick",
      "rotation": 3
    },
    {
      "x": -6,
      "y": 1,
      "z": 0,
      "name": "Rock_Stone_Brick",
      "rotation": 3
    },
    {
      "x": -6,
      "y": 2,
      "z": 0,
      "name": "Rock_Stone_Brick",
      "rotation": 3
    },
    {
      "x": -6,
      "y": 6,
      "z": 0,
      "name": "Wood_Beech_Branch_Long",
      "support": 15,
      "rotation": 4
    },
    {
      "x": -6,
      "y": 7,
      "z": 0,
      "name": "Rock_Stone_Cobble_Roof_Shallow",
      "filler": 1,
      "rotation": 3
    },
    {
      "x": -6,
      "y": 0,
      "z": 1,
      "name": "Rock_Stone_Brick",
      "rotation": 3
    },
    {
      "x": -6,
      "y": 1,
      "z": 1,
      "name": "Rock_Stone_Brick",
      "rotation": 3
    },
    {
      "x": -6,
      "y": 2,
      "z": 1,
      "name": "Rock_Stone_Brick",
      "rotation": 3
    },
    {
      "x": -6,
      "y": 3,
      "z": 1,
      "name": "Rock_Stone_Brick",
      "rotation": 3
    },
    {
      "x": -6,
      "y": 4,
      "z": 1,
      "name": "Rubble_Stone_Medium",
      "support": 15,
      "rotation": 3
    },
    {
      "x": -6,
      "y": 6,
      "z": 1,
      "name": "Wood_Beech_Branch_Long",
      "support": 15,
      "rotation": 4
    },
    {
      "x": -6,
      "y": 7,
      "z": 1,
      "name": "Rock_Stone_Cobble_Roof_Shallow",
      "filler": 1,
      "rotation": 3
    },
    {
      "x": -6,
      "y": 0,
      "z": 2,
      "name": "Rock_Stone_Brick",
      "rotation": 3
    },
    {
      "x": -6,
      "y": 1,
      "z": 2,
      "name": "Rock_Stone_Brick",
      "rotation": 3
    },
    {
      "x": -6,
      "y": 2,
      "z": 2,
      "name": "Rock_Stone_Brick",
      "rotation": 3
    },
    {
      "x": -6,
      "y": 3,
      "z": 2,
      "name": "Rock_Stone_Brick",
      "rotation": 3
    },
    {
      "x": -6,
      "y": 4,
      "z": 2,
      "name": "Rock_Stone_Brick",
      "rotation": 3
    },
    {
      "x": -6,
      "y": 6,
      "z": 2,
      "name": "Wood_Beech_Branch_Long",
      "support": 15,
      "rotation": 4
    },
    {
      "x": -6,
      "y": 7,
      "z": 2,
      "name": "Rock_Stone_Cobble_Roof_Shallow",
      "filler": 1,
      "rotation": 3
    },
    {
      "x": -6,
      "y": 0,
      "z": 3,
      "name": "Rock_Stone_Brick",
      "rotation": 3
    },
    {
      "x": -6,
      "y": 1,
      "z": 3,
      "name": "Wood_Beech_Trunk",
      "support": 15,
      "rotation": 3
    },
    {
      "x": -6,
      "y": 2,
      "z": 3,
      "name": "Wood_Beech_Trunk",
      "support": 15,
      "rotation": 3
    },
    {
      "x": -6,
      "y": 3,
      "z": 3,
      "name": "Wood_Beech_Trunk",
      "support": 15,
      "rotation": 3
    },
    {
      "x": -6,
      "y": 4,
      "z": 3,
      "name": "Wood_Beech_Trunk",
      "support": 15,
      "rotation": 3
    },
    {
      "x": -6,
      "y": 5,
      "z": 3,
      "name": "Wood_Beech_Trunk",
      "support": 15,
      "rotation": 3
    },
    {
      "x": -6,
      "y": 6,
      "z": 3,
      "name": "Wood_Beech_Trunk",
      "support": 15,
      "rotation": 4
    },
    {
      "x": -6,
      "y": 7,
      "z": 3,
      "name": "Rock_Stone_Cobble_Roof_Shallow",
      "filler": 1,
      "rotation": 3
    },
    {
      "x": -5,
      "y": 0,
      "z": -3,
      "name": "Rock_Stone_Brick",
      "rotation": 3
    },
    {
      "x": -5,
      "y": 6,
      "z": -3,
      "name": "Wood_Beech_Branch_Long",
      "support": 15,
      "rotation": 7
    },
    {
      "x": -5,
      "y": 7,
      "z": -3,
      "name": "Wood_Beech_Trunk",
      "support": 15,
      "rotation": 7
    },
    {
      "x": -5,
      "y": 8,
      "z": -3,
      "name": "Rock_Stone_Cobble_Roof",
      "rotation": 3
    },
    {
      "x": -5,
      "y": 0,
      "z": -2,
      "name": "Soil_Gravel",
      "support": 15,
      "rotation": 3
    },
    {
      "x": -5,
      "y": 1,
      "z": -2,
      "name": "Rubble_Stone_Medium",
      "support": 15,
      "rotation": 3
    },
    {
      "x": -5,
      "y": 7,
      "z": -2,
      "name": "Wood_Beech_Trunk",
      "support": 15,
      "rotation": 4
    },
    {
      "x": -5,
      "y": 8,
      "z": -2,
      "name": "Rock_Stone_Cobble_Roof",
      "rotation": 3
    },
    {
      "x": -5,
      "y": 0,
      "z": -1,
      "name": "Soil_Gravel",
      "support": 15,
      "rotation": 3
    },
    {
      "x": -5,
      "y": 1,
      "z": -1,
      "name": "Rock_Stone_Cobble_Half",
      "rotation": 7
    },
    {
      "x": -5,
      "y": 7,
      "z": -1,
      "name": "Wood_Beech_Trunk",
      "support": 15,
      "rotation": 4
    },
    {
      "x": -5,
      "y": 8,
      "z": -1,
      "name": "Rock_Stone_Cobble_Roof",
      "rotation": 3
    },
    {
      "x": -5,
      "y": 0,
      "z": 0,
      "name": "Soil_Gravel",
      "support": 15,
      "rotation": 3
    },
    {
      "x": -5,
      "y": 1,
      "z": 0,
      "name": "Rock_Stone_Cobble_Half",
      "rotation": 7
    },
    {
      "x": -5,
      "y": 4,
      "z": 0,
      "name": "*Rock_Stone_Cobble_Stairs_State_Definitions_Corner_Left",
      "rotation": 2
    },
    {
      "x": -5,
      "y": 7,
      "z": 0,
      "name": "Wood_Beech_Trunk",
      "support": 15,
      "rotation": 4
    },
    {
      "x": -5,
      "y": 8,
      "z": 0,
      "name": "Rock_Stone_Cobble_Roof",
      "rotation": 3
    },
    {
      "x": -5,
      "y": 0,
      "z": 1,
      "name": "Soil_Gravel",
      "support": 15,
      "rotation": 3
    },
    {
      "x": -5,
      "y": 1,
      "z": 1,
      "name": "Rock_Stone_Cobble",
      "rotation": 3
    },
    {
      "x": -5,
      "y": 2,
      "z": 1,
      "name": "Rock_Stone_Cobble_Half",
      "rotation": 5
    },
    {
      "x": -5,
      "y": 3,
      "z": 1,
      "name": "Rock_Stone_Cobble_Half",
      "rotation": 5
    },
    {
      "x": -5,
      "y": 4,
      "z": 1,
      "name": "Rock_Stone_Cobble_Stairs",
      "rotation": 3
    },
    {
      "x": -5,
      "y": 7,
      "z": 1,
      "name": "Wood_Beech_Trunk",
      "support": 15,
      "rotation": 4
    },
    {
      "x": -5,
      "y": 8,
      "z": 1,
      "name": "Rock_Stone_Cobble_Roof",
      "rotation": 3
    },
    {
      "x": -5,
      "y": 0,
      "z": 2,
      "name": "Soil_Gravel",
      "support": 15,
      "rotation": 3
    },
    {
      "x": -5,
      "y": 1,
      "z": 2,
      "name": "Rock_Stone_Cobble",
      "rotation": 3
    },
    {
      "x": -5,
      "y": 2,
      "z": 2,
      "name": "Rock_Stone_Cobble",
      "rotation": 3
    },
    {
      "x": -5,
      "y": 3,
      "z": 2,
      "name": "Rock_Stone_Cobble",
      "rotation": 3
    },
    {
      "x": -5,
      "y": 4,
      "z": 2,
      "name": "*Rock_Stone_Cobble_Stairs_State_Definitions_Corner_Right"
    },
    {
      "x": -5,
      "y": 7,
      "z": 2,
      "name": "Wood_Beech_Trunk",
      "support": 15,
      "rotation": 4
    },
    {
      "x": -5,
      "y": 8,
      "z": 2,
      "name": "Rock_Stone_Cobble_Roof",
      "rotation": 3
    },
    {
      "x": -5,
      "y": 0,
      "z": 3,
      "name": "Rock_Stone_Brick",
      "rotation": 3
    },
    {
      "x": -5,
      "y": 1,
      "z": 3,
      "name": "*Wood_Village_Wall_Full_State_Definitions_Bottom"
    },
    {
      "x": -5,
      "y": 2,
      "z": 3,
      "name": "*Wood_Village_Wall_Full_State_Definitions_Middle",
      "rotation": 3
    },
    {
      "x": -5,
      "y": 3,
      "z": 3,
      "name": "*Wood_Village_Wall_Full_State_Definitions_Middle",
      "rotation": 3
    },
    {
      "x": -5,
      "y": 4,
      "z": 3,
      "name": "*Wood_Village_Wall_Full_State_Definitions_Middle",
      "rotation": 3
    },
    {
      "x": -5,
      "y": 5,
      "z": 3,
      "name": "*Wood_Village_Wall_Full_State_Definitions_Top",
      "rotation": 3
    },
    {
      "x": -5,
      "y": 6,
      "z": 3,
      "name": "Wood_Beech_Trunk",
      "support": 15,
      "rotation": 7
    },
    {
      "x": -5,
      "y": 7,
      "z": 3,
      "name": "Rock_Stone_Cobble",
      "rotation": 3
    },
    {
      "x": -5,
      "y": 8,
      "z": 3,
      "name": "Rock_Stone_Cobble_Roof",
      "rotation": 3
    },
    {
      "x": -4,
      "y": 0,
      "z": -3,
      "name": "Rock_Stone_Brick",
      "rotation": 3
    },
    {
      "x": -4,
      "y": 6,
      "z": -3,
      "name": "Wood_Beech_Branch_Long",
      "support": 15,
      "rotation": 7
    },
    {
      "x": -4,
      "y": 7,
      "z": -3,
      "name": "Wood_Beech_Trunk",
      "support": 15,
      "rotation": 7
    },
    {
      "x": -4,
      "y": 8,
      "z": -3,
      "name": "Rock_Stone_Cobble",
      "rotation": 3
    },
    {
      "x": -4,
      "y": 9,
      "z": -3,
      "name": "Rock_Stone_Cobble_Roof",
      "rotation": 3
    },
    {
      "x": -4,
      "y": 0,
      "z": -2,
      "name": "Soil_Gravel",
      "support": 15,
      "rotation": 3
    },
    {
      "x": -4,
      "y": 1,
      "z": -2,
      "name": "Rock_Stone_Cobble_Half",
      "rotation": 6
    },
    {
      "x": -4,
      "y": 7,
      "z": -2,
      "name": "Rock_Stone_Cobble",
      "rotation": 3
    },
    {
      "x": -4,
      "y": 8,
      "z": -2,
      "name": "Rock_Stone_Cobble",
      "rotation": 3
    },
    {
      "x": -4,
      "y": 9,
      "z": -2,
      "name": "Rock_Stone_Cobble_Roof",
      "rotation": 3
    },
    {
      "x": -4,
      "y": 0,
      "z": -1,
      "name": "Soil_Gravel",
      "support": 15,
      "rotation": 3
    },
    {
      "x": -4,
      "y": 1,
      "z": -1,
      "name": "Wood_Fire_Trunk_Full",
      "support": 15,
      "rotation": 4
    },
    {
      "x": -4,
      "y": 7,
      "z": -1,
      "name": "Rock_Stone_Cobble",
      "rotation": 3
    },
    {
      "x": -4,
      "y": 8,
      "z": -1,
      "name": "Rock_Stone_Cobble",
      "rotation": 3
    },
    {
      "x": -4,
      "y": 9,
      "z": -1,
      "name": "Rock_Stone_Cobble_Roof",
      "rotation": 3
    },
    {
      "x": -4,
      "y": 0,
      "z": 0,
      "name": "Soil_Gravel",
      "support": 15,
      "rotation": 3
    },
    {
      "x": -4,
      "y": 1,
      "z": 0,
      "name": "Wood_Fire_Trunk_Full",
      "support": 15,
      "rotation": 4
    },
    {
      "x": -4,
      "y": 4,
      "z": 0,
      "name": "Rock_Stone_Cobble_Stairs",
      "rotation": 2
    },
    {
      "x": -4,
      "y": 7,
      "z": 0,
      "name": "Rock_Stone_Cobble",
      "rotation": 3
    },
    {
      "x": -4,
      "y": 8,
      "z": 0,
      "name": "Rock_Stone_Cobble",
      "rotation": 3
    },
    {
      "x": -4,
      "y": 9,
      "z": 0,
      "name": "Rock_Stone_Cobble_Roof",
      "rotation": 3
    },
    {
      "x": -4,
      "y": 0,
      "z": 1,
      "name": "Soil_Gravel",
      "support": 15,
      "rotation": 3
    },
    {
      "x": -4,
      "y": 1,
      "z": 1,
      "name": "Wood_Fire_Trunk_Full",
      "support": 15
    },
    {
      "x": -4,
      "y": 2,
      "z": 1,
      "name": "Bench_Furnace",
      "components": {
        "Components": {
          "processingBench": {
            "Position": {
              "X": 1,
              "Y": 192,
              "Z": 30
            },
            "TierLevel": 1,
            "UpgradeItems": [],
            "InputContainer": {
              "Id": "Simple",
              "Capacity": 2,
              "Items": {}
            },
            "FuelContainer": {
              "Id": "Simple",
              "Capacity": 1,
              "Items": {}
            },
            "OutputContainer": {
              "Id": "Simple",
              "Capacity": 4,
              "Items": {}
            },
            "Progress": 0.0,
            "FuelTime": 0.0,
            "Active": false,
            "NextExtra": 2
          },
          "PlacedByInteraction": {
            "WhoPlacedUuid": {
              "$binary": "LRk7KNJbT1G5snO5bfFgMQ==",
              "$type": "04"
            }
          }
        }
      },
      "rotation": 2
    },
    {
      "x": -4,
      "y": 3,
      "z": 1,
      "name": "Bench_Furnace",
      "filler": 1024,
      "rotation": 2
    },
    {
      "x": -4,
      "y": 4,
      "z": 1,
      "name": "Rock_Stone_Cobble_Half",
      "rotation": 11
    },
    {
      "x": -4,
      "y": 5,
      "z": 1,
      "name": "Rock_Stone_Cobble_Stairs",
      "rotation": 3
    },
    {
      "x": -4,
      "y": 6,
      "z": 1,
      "name": "Rock_Stone_Cobble_Half",
      "rotation": 7
    },
    {
      "x": -4,
      "y": 7,
      "z": 1,
      "name": "Rock_Stone_Cobble_Half",
      "rotation": 7
    },
    {
      "x": -4,
      "y": 8,
      "z": 1,
      "name": "Rock_Stone_Cobble_Half",
      "rotation": 7
    },
    {
      "x": -4,
      "y": 9,
      "z": 1,
      "name": "Rock_Stone_Cobble_Half",
      "rotation": 7
    },
    {
      "x": -4,
      "y": 10,
      "z": 1,
      "name": "Rock_Stone_Cobble_Half",
      "rotation": 7
    },
    {
      "x": -4,
      "y": 11,
      "z": 1,
      "name": "Rock_Stone_Cobble_Half",
      "rotation": 7
    },
    {
      "x": -4,
      "y": 12,
      "z": 1,
      "name": "Rock_Stone_Cobble_Half",
      "rotation": 7
    },
    {
      "x": -4,
      "y": 0,
      "z": 2,
      "name": "Soil_Gravel",
      "support": 15,
      "rotation": 3
    },
    {
      "x": -4,
      "y": 1,
      "z": 2,
      "name": "Rock_Stone_Cobble",
      "rotation": 3
    },
    {
      "x": -4,
      "y": 2,
      "z": 2,
      "name": "Rock_Stone_Cobble",
      "rotation": 3
    },
    {
      "x": -4,
      "y": 3,
      "z": 2,
      "name": "Rock_Stone_Cobble",
      "rotation": 3
    },
    {
      "x": -4,
      "y": 4,
      "z": 2,
      "name": "Rock_Stone_Cobble_Stairs"
    },
    {
      "x": -4,
      "y": 7,
      "z": 2,
      "name": "Rock_Stone_Cobble",
      "rotation": 3
    },
    {
      "x": -4,
      "y": 8,
      "z": 2,
      "name": "Rock_Stone_Cobble_Half",
      "rotation": 7
    },
    {
      "x": -4,
      "y": 9,
      "z": 2,
      "name": "Rock_Stone_Cobble_Roof_Hollow",
      "rotation": 3
    },
    {
      "x": -4,
      "y": 0,
      "z": 3,
      "name": "Rock_Stone_Brick",
      "rotation": 3
    },
    {
      "x": -4,
      "y": 1,
      "z": 3,
      "name": "*Wood_Village_Wall_Full_State_Definitions_Bottom"
    },
    {
      "x": -4,
      "y": 2,
      "z": 3,
      "name": "*Wood_Village_Wall_Full_State_Definitions_Middle",
      "rotation": 3
    },
    {
      "x": -4,
      "y": 3,
      "z": 3,
      "name": "*Wood_Village_Wall_Full_State_Definitions_Middle",
      "rotation": 3
    },
    {
      "x": -4,
      "y": 4,
      "z": 3,
      "name": "*Wood_Village_Wall_Full_State_Definitions_Middle",
      "rotation": 3
    },
    {
      "x": -4,
      "y": 5,
      "z": 3,
      "name": "*Wood_Village_Wall_Full_State_Definitions_Top",
      "rotation": 3
    },
    {
      "x": -4,
      "y": 6,
      "z": 3,
      "name": "Wood_Beech_Trunk",
      "support": 15,
      "rotation": 7
    },
    {
      "x": -4,
      "y": 7,
      "z": 3,
      "name": "Rock_Stone_Cobble",
      "rotation": 3
    },
    {
      "x": -4,
      "y": 8,
      "z": 3,
      "name": "Rock_Stone_Cobble",
      "rotation": 3
    },
    {
      "x": -4,
      "y": 9,
      "z": 3,
      "name": "Rock_Stone_Cobble_Roof",
      "rotation": 3
    },
    {
      "x": -3,
      "y": 0,
      "z": -3,
      "name": "Rock_Stone_Brick",
      "rotation": 3
    },
    {
      "x": -3,
      "y": 6,
      "z": -3,
      "name": "Wood_Beech_Branch_Long",
      "support": 15,
      "rotation": 7
    },
    {
      "x": -3,
      "y": 7,
      "z": -3,
      "name": "Wood_Beech_Trunk",
      "support": 15,
      "rotation": 5
    },
    {
      "x": -3,
      "y": 8,
      "z": -3,
      "name": "Rock_Stone_Cobble"
    },
    {
      "x": -3,
      "y": 9,
      "z": -3,
      "name": "Rock_Stone_Cobble"
    },
    {
      "x": -3,
      "y": 10,
      "z": -3,
      "name": "Rock_Stone_Cobble_Roof",
      "rotation": 3
    },
    {
      "x": -3,
      "y": 0,
      "z": -2,
      "name": "Soil_Gravel",
      "support": 15,
      "rotation": 3
    },
    {
      "x": -3,
      "y": 1,
      "z": -2,
      "name": "Rock_Stone_Cobble_Half",
      "rotation": 6
    },
    {
      "x": -3,
      "y": 7,
      "z": -2,
      "name": "Wood_Beech_Trunk",
      "support": 15,
      "rotation": 4
    },
    {
      "x": -3,
      "y": 8,
      "z": -2,
      "name": "Rock_Stone_Cobble",
      "rotation": 3
    },
    {
      "x": -3,
      "y": 9,
      "z": -2,
      "name": "Rock_Stone_Cobble_Half",
      "rotation": 3
    },
    {
      "x": -3,
      "y": 10,
      "z": -2,
      "name": "Rock_Stone_Cobble_Roof_Hollow",
      "rotation": 3
    },
    {
      "x": -3,
      "y": 0,
      "z": -1,
      "name": "Soil_Gravel",
      "support": 15,
      "rotation": 3
    },
    {
      "x": -3,
      "y": 1,
      "z": -1,
      "name": "Wood_Fire_Trunk_Full",
      "support": 15,
      "rotation": 4
    },
    {
      "x": -3,
      "y": 7,
      "z": -1,
      "name": "Wood_Beech_Trunk",
      "support": 15,
      "rotation": 4
    },
    {
      "x": -3,
      "y": 8,
      "z": -1,
      "name": "Rock_Stone_Cobble",
      "rotation": 3
    },
    {
      "x": -3,
      "y": 9,
      "z": -1,
      "name": "Rock_Stone_Cobble_Half",
      "rotation": 3
    },
    {
      "x": -3,
      "y": 10,
      "z": -1,
      "name": "Rock_Stone_Cobble_Roof_Hollow",
      "rotation": 3
    },
    {
      "x": -3,
      "y": 0,
      "z": 0,
      "name": "Soil_Gravel",
      "support": 15,
      "rotation": 3
    },
    {
      "x": -3,
      "y": 1,
      "z": 0,
      "name": "Wood_Fire_Trunk_Full",
      "support": 15,
      "rotation": 4
    },
    {
      "x": -3,
      "y": 4,
      "z": 0,
      "name": "Rock_Stone_Cobble_Stairs",
      "rotation": 2
    },
    {
      "x": -3,
      "y": 7,
      "z": 0,
      "name": "Wood_Beech_Trunk",
      "support": 15,
      "rotation": 4
    },
    {
      "x": -3,
      "y": 8,
      "z": 0,
      "name": "Rock_Stone_Cobble",
      "rotation": 3
    },
    {
      "x": -3,
      "y": 9,
      "z": 0,
      "name": "Rock_Stone_Cobble",
      "rotation": 3
    },
    {
      "x": -3,
      "y": 10,
      "z": 0,
      "name": "Rock_Stone_Cobble_Roof",
      "rotation": 3
    },
    {
      "x": -3,
      "y": 0,
      "z": 1,
      "name": "Soil_Gravel",
      "support": 15,
      "rotation": 3
    },
    {
      "x": -3,
      "y": 1,
      "z": 1,
      "name": "Wood_Fire_Trunk_Full",
      "support": 15
    },
    {
      "x": -3,
      "y": 2,
      "z": 1,
      "name": "Bench_Furnace",
      "filler": 1,
      "rotation": 2
    },
    {
      "x": -3,
      "y": 3,
      "z": 1,
      "name": "Bench_Furnace",
      "filler": 1025,
      "rotation": 2
    },
    {
      "x": -3,
      "y": 4,
      "z": 1,
      "name": "Rock_Stone_Cobble_Half",
      "rotation": 11
    },
    {
      "x": -3,
      "y": 5,
      "z": 1,
      "name": "Rock_Stone_Cobble_Stairs",
      "rotation": 1
    },
    {
      "x": -3,
      "y": 6,
      "z": 1,
      "name": "Rock_Stone_Cobble_Half",
      "rotation": 5
    },
    {
      "x": -3,
      "y": 7,
      "z": 1,
      "name": "Rock_Stone_Cobble_Half",
      "rotation": 5
    },
    {
      "x": -3,
      "y": 8,
      "z": 1,
      "name": "Rock_Stone_Cobble_Half",
      "rotation": 5
    },
    {
      "x": -3,
      "y": 9,
      "z": 1,
      "name": "Rock_Stone_Cobble",
      "rotation": 3
    },
    {
      "x": -3,
      "y": 10,
      "z": 1,
      "name": "Rock_Stone_Cobble_Half",
      "rotation": 5
    },
    {
      "x": -3,
      "y": 11,
      "z": 1,
      "name": "Rock_Stone_Cobble_Half",
      "rotation": 5
    },
    {
      "x": -3,
      "y": 12,
      "z": 1,
      "name": "Rock_Stone_Cobble_Half",
      "rotation": 5
    },
    {
      "x": -3,
      "y": 0,
      "z": 2,
      "name": "Soil_Gravel",
      "support": 15,
      "rotation": 3
    },
    {
      "x": -3,
      "y": 1,
      "z": 2,
      "name": "Rock_Stone_Cobble",
      "rotation": 3
    },
    {
      "x": -3,
      "y": 2,
      "z": 2,
      "name": "Rock_Stone_Cobble",
      "rotation": 3
    },
    {
      "x": -3,
      "y": 3,
      "z": 2,
      "name": "Rock_Stone_Cobble",
      "rotation": 3
    },
    {
      "x": -3,
      "y": 4,
      "z": 2,
      "name": "Rock_Stone_Cobble_Stairs"
    },
    {
      "x": -3,
      "y": 7,
      "z": 2,
      "name": "Wood_Beech_Trunk",
      "support": 15,
      "rotation": 4
    },
    {
      "x": -3,
      "y": 8,
      "z": 2,
      "name": "Rock_Stone_Cobble_Half",
      "rotation": 5
    },
    {
      "x": -3,
      "y": 9,
      "z": 2,
      "name": "Rock_Stone_Cobble_Half",
      "rotation": 3
    },
    {
      "x": -3,
      "y": 10,
      "z": 2,
      "name": "Rock_Stone_Cobble_Roof_Hollow",
      "rotation": 3
    },
    {
      "x": -3,
      "y": 0,
      "z": 3,
      "name": "Rock_Stone_Brick",
      "rotation": 3
    },
    {
      "x": -3,
      "y": 1,
      "z": 3,
      "name": "Wood_Beech_Trunk",
      "support": 15
    },
    {
      "x": -3,
      "y": 2,
      "z": 3,
      "name": "Wood_Beech_Trunk",
      "support": 15
    },
    {
      "x": -3,
      "y": 3,
      "z": 3,
      "name": "Wood_Beech_Trunk",
      "support": 15
    },
    {
      "x": -3,
      "y": 4,
      "z": 3,
      "name": "Wood_Beech_Trunk",
      "support": 15
    },
    {
      "x": -3,
      "y": 5,
      "z": 3,
      "name": "Wood_Beech_Trunk",
      "support": 15
    },
    {
      "x": -3,
      "y": 6,
      "z": 3,
      "name": "Wood_Beech_Trunk",
      "support": 15,
      "rotation": 7
    },
    {
      "x": -3,
      "y": 7,
      "z": 3,
      "name": "Rock_Stone_Cobble"
    },
    {
      "x": -3,
      "y": 8,
      "z": 3,
      "name": "Rock_Stone_Cobble",
      "rotation": 3
    },
    {
      "x": -3,
      "y": 9,
      "z": 3,
      "name": "Rock_Stone_Cobble",
      "rotation": 3
    },
    {
      "x": -3,
      "y": 10,
      "z": 3,
      "name": "Rock_Stone_Cobble_Roof",
      "rotation": 3
    },
    {
      "x": -2,
      "y": 0,
      "z": -3,
      "name": "Rock_Stone_Brick",
      "rotation": 3
    },
    {
      "x": -2,
      "y": 6,
      "z": -3,
      "name": "Wood_Beech_Branch_Long",
      "support": 15,
      "rotation": 7
    },
    {
      "x": -2,
      "y": 7,
      "z": -3,
      "name": "Wood_Beech_Trunk",
      "support": 15,
      "rotation": 7
    },
    {
      "x": -2,
      "y": 8,
      "z": -3,
      "name": "Furniture_Tavern_Window"
    },
    {
      "x": -2,
      "y": 9,
      "z": -3,
      "name": "Rock_Stone_Cobble"
    },
    {
      "x": -2,
      "y": 10,
      "z": -3,
      "name": "Rock_Stone_Cobble"
    },
    {
      "x": -2,
      "y": 11,
      "z": -3,
      "name": "Rock_Stone_Cobble_Roof_Flat",
      "rotation": 1
    },
    {
      "x": -2,
      "y": 0,
      "z": -2,
      "name": "Soil_Gravel",
      "support": 15,
      "rotation": 3
    },
    {
      "x": -2,
      "y": 7,
      "z": -2,
      "name": "Rock_Stone_Cobble",
      "rotation": 3
    },
    {
      "x": -2,
      "y": 8,
      "z": -2,
      "name": "Rock_Stone_Cobble",
      "rotation": 3
    },
    {
      "x": -2,
      "y": 9,
      "z": -2,
      "name": "Rock_Stone_Cobble",
      "rotation": 3
    },
    {
      "x": -2,
      "y": 10,
      "z": -2,
      "name": "Rock_Stone_Cobble"
    },
    {
      "x": -2,
      "y": 11,
      "z": -2,
      "name": "Rock_Stone_Cobble_Roof_Flat",
      "rotation": 1
    },
    {
      "x": -2,
      "y": 0,
      "z": -1,
      "name": "Soil_Gravel",
      "support": 15,
      "rotation": 3
    },
    {
      "x": -2,
      "y": 1,
      "z": -1,
      "name": "Rock_Stone_Cobble_Half",
      "rotation": 5
    },
    {
      "x": -2,
      "y": 7,
      "z": -1,
      "name": "Rock_Stone_Cobble",
      "rotation": 3
    },
    {
      "x": -2,
      "y": 8,
      "z": -1,
      "name": "Rock_Stone_Cobble",
      "rotation": 3
    },
    {
      "x": -2,
      "y": 9,
      "z": -1,
      "name": "Rock_Stone_Cobble",
      "rotation": 3
    },
    {
      "x": -2,
      "y": 10,
      "z": -1,
      "name": "Rock_Stone_Cobble"
    },
    {
      "x": -2,
      "y": 11,
      "z": -1,
      "name": "Rock_Stone_Cobble_Roof_Flat",
      "rotation": 1
    },
    {
      "x": -2,
      "y": 0,
      "z": 0,
      "name": "Soil_Gravel",
      "support": 15,
      "rotation": 3
    },
    {
      "x": -2,
      "y": 1,
      "z": 0,
      "name": "Rock_Stone_Cobble_Half",
      "rotation": 5
    },
    {
      "x": -2,
      "y": 4,
      "z": 0,
      "name": "*Rock_Stone_Cobble_Stairs_State_Definitions_Corner_Left",
      "rotation": 1
    },
    {
      "x": -2,
      "y": 7,
      "z": 0,
      "name": "Rock_Stone_Cobble",
      "rotation": 3
    },
    {
      "x": -2,
      "y": 8,
      "z": 0,
      "name": "Rock_Stone_Cobble",
      "rotation": 3
    },
    {
      "x": -2,
      "y": 9,
      "z": 0,
      "name": "Rock_Stone_Cobble"
    },
    {
      "x": -2,
      "y": 10,
      "z": 0,
      "name": "Rock_Stone_Cobble"
    },
    {
      "x": -2,
      "y": 11,
      "z": 0,
      "name": "Rock_Stone_Cobble_Roof_Flat",
      "rotation": 1
    },
    {
      "x": -2,
      "y": 0,
      "z": 1,
      "name": "Soil_Gravel",
      "support": 15,
      "rotation": 3
    },
    {
      "x": -2,
      "y": 1,
      "z": 1,
      "name": "Rock_Stone_Cobble",
      "rotation": 3
    },
    {
      "x": -2,
      "y": 2,
      "z": 1,
      "name": "Rock_Stone_Cobble_Half",
      "rotation": 7
    },
    {
      "x": -2,
      "y": 3,
      "z": 1,
      "name": "Rock_Stone_Cobble_Half",
      "rotation": 7
    },
    {
      "x": -2,
      "y": 4,
      "z": 1,
      "name": "Rock_Stone_Cobble_Stairs",
      "rotation": 1
    },
    {
      "x": -2,
      "y": 7,
      "z": 1,
      "name": "Rock_Stone_Cobble",
      "rotation": 3
    },
    {
      "x": -2,
      "y": 8,
      "z": 1,
      "name": "Rock_Stone_Cobble",
      "rotation": 3
    },
    {
      "x": -2,
      "y": 9,
      "z": 1,
      "name": "Rock_Stone_Cobble"
    },
    {
      "x": -2,
      "y": 10,
      "z": 1,
      "name": "Rock_Stone_Cobble"
    },
    {
      "x": -2,
      "y": 11,
      "z": 1,
      "name": "Rock_Stone_Cobble_Roof_Flat",
      "rotation": 1
    },
    {
      "x": -2,
      "y": 0,
      "z": 2,
      "name": "Soil_Gravel",
      "support": 15,
      "rotation": 3
    },
    {
      "x": -2,
      "y": 1,
      "z": 2,
      "name": "Rock_Stone_Cobble",
      "rotation": 3
    },
    {
      "x": -2,
      "y": 2,
      "z": 2,
      "name": "Rock_Stone_Cobble",
      "rotation": 3
    },
    {
      "x": -2,
      "y": 3,
      "z": 2,
      "name": "Rock_Stone_Cobble",
      "rotation": 3
    },
    {
      "x": -2,
      "y": 4,
      "z": 2,
      "name": "*Rock_Stone_Cobble_Stairs_State_Definitions_Corner_Left"
    },
    {
      "x": -2,
      "y": 7,
      "z": 2,
      "name": "Rock_Stone_Cobble",
      "rotation": 3
    },
    {
      "x": -2,
      "y": 8,
      "z": 2,
      "name": "Rock_Stone_Cobble",
      "rotation": 3
    },
    {
      "x": -2,
      "y": 9,
      "z": 2,
      "name": "Rock_Stone_Cobble"
    },
    {
      "x": -2,
      "y": 10,
      "z": 2,
      "name": "Rock_Stone_Cobble"
    },
    {
      "x": -2,
      "y": 11,
      "z": 2,
      "name": "Rock_Stone_Cobble_Roof_Flat",
      "rotation": 1
    },
    {
      "x": -2,
      "y": 0,
      "z": 3,
      "name": "Rock_Stone_Brick",
      "rotation": 3
    },
    {
      "x": -2,
      "y": 1,
      "z": 3,
      "name": "*Wood_Village_Wall_Full_State_Definitions_Bottom"
    },
    {
      "x": -2,
      "y": 2,
      "z": 3,
      "name": "*Wood_Village_Wall_Full_State_Definitions_Middle",
      "rotation": 3
    },
    {
      "x": -2,
      "y": 3,
      "z": 3,
      "name": "*Wood_Village_Wall_Full_State_Definitions_Middle",
      "rotation": 3
    },
    {
      "x": -2,
      "y": 4,
      "z": 3,
      "name": "*Wood_Village_Wall_Full_State_Definitions_Middle",
      "rotation": 3
    },
    {
      "x": -2,
      "y": 5,
      "z": 3,
      "name": "*Wood_Village_Wall_Full_State_Definitions_Top",
      "rotation": 3
    },
    {
      "x": -2,
      "y": 6,
      "z": 3,
      "name": "Wood_Beech_Trunk",
      "support": 15,
      "rotation": 7
    },
    {
      "x": -2,
      "y": 7,
      "z": 3,
      "name": "Rock_Stone_Cobble",
      "rotation": 3
    },
    {
      "x": -2,
      "y": 8,
      "z": 3,
      "name": "Rock_Stone_Cobble",
      "rotation": 3
    },
    {
      "x": -2,
      "y": 9,
      "z": 3,
      "name": "Rock_Stone_Cobble"
    },
    {
      "x": -2,
      "y": 10,
      "z": 3,
      "name": "Rock_Stone_Cobble"
    },
    {
      "x": -2,
      "y": 11,
      "z": 3,
      "name": "Rock_Stone_Cobble_Roof_Flat",
      "rotation": 1
    },
    {
      "x": -1,
      "y": 0,
      "z": -3,
      "name": "Rock_Stone_Brick",
      "rotation": 3
    },
    {
      "x": -1,
      "y": 6,
      "z": -3,
      "name": "Wood_Beech_Branch_Long",
      "support": 15,
      "rotation": 7
    },
    {
      "x": -1,
      "y": 7,
      "z": -3,
      "name": "Wood_Beech_Trunk",
      "support": 15,
      "rotation": 7
    },
    {
      "x": -1,
      "y": 8,
      "z": -3,
      "name": "Furniture_Tavern_Window"
    },
    {
      "x": -1,
      "y": 9,
      "z": -3,
      "name": "Furniture_Tavern_Window"
    },
    {
      "x": -1,
      "y": 10,
      "z": -3,
      "name": "Rock_Stone_Cobble"
    },
    {
      "x": -1,
      "y": 11,
      "z": -3,
      "name": "Rock_Stone_Cobble_Roof_Flat",
      "rotation": 1
    },
    {
      "x": -1,
      "y": 0,
      "z": -2,
      "name": "Soil_Gravel",
      "support": 15,
      "rotation": 3
    },
    {
      "x": -1,
      "y": 7,
      "z": -2,
      "name": "Rock_Stone_Cobble",
      "rotation": 3
    },
    {
      "x": -1,
      "y": 8,
      "z": -2,
      "name": "Rock_Stone_Cobble",
      "rotation": 3
    },
    {
      "x": -1,
      "y": 9,
      "z": -2,
      "name": "Rock_Stone_Cobble"
    },
    {
      "x": -1,
      "y": 10,
      "z": -2,
      "name": "Rock_Stone_Cobble"
    },
    {
      "x": -1,
      "y": 11,
      "z": -2,
      "name": "Rock_Stone_Cobble_Roof_Flat",
      "rotation": 1
    },
    {
      "x": -1,
      "y": 0,
      "z": -1,
      "name": "Soil_Gravel",
      "support": 15,
      "rotation": 3
    },
    {
      "x": -1,
      "y": 7,
      "z": -1,
      "name": "Rock_Stone_Cobble",
      "rotation": 3
    },
    {
      "x": -1,
      "y": 8,
      "z": -1,
      "name": "Rock_Stone_Cobble",
      "rotation": 3
    },
    {
      "x": -1,
      "y": 9,
      "z": -1,
      "name": "Rock_Stone_Cobble"
    },
    {
      "x": -1,
      "y": 10,
      "z": -1,
      "name": "Rock_Stone_Cobble"
    },
    {
      "x": -1,
      "y": 11,
      "z": -1,
      "name": "Rock_Stone_Cobble_Roof_Flat",
      "rotation": 1
    },
    {
      "x": -1,
      "y": 0,
      "z": 0,
      "name": "Soil_Gravel",
      "support": 15,
      "rotation": 3
    },
    {
      "x": -1,
      "y": 7,
      "z": 0,
      "name": "Rock_Stone_Cobble",
      "rotation": 3
    },
    {
      "x": -1,
      "y": 8,
      "z": 0,
      "name": "Rock_Stone_Cobble",
      "rotation": 3
    },
    {
      "x": -1,
      "y": 9,
      "z": 0,
      "name": "Rock_Stone_Cobble"
    },
    {
      "x": -1,
      "y": 10,
      "z": 0,
      "name": "Rock_Stone_Cobble"
    },
    {
      "x": -1,
      "y": 11,
      "z": 0,
      "name": "Rock_Stone_Cobble_Roof_Flat",
      "rotation": 1
    },
    {
      "x": -1,
      "y": 0,
      "z": 1,
      "name": "Soil_Gravel",
      "support": 15,
      "rotation": 3
    },
    {
      "x": -1,
      "y": 7,
      "z": 1,
      "name": "Rock_Stone_Cobble",
      "rotation": 3
    },
    {
      "x": -1,
      "y": 8,
      "z": 1,
      "name": "Rock_Stone_Cobble",
      "rotation": 3
    },
    {
      "x": -1,
      "y": 9,
      "z": 1,
      "name": "Rock_Stone_Cobble"
    },
    {
      "x": -1,
      "y": 10,
      "z": 1,
      "name": "Rock_Stone_Cobble"
    },
    {
      "x": -1,
      "y": 11,
      "z": 1,
      "name": "Rock_Stone_Cobble_Roof_Flat",
      "rotation": 1
    },
    {
      "x": -1,
      "y": 0,
      "z": 2,
      "name": "Soil_Gravel",
      "support": 15,
      "rotation": 3
    },
    {
      "x": -1,
      "y": 7,
      "z": 2,
      "name": "Rock_Stone_Cobble",
      "rotation": 3
    },
    {
      "x": -1,
      "y": 8,
      "z": 2,
      "name": "Rock_Stone_Cobble",
      "rotation": 3
    },
    {
      "x": -1,
      "y": 9,
      "z": 2,
      "name": "Rock_Stone_Cobble"
    },
    {
      "x": -1,
      "y": 10,
      "z": 2,
      "name": "Rock_Stone_Cobble"
    },
    {
      "x": -1,
      "y": 11,
      "z": 2,
      "name": "Rock_Stone_Cobble_Roof_Flat",
      "rotation": 1
    },
    {
      "x": -1,
      "y": 0,
      "z": 3,
      "name": "Rock_Stone_Brick",
      "rotation": 3
    },
    {
      "x": -1,
      "y": 1,
      "z": 3,
      "name": "*Wood_Village_Wall_Full_State_Definitions_Bottom"
    },
    {
      "x": -1,
      "y": 2,
      "z": 3,
      "name": "*Wood_Village_Wall_Full_State_Definitions_Middle",
      "rotation": 3
    },
    {
      "x": -1,
      "y": 3,
      "z": 3,
      "name": "*Wood_Village_Wall_Full_State_Definitions_Middle",
      "rotation": 3
    },
    {
      "x": -1,
      "y": 4,
      "z": 3,
      "name": "*Wood_Village_Wall_Full_State_Definitions_Middle",
      "rotation": 3
    },
    {
      "x": -1,
      "y": 5,
      "z": 3,
      "name": "*Wood_Village_Wall_Full_State_Definitions_Top",
      "rotation": 3
    },
    {
      "x": -1,
      "y": 6,
      "z": 3,
      "name": "Wood_Beech_Trunk",
      "support": 15,
      "rotation": 7
    },
    {
      "x": -1,
      "y": 7,
      "z": 3,
      "name": "Rock_Stone_Cobble"
    },
    {
      "x": -1,
      "y": 8,
      "z": 3,
      "name": "Rock_Stone_Cobble",
      "rotation": 3
    },
    {
      "x": -1,
      "y": 9,
      "z": 3,
      "name": "Rock_Stone_Cobble"
    },
    {
      "x": -1,
      "y": 10,
      "z": 3,
      "name": "Rock_Stone_Cobble"
    },
    {
      "x": -1,
      "y": 11,
      "z": 3,
      "name": "Rock_Stone_Cobble_Roof_Flat",
      "rotation": 1
    },
    {
      "x": 0,
      "y": 0,
      "z": -3,
      "name": "Rock_Stone_Brick",
      "rotation": 3
    },
    {
      "x": 0,
      "y": 6,
      "z": -3,
      "name": "Wood_Beech_Branch_Long",
      "support": 15,
      "rotation": 7
    },
    {
      "x": 0,
      "y": 7,
      "z": -3,
      "name": "Wood_Beech_Trunk",
      "support": 15,
      "rotation": 5
    },
    {
      "x": 0,
      "y": 8,
      "z": -3,
      "name": "Furniture_Tavern_Window"
    },
    {
      "x": 0,
      "y": 9,
      "z": -3,
      "name": "Furniture_Tavern_Window"
    },
    {
      "x": 0,
      "y": 10,
      "z": -3,
      "name": "Wood_Beech_Trunk",
      "support": 15,
      "rotation": 4
    },
    {
      "x": 0,
      "y": 11,
      "z": -3,
      "name": "Rock_Stone_Cobble_Roof_Flat",
      "rotation": 1
    },
    {
      "x": 0,
      "y": 0,
      "z": -2,
      "name": "Soil_Gravel",
      "support": 15,
      "rotation": 3
    },
    {
      "x": 0,
      "y": 7,
      "z": -2,
      "name": "Wood_Beech_Trunk",
      "support": 15,
      "rotation": 4
    },
    {
      "x": 0,
      "y": 8,
      "z": -2,
      "name": "Rock_Stone_Cobble",
      "rotation": 3
    },
    {
      "x": 0,
      "y": 10,
      "z": -2,
      "name": "Wood_Beech_Trunk",
      "support": 15,
      "rotation": 4
    },
    {
      "x": 0,
      "y": 11,
      "z": -2,
      "name": "Rock_Stone_Cobble_Roof_Flat",
      "rotation": 1
    },
    {
      "x": 0,
      "y": 0,
      "z": -1,
      "name": "Soil_Gravel",
      "support": 15,
      "rotation": 3
    },
    {
      "x": 0,
      "y": 7,
      "z": -1,
      "name": "Wood_Beech_Trunk",
      "support": 15,
      "rotation": 4
    },
    {
      "x": 0,
      "y": 8,
      "z": -1,
      "name": "Rock_Stone_Cobble",
      "rotation": 3
    },
    {
      "x": 0,
      "y": 10,
      "z": -1,
      "name": "Wood_Beech_Trunk",
      "support": 15,
      "rotation": 4
    },
    {
      "x": 0,
      "y": 11,
      "z": -1,
      "name": "Rock_Stone_Cobble_Roof_Flat",
      "rotation": 1
    },
    {
      "x": 0,
      "y": 0,
      "z": 0,
      "name": "Soil_Gravel",
      "support": 15,
      "rotation": 3
    },
    {
      "x": 0,
      "y": 4,
      "z": 0,
      "name": "Deco_Lantern_Ceiling"
    },
    {
      "x": 0,
      "y": 5,
      "z": 0,
      "name": "Deco_Iron_Chain_Small"
    },
    {
      "x": 0,
      "y": 6,
      "z": 0,
      "name": "Deco_Iron_Chain_Small"
    },
    {
      "x": 0,
      "y": 7,
      "z": 0,
      "name": "Wood_Beech_Trunk",
      "support": 15,
      "rotation": 4
    },
    {
      "x": 0,
      "y": 8,
      "z": 0,
      "name": "Rock_Stone_Cobble",
      "rotation": 3
    },
    {
      "x": 0,
      "y": 9,
      "z": 0,
      "name": "Rock_Stone_Cobble"
    },
    {
      "x": 0,
      "y": 10,
      "z": 0,
      "name": "Wood_Beech_Trunk",
      "support": 15,
      "rotation": 4
    },
    {
      "x": 0,
      "y": 11,
      "z": 0,
      "name": "Rock_Stone_Cobble_Roof_Flat",
      "rotation": 1
    },
    {
      "x": 0,
      "y": 0,
      "z": 1,
      "name": "Soil_Gravel",
      "support": 15,
      "rotation": 3
    },
    {
      "x": 0,
      "y": 7,
      "z": 1,
      "name": "Wood_Beech_Trunk",
      "support": 15,
      "rotation": 4
    },
    {
      "x": 0,
      "y": 8,
      "z": 1,
      "name": "Rock_Stone_Cobble",
      "rotation": 3
    },
    {
      "x": 0,
      "y": 9,
      "z": 1,
      "name": "Rock_Stone_Cobble"
    },
    {
      "x": 0,
      "y": 10,
      "z": 1,
      "name": "Wood_Beech_Trunk",
      "support": 15,
      "rotation": 4
    },
    {
      "x": 0,
      "y": 11,
      "z": 1,
      "name": "Rock_Stone_Cobble_Roof_Flat",
      "rotation": 1
    },
    {
      "x": 0,
      "y": 0,
      "z": 2,
      "name": "Soil_Gravel",
      "support": 15,
      "rotation": 3
    },
    {
      "x": 0,
      "y": 7,
      "z": 2,
      "name": "Wood_Beech_Trunk",
      "support": 15,
      "rotation": 4
    },
    {
      "x": 0,
      "y": 8,
      "z": 2,
      "name": "Rock_Stone_Cobble",
      "rotation": 3
    },
    {
      "x": 0,
      "y": 9,
      "z": 2,
      "name": "Rock_Stone_Cobble"
    },
    {
      "x": 0,
      "y": 10,
      "z": 2,
      "name": "Wood_Beech_Trunk",
      "support": 15,
      "rotation": 4
    },
    {
      "x": 0,
      "y": 11,
      "z": 2,
      "name": "Rock_Stone_Cobble_Roof_Flat",
      "rotation": 1
    },
    {
      "x": 0,
      "y": 0,
      "z": 3,
      "name": "Rock_Stone_Brick",
      "rotation": 3
    },
    {
      "x": 0,
      "y": 1,
      "z": 3,
      "name": "Wood_Beech_Trunk",
      "support": 15
    },
    {
      "x": 0,
      "y": 2,
      "z": 3,
      "name": "Wood_Beech_Trunk",
      "support": 15
    },
    {
      "x": 0,
      "y": 3,
      "z": 3,
      "name": "Wood_Beech_Trunk",
      "support": 15
    },
    {
      "x": 0,
      "y": 4,
      "z": 3,
      "name": "Wood_Beech_Trunk",
      "support": 15
    },
    {
      "x": 0,
      "y": 5,
      "z": 3,
      "name": "Wood_Beech_Trunk",
      "support": 15
    },
    {
      "x": 0,
      "y": 6,
      "z": 3,
      "name": "Wood_Beech_Trunk",
      "support": 15,
      "rotation": 7
    },
    {
      "x": 0,
      "y": 7,
      "z": 3,
      "name": "Wood_Beech_Trunk",
      "support": 15
    },
    {
      "x": 0,
      "y": 8,
      "z": 3,
      "name": "Wood_Beech_Trunk",
      "support": 15
    },
    {
      "x": 0,
      "y": 9,
      "z": 3,
      "name": "Wood_Beech_Trunk",
      "support": 15
    },
    {
      "x": 0,
      "y": 10,
      "z": 3,
      "name": "Wood_Beech_Trunk",
      "support": 15,
      "rotation": 4
    },
    {
      "x": 0,
      "y": 11,
      "z": 3,
      "name": "Rock_Stone_Cobble_Roof_Flat",
      "rotation": 1
    },
    {
      "x": 1,
      "y": 0,
      "z": -3,
      "name": "Rock_Stone_Brick",
      "rotation": 1
    },
    {
      "x": 1,
      "y": 6,
      "z": -3,
      "name": "Wood_Beech_Branch_Long",
      "support": 15,
      "rotation": 7
    },
    {
      "x": 1,
      "y": 7,
      "z": -3,
      "name": "Wood_Beech_Trunk",
      "support": 15,
      "rotation": 5
    },
    {
      "x": 1,
      "y": 8,
      "z": -3,
      "name": "Furniture_Tavern_Window"
    },
    {
      "x": 1,
      "y": 9,
      "z": -3,
      "name": "Furniture_Tavern_Window"
    },
    {
      "x": 1,
      "y": 10,
      "z": -3,
      "name": "Rock_Stone_Cobble"
    },
    {
      "x": 1,
      "y": 11,
      "z": -3,
      "name": "Rock_Stone_Cobble_Roof_Flat",
      "rotation": 1
    },
    {
      "x": 1,
      "y": 0,
      "z": -2,
      "name": "Soil_Gravel",
      "support": 15,
      "rotation": 3
    },
    {
      "x": 1,
      "y": 8,
      "z": -2,
      "name": "Rock_Stone_Cobble"
    },
    {
      "x": 1,
      "y": 9,
      "z": -2,
      "name": "Rock_Stone_Cobble"
    },
    {
      "x": 1,
      "y": 10,
      "z": -2,
      "name": "Rock_Stone_Cobble"
    },
    {
      "x": 1,
      "y": 11,
      "z": -2,
      "name": "Rock_Stone_Cobble_Roof_Flat",
      "rotation": 1
    },
    {
      "x": 1,
      "y": 0,
      "z": -1,
      "name": "Soil_Gravel",
      "support": 15,
      "rotation": 3
    },
    {
      "x": 1,
      "y": 8,
      "z": -1,
      "name": "Rock_Stone_Cobble"
    },
    {
      "x": 1,
      "y": 9,
      "z": -1,
      "name": "Rock_Stone_Cobble"
    },
    {
      "x": 1,
      "y": 10,
      "z": -1,
      "name": "Rock_Stone_Cobble"
    },
    {
      "x": 1,
      "y": 11,
      "z": -1,
      "name": "Rock_Stone_Cobble_Roof_Flat",
      "rotation": 1
    },
    {
      "x": 1,
      "y": 0,
      "z": 0,
      "name": "Soil_Gravel",
      "support": 15,
      "rotation": 3
    },
    {
      "x": 1,
      "y": 8,
      "z": 0,
      "name": "Rock_Stone_Cobble"
    },
    {
      "x": 1,
      "y": 9,
      "z": 0,
      "name": "Rock_Stone_Cobble"
    },
    {
      "x": 1,
      "y": 10,
      "z": 0,
      "name": "Rock_Stone_Cobble"
    },
    {
      "x": 1,
      "y": 11,
      "z": 0,
      "name": "Rock_Stone_Cobble_Roof_Flat",
      "rotation": 1
    },
    {
      "x": 1,
      "y": 0,
      "z": 1,
      "name": "Soil_Gravel",
      "support": 15,
      "rotation": 3
    },
    {
      "x": 1,
      "y": 8,
      "z": 1,
      "name": "Rock_Stone_Cobble"
    },
    {
      "x": 1,
      "y": 10,
      "z": 1,
      "name": "Rock_Stone_Cobble"
    },
    {
      "x": 1,
      "y": 11,
      "z": 1,
      "name": "Rock_Stone_Cobble_Roof_Flat",
      "rotation": 1
    },
    {
      "x": 1,
      "y": 0,
      "z": 2,
      "name": "Soil_Gravel",
      "support": 15,
      "rotation": 3
    },
    {
      "x": 1,
      "y": 8,
      "z": 2,
      "name": "Rock_Stone_Cobble"
    },
    {
      "x": 1,
      "y": 9,
      "z": 2,
      "name": "Rock_Stone_Cobble"
    },
    {
      "x": 1,
      "y": 10,
      "z": 2,
      "name": "Rock_Stone_Cobble"
    },
    {
      "x": 1,
      "y": 11,
      "z": 2,
      "name": "Rock_Stone_Cobble_Roof_Flat",
      "rotation": 1
    },
    {
      "x": 1,
      "y": 0,
      "z": 3,
      "name": "Rock_Stone_Brick",
      "rotation": 3
    },
    {
      "x": 1,
      "y": 1,
      "z": 3,
      "name": "*Wood_Village_Wall_Full_State_Definitions_Bottom"
    },
    {
      "x": 1,
      "y": 2,
      "z": 3,
      "name": "*Wood_Village_Wall_Full_State_Definitions_Middle",
      "rotation": 3
    },
    {
      "x": 1,
      "y": 3,
      "z": 3,
      "name": "*Wood_Village_Wall_Full_State_Definitions_Middle",
      "rotation": 3
    },
    {
      "x": 1,
      "y": 4,
      "z": 3,
      "name": "*Wood_Village_Wall_Full_State_Definitions_Middle",
      "rotation": 3
    },
    {
      "x": 1,
      "y": 5,
      "z": 3,
      "name": "*Wood_Village_Wall_Full_State_Definitions_Top",
      "rotation": 3
    },
    {
      "x": 1,
      "y": 6,
      "z": 3,
      "name": "Wood_Beech_Trunk",
      "support": 15,
      "rotation": 7
    },
    {
      "x": 1,
      "y": 7,
      "z": 3,
      "name": "Rock_Stone_Cobble"
    },
    {
      "x": 1,
      "y": 8,
      "z": 3,
      "name": "Rock_Stone_Cobble"
    },
    {
      "x": 1,
      "y": 9,
      "z": 3,
      "name": "Rock_Stone_Cobble"
    },
    {
      "x": 1,
      "y": 10,
      "z": 3,
      "name": "Rock_Stone_Cobble"
    },
    {
      "x": 1,
      "y": 11,
      "z": 3,
      "name": "Rock_Stone_Cobble_Roof_Flat",
      "rotation": 1
    },
    {
      "x": 2,
      "y": 0,
      "z": -3,
      "name": "Rock_Stone_Brick",
      "rotation": 3
    },
    {
      "x": 2,
      "y": 6,
      "z": -3,
      "name": "Wood_Beech_Branch_Long",
      "support": 15,
      "rotation": 5
    },
    {
      "x": 2,
      "y": 7,
      "z": -3,
      "name": "Wood_Beech_Trunk",
      "support": 15,
      "rotation": 5
    },
    {
      "x": 2,
      "y": 8,
      "z": -3,
      "name": "Furniture_Tavern_Window"
    },
    {
      "x": 2,
      "y": 9,
      "z": -3,
      "name": "Rock_Stone_Cobble"
    },
    {
      "x": 2,
      "y": 10,
      "z": -3,
      "name": "Rock_Stone_Cobble"
    },
    {
      "x": 2,
      "y": 11,
      "z": -3,
      "name": "Rock_Stone_Cobble_Roof_Flat",
      "rotation": 1
    },
    {
      "x": 2,
      "y": 0,
      "z": -2,
      "name": "Soil_Gravel",
      "support": 15,
      "rotation": 3
    },
    {
      "x": 2,
      "y": 8,
      "z": -2,
      "name": "Rock_Stone_Cobble"
    },
    {
      "x": 2,
      "y": 9,
      "z": -2,
      "name": "Rock_Stone_Cobble"
    },
    {
      "x": 2,
      "y": 10,
      "z": -2,
      "name": "Rock_Stone_Cobble"
    },
    {
      "x": 2,
      "y": 11,
      "z": -2,
      "name": "Rock_Stone_Cobble_Roof_Flat",
      "rotation": 1
    },
    {
      "x": 2,
      "y": 0,
      "z": -1,
      "name": "Soil_Gravel",
      "support": 15,
      "rotation": 3
    },
    {
      "x": 2,
      "y": 8,
      "z": -1,
      "name": "Rock_Stone_Cobble"
    },
    {
      "x": 2,
      "y": 9,
      "z": -1,
      "name": "Rock_Stone_Cobble"
    },
    {
      "x": 2,
      "y": 10,
      "z": -1,
      "name": "Rock_Stone_Cobble"
    },
    {
      "x": 2,
      "y": 11,
      "z": -1,
      "name": "Rock_Stone_Cobble_Roof_Flat",
      "rotation": 1
    },
    {
      "x": 2,
      "y": 0,
      "z": 0,
      "name": "Soil_Gravel",
      "support": 15,
      "rotation": 3
    },
    {
      "x": 2,
      "y": 8,
      "z": 0,
      "name": "Rock_Stone_Cobble"
    },
    {
      "x": 2,
      "y": 9,
      "z": 0,
      "name": "Rock_Stone_Cobble"
    },
    {
      "x": 2,
      "y": 10,
      "z": 0,
      "name": "Rock_Stone_Cobble"
    },
    {
      "x": 2,
      "y": 11,
      "z": 0,
      "name": "Rock_Stone_Cobble_Roof_Flat",
      "rotation": 1
    },
    {
      "x": 2,
      "y": 0,
      "z": 1,
      "name": "Soil_Gravel",
      "support": 15,
      "rotation": 3
    },
    {
      "x": 2,
      "y": 8,
      "z": 1,
      "name": "Rock_Stone_Cobble"
    },
    {
      "x": 2,
      "y": 9,
      "z": 1,
      "name": "Rock_Stone_Cobble"
    },
    {
      "x": 2,
      "y": 10,
      "z": 1,
      "name": "Rock_Stone_Cobble"
    },
    {
      "x": 2,
      "y": 11,
      "z": 1,
      "name": "Rock_Stone_Cobble_Roof_Flat",
      "rotation": 1
    },
    {
      "x": 2,
      "y": 0,
      "z": 2,
      "name": "Soil_Gravel",
      "support": 15,
      "rotation": 3
    },
    {
      "x": 2,
      "y": 8,
      "z": 2,
      "name": "Rock_Stone_Cobble"
    },
    {
      "x": 2,
      "y": 9,
      "z": 2,
      "name": "Rock_Stone_Cobble"
    },
    {
      "x": 2,
      "y": 10,
      "z": 2,
      "name": "Rock_Stone_Cobble"
    },
    {
      "x": 2,
      "y": 11,
      "z": 2,
      "name": "Rock_Stone_Cobble_Roof_Flat",
      "rotation": 1
    },
    {
      "x": 2,
      "y": 0,
      "z": 3,
      "name": "Rock_Stone_Brick",
      "rotation": 3
    },
    {
      "x": 2,
      "y": 1,
      "z": 3,
      "name": "*Wood_Village_Wall_Full_State_Definitions_Bottom"
    },
    {
      "x": 2,
      "y": 2,
      "z": 3,
      "name": "*Wood_Village_Wall_Full_State_Definitions_Middle"
    },
    {
      "x": 2,
      "y": 3,
      "z": 3,
      "name": "*Wood_Village_Wall_Full_State_Definitions_Middle"
    },
    {
      "x": 2,
      "y": 4,
      "z": 3,
      "name": "*Wood_Village_Wall_Full_State_Definitions_Middle"
    },
    {
      "x": 2,
      "y": 5,
      "z": 3,
      "name": "*Wood_Village_Wall_Full_State_Definitions_Top"
    },
    {
      "x": 2,
      "y": 6,
      "z": 3,
      "name": "Wood_Beech_Trunk",
      "support": 15,
      "rotation": 5
    },
    {
      "x": 2,
      "y": 7,
      "z": 3,
      "name": "Rock_Stone_Cobble"
    },
    {
      "x": 2,
      "y": 8,
      "z": 3,
      "name": "Rock_Stone_Cobble"
    },
    {
      "x": 2,
      "y": 9,
      "z": 3,
      "name": "Rock_Stone_Cobble"
    },
    {
      "x": 2,
      "y": 10,
      "z": 3,
      "name": "Rock_Stone_Cobble"
    },
    {
      "x": 2,
      "y": 11,
      "z": 3,
      "name": "Rock_Stone_Cobble_Roof_Flat",
      "rotation": 1
    },
    {
      "x": 3,
      "y": 0,
      "z": -3,
      "name": "Rock_Stone_Brick",
      "rotation": 3
    },
    {
      "x": 3,
      "y": 6,
      "z": -3,
      "name": "Wood_Beech_Branch_Long",
      "support": 15,
      "rotation": 5
    },
    {
      "x": 3,
      "y": 7,
      "z": -3,
      "name": "Wood_Beech_Trunk",
      "support": 15,
      "rotation": 5
    },
    {
      "x": 3,
      "y": 8,
      "z": -3,
      "name": "Rock_Stone_Cobble"
    },
    {
      "x": 3,
      "y": 9,
      "z": -3,
      "name": "Rock_Stone_Cobble"
    },
    {
      "x": 3,
      "y": 10,
      "z": -3,
      "name": "Rock_Stone_Cobble_Roof",
      "rotation": 1
    },
    {
      "x": 3,
      "y": 0,
      "z": -2,
      "name": "Soil_Gravel",
      "support": 15,
      "rotation": 3
    },
    {
      "x": 3,
      "y": 7,
      "z": -2,
      "name": "Wood_Beech_Trunk",
      "support": 15,
      "rotation": 4
    },
    {
      "x": 3,
      "y": 8,
      "z": -2,
      "name": "Rock_Stone_Cobble"
    },
    {
      "x": 3,
      "y": 9,
      "z": -2,
      "name": "Rock_Stone_Cobble"
    },
    {
      "x": 3,
      "y": 10,
      "z": -2,
      "name": "Rock_Stone_Cobble_Roof",
      "rotation": 1
    },
    {
      "x": 3,
      "y": 0,
      "z": -1,
      "name": "Soil_Gravel",
      "support": 15,
      "rotation": 3
    },
    {
      "x": 3,
      "y": 7,
      "z": -1,
      "name": "Wood_Beech_Trunk",
      "support": 15,
      "rotation": 4
    },
    {
      "x": 3,
      "y": 8,
      "z": -1,
      "name": "Rock_Stone_Cobble"
    },
    {
      "x": 3,
      "y": 9,
      "z": -1,
      "name": "Rock_Stone_Cobble"
    },
    {
      "x": 3,
      "y": 10,
      "z": -1,
      "name": "Rock_Stone_Cobble_Roof",
      "rotation": 1
    },
    {
      "x": 3,
      "y": 0,
      "z": 0,
      "name": "Soil_Gravel",
      "support": 15,
      "rotation": 3
    },
    {
      "x": 3,
      "y": 7,
      "z": 0,
      "name": "Wood_Beech_Trunk",
      "support": 15,
      "rotation": 4
    },
    {
      "x": 3,
      "y": 8,
      "z": 0,
      "name": "Rock_Stone_Cobble"
    },
    {
      "x": 3,
      "y": 9,
      "z": 0,
      "name": "Rock_Stone_Cobble"
    },
    {
      "x": 3,
      "y": 10,
      "z": 0,
      "name": "Rock_Stone_Cobble_Roof",
      "rotation": 1
    },
    {
      "x": 3,
      "y": 0,
      "z": 1,
      "name": "Soil_Gravel",
      "support": 15,
      "rotation": 3
    },
    {
      "x": 3,
      "y": 7,
      "z": 1,
      "name": "Wood_Beech_Trunk",
      "support": 15,
      "rotation": 4
    },
    {
      "x": 3,
      "y": 8,
      "z": 1,
      "name": "Rock_Stone_Cobble"
    },
    {
      "x": 3,
      "y": 9,
      "z": 1,
      "name": "Rock_Stone_Cobble"
    },
    {
      "x": 3,
      "y": 10,
      "z": 1,
      "name": "Rock_Stone_Cobble_Roof",
      "rotation": 1
    },
    {
      "x": 3,
      "y": 0,
      "z": 2,
      "name": "Soil_Gravel",
      "support": 15,
      "rotation": 3
    },
    {
      "x": 3,
      "y": 7,
      "z": 2,
      "name": "Wood_Beech_Trunk",
      "support": 15,
      "rotation": 4
    },
    {
      "x": 3,
      "y": 8,
      "z": 2,
      "name": "Rock_Stone_Cobble"
    },
    {
      "x": 3,
      "y": 9,
      "z": 2,
      "name": "Rock_Stone_Cobble"
    },
    {
      "x": 3,
      "y": 10,
      "z": 2,
      "name": "Rock_Stone_Cobble_Roof",
      "rotation": 1
    },
    {
      "x": 3,
      "y": 0,
      "z": 3,
      "name": "Rock_Stone_Brick"
    },
    {
      "x": 3,
      "y": 1,
      "z": 3,
      "name": "Wood_Beech_Trunk",
      "support": 15
    },
    {
      "x": 3,
      "y": 2,
      "z": 3,
      "name": "Wood_Beech_Trunk",
      "support": 15
    },
    {
      "x": 3,
      "y": 3,
      "z": 3,
      "name": "Wood_Beech_Trunk",
      "support": 15
    },
    {
      "x": 3,
      "y": 4,
      "z": 3,
      "name": "Wood_Beech_Trunk",
      "support": 15
    },
    {
      "x": 3,
      "y": 5,
      "z": 3,
      "name": "Wood_Beech_Trunk",
      "support": 15
    },
    {
      "x": 3,
      "y": 6,
      "z": 3,
      "name": "Wood_Beech_Trunk",
      "support": 15,
      "rotation": 5
    },
    {
      "x": 3,
      "y": 7,
      "z": 3,
      "name": "Rock_Stone_Cobble"
    },
    {
      "x": 3,
      "y": 8,
      "z": 3,
      "name": "Rock_Stone_Cobble"
    },
    {
      "x": 3,
      "y": 9,
      "z": 3,
      "name": "Rock_Stone_Cobble"
    },
    {
      "x": 3,
      "y": 10,
      "z": 3,
      "name": "Rock_Stone_Cobble_Roof",
      "rotation": 1
    },
    {
      "x": 4,
      "y": 0,
      "z": -3,
      "name": "Rock_Stone_Brick",
      "rotation": 3
    },
    {
      "x": 4,
      "y": 6,
      "z": -3,
      "name": "Wood_Beech_Branch_Long",
      "support": 15,
      "rotation": 5
    },
    {
      "x": 4,
      "y": 7,
      "z": -3,
      "name": "Wood_Beech_Trunk",
      "support": 15,
      "rotation": 5
    },
    {
      "x": 4,
      "y": 8,
      "z": -3,
      "name": "Rock_Stone_Cobble"
    },
    {
      "x": 4,
      "y": 9,
      "z": -3,
      "name": "Rock_Stone_Cobble_Roof",
      "rotation": 1
    },
    {
      "x": 4,
      "y": 0,
      "z": -2,
      "name": "Soil_Gravel",
      "support": 15,
      "rotation": 3
    },
    {
      "x": 4,
      "y": 8,
      "z": -2,
      "name": "Rock_Stone_Cobble"
    },
    {
      "x": 4,
      "y": 9,
      "z": -2,
      "name": "Rock_Stone_Cobble_Roof",
      "rotation": 1
    },
    {
      "x": 4,
      "y": 0,
      "z": -1,
      "name": "Soil_Gravel",
      "support": 15,
      "rotation": 3
    },
    {
      "x": 4,
      "y": 8,
      "z": -1,
      "name": "Rock_Stone_Cobble"
    },
    {
      "x": 4,
      "y": 9,
      "z": -1,
      "name": "Rock_Stone_Cobble_Roof",
      "rotation": 1
    },
    {
      "x": 4,
      "y": 0,
      "z": 0,
      "name": "Soil_Gravel",
      "support": 15,
      "rotation": 3
    },
    {
      "x": 4,
      "y": 8,
      "z": 0,
      "name": "Rock_Stone_Cobble"
    },
    {
      "x": 4,
      "y": 9,
      "z": 0,
      "name": "Rock_Stone_Cobble_Roof",
      "rotation": 1
    },
    {
      "x": 4,
      "y": 0,
      "z": 1,
      "name": "Soil_Gravel",
      "support": 15,
      "rotation": 3
    },
    {
      "x": 4,
      "y": 8,
      "z": 1,
      "name": "Rock_Stone_Cobble"
    },
    {
      "x": 4,
      "y": 9,
      "z": 1,
      "name": "Rock_Stone_Cobble_Roof",
      "rotation": 1
    },
    {
      "x": 4,
      "y": 0,
      "z": 2,
      "name": "Soil_Gravel",
      "support": 15,
      "rotation": 3
    },
    {
      "x": 4,
      "y": 1,
      "z": 2,
      "name": "Bench_Weapon",
      "components": {
        "Components": {
          "PlacedByInteraction": {
            "WhoPlacedUuid": {
              "$binary": "KOVaxfjkQ0KARYZRuCHO+w==",
              "$type": "04"
            }
          },
          "crafting": {
            "Position": {
              "X": 9,
              "Y": 191,
              "Z": 31
            },
            "TierLevel": 1,
            "UpgradeItems": []
          }
        }
      },
      "rotation": 2
    },
    {
      "x": 4,
      "y": 2,
      "z": 2,
      "name": "Bench_Weapon",
      "filler": 1024,
      "rotation": 2
    },
    {
      "x": 4,
      "y": 8,
      "z": 2,
      "name": "Rock_Stone_Cobble"
    },
    {
      "x": 4,
      "y": 9,
      "z": 2,
      "name": "Rock_Stone_Cobble_Roof",
      "rotation": 1
    },
    {
      "x": 4,
      "y": 0,
      "z": 3,
      "name": "Rock_Stone_Brick"
    },
    {
      "x": 4,
      "y": 1,
      "z": 3,
      "name": "*Wood_Village_Wall_Full_State_Definitions_Bottom"
    },
    {
      "x": 4,
      "y": 2,
      "z": 3,
      "name": "*Wood_Village_Wall_Full_State_Definitions_Middle"
    },
    {
      "x": 4,
      "y": 3,
      "z": 3,
      "name": "*Wood_Village_Wall_Full_State_Definitions_Middle"
    },
    {
      "x": 4,
      "y": 4,
      "z": 3,
      "name": "*Wood_Village_Wall_Full_State_Definitions_Middle"
    },
    {
      "x": 4,
      "y": 5,
      "z": 3,
      "name": "*Wood_Village_Wall_Full_State_Definitions_Top"
    },
    {
      "x": 4,
      "y": 6,
      "z": 3,
      "name": "Wood_Beech_Trunk",
      "support": 15,
      "rotation": 5
    },
    {
      "x": 4,
      "y": 7,
      "z": 3,
      "name": "Rock_Stone_Cobble"
    },
    {
      "x": 4,
      "y": 8,
      "z": 3,
      "name": "Rock_Stone_Cobble"
    },
    {
      "x": 4,
      "y": 9,
      "z": 3,
      "name": "Rock_Stone_Cobble_Roof",
      "rotation": 1
    },
    {
      "x": 5,
      "y": 0,
      "z": -3,
      "name": "Rock_Stone_Brick",
      "rotation": 3
    },
    {
      "x": 5,
      "y": 6,
      "z": -3,
      "name": "Wood_Beech_Branch_Long",
      "support": 15,
      "rotation": 5
    },
    {
      "x": 5,
      "y": 7,
      "z": -3,
      "name": "Wood_Beech_Trunk",
      "support": 15,
      "rotation": 5
    },
    {
      "x": 5,
      "y": 8,
      "z": -3,
      "name": "Rock_Stone_Cobble_Roof",
      "rotation": 1
    },
    {
      "x": 5,
      "y": 0,
      "z": -2,
      "name": "Soil_Gravel",
      "support": 15,
      "rotation": 3
    },
    {
      "x": 5,
      "y": 1,
      "z": -2,
      "name": "Rubble_Stone_Medium",
      "support": 15
    },
    {
      "x": 5,
      "y": 8,
      "z": -2,
      "name": "Rock_Stone_Cobble_Roof_Hollow",
      "rotation": 1
    },
    {
      "x": 5,
      "y": 0,
      "z": -1,
      "name": "Soil_Gravel",
      "support": 15,
      "rotation": 3
    },
    {
      "x": 5,
      "y": 8,
      "z": -1,
      "name": "Rock_Stone_Cobble_Roof_Hollow",
      "rotation": 1
    },
    {
      "x": 5,
      "y": 0,
      "z": 0,
      "name": "Soil_Gravel",
      "support": 15,
      "rotation": 3
    },
    {
      "x": 5,
      "y": 8,
      "z": 0,
      "name": "Rock_Stone_Cobble_Roof_Hollow",
      "rotation": 1
    },
    {
      "x": 5,
      "y": 0,
      "z": 1,
      "name": "Soil_Gravel",
      "support": 15,
      "rotation": 3
    },
    {
      "x": 5,
      "y": 8,
      "z": 1,
      "name": "Rock_Stone_Cobble_Roof_Hollow",
      "rotation": 1
    },
    {
      "x": 5,
      "y": 0,
      "z": 2,
      "name": "Soil_Gravel",
      "support": 15,
      "rotation": 3
    },
    {
      "x": 5,
      "y": 1,
      "z": 2,
      "name": "Bench_Weapon",
      "filler": 1,
      "rotation": 2
    },
    {
      "x": 5,
      "y": 2,
      "z": 2,
      "name": "Bench_Weapon",
      "filler": 1025,
      "rotation": 2
    },
    {
      "x": 5,
      "y": 8,
      "z": 2,
      "name": "Rock_Stone_Cobble_Roof_Hollow",
      "rotation": 1
    },
    {
      "x": 5,
      "y": 0,
      "z": 3,
      "name": "Rock_Stone_Brick"
    },
    {
      "x": 5,
      "y": 1,
      "z": 3,
      "name": "*Wood_Village_Wall_Full_State_Definitions_Bottom"
    },
    {
      "x": 5,
      "y": 2,
      "z": 3,
      "name": "*Wood_Village_Wall_Full_State_Definitions_Middle"
    },
    {
      "x": 5,
      "y": 3,
      "z": 3,
      "name": "*Wood_Village_Wall_Full_State_Definitions_Middle"
    },
    {
      "x": 5,
      "y": 4,
      "z": 3,
      "name": "*Wood_Village_Wall_Full_State_Definitions_Middle"
    },
    {
      "x": 5,
      "y": 5,
      "z": 3,
      "name": "*Wood_Village_Wall_Full_State_Definitions_Top"
    },
    {
      "x": 5,
      "y": 6,
      "z": 3,
      "name": "Wood_Beech_Trunk",
      "support": 15,
      "rotation": 5
    },
    {
      "x": 5,
      "y": 7,
      "z": 3,
      "name": "Rock_Stone_Cobble"
    },
    {
      "x": 5,
      "y": 8,
      "z": 3,
      "name": "Rock_Stone_Cobble_Roof",
      "rotation": 1
    },
    {
      "x": 6,
      "y": 0,
      "z": -3,
      "name": "Rock_Stone_Brick"
    },
    {
      "x": 6,
      "y": 1,
      "z": -3,
      "name": "Rock_Stone_Brick",
      "rotation": 3
    },
    {
      "x": 6,
      "y": 2,
      "z": -3,
      "name": "Rock_Stone_Cobble_Beam"
    },
    {
      "x": 6,
      "y": 3,
      "z": -3,
      "name": "Wood_Beech_Branch_Long",
      "support": 15
    },
    {
      "x": 6,
      "y": 4,
      "z": -3,
      "name": "Wood_Beech_Branch_Long",
      "support": 15
    },
    {
      "x": 6,
      "y": 5,
      "z": -3,
      "name": "Wood_Beech_Branch_Long",
      "support": 15
    },
    {
      "x": 6,
      "y": 6,
      "z": -3,
      "name": "Wood_Beech_Trunk",
      "support": 15
    },
    {
      "x": 6,
      "y": 7,
      "z": -3,
      "name": "Rock_Stone_Cobble_Roof_Shallow",
      "filler": 31,
      "rotation": 1
    },
    {
      "x": 6,
      "y": 0,
      "z": -2,
      "name": "Rock_Stone_Brick"
    },
    {
      "x": 6,
      "y": 1,
      "z": -2,
      "name": "Rock_Stone_Brick"
    },
    {
      "x": 6,
      "y": 2,
      "z": -2,
      "name": "Rubble_Stone_Medium",
      "support": 15
    },
    {
      "x": 6,
      "y": 6,
      "z": -2,
      "name": "Wood_Beech_Branch_Long",
      "support": 15,
      "rotation": 4
    },
    {
      "x": 6,
      "y": 7,
      "z": -2,
      "name": "Rock_Stone_Cobble_Roof_Shallow",
      "filler": 31,
      "rotation": 1
    },
    {
      "x": 6,
      "y": 0,
      "z": -1,
      "name": "Rock_Stone_Brick"
    },
    {
      "x": 6,
      "y": 1,
      "z": -1,
      "name": "Rock_Stone_Brick"
    },
    {
      "x": 6,
      "y": 2,
      "z": -1,
      "name": "Rock_Stone_Brick"
    },
    {
      "x": 6,
      "y": 6,
      "z": -1,
      "name": "Wood_Beech_Branch_Long",
      "support": 15,
      "rotation": 4
    },
    {
      "x": 6,
      "y": 7,
      "z": -1,
      "name": "Rock_Stone_Cobble_Roof_Shallow",
      "filler": 31,
      "rotation": 1
    },
    {
      "x": 6,
      "y": 0,
      "z": 0,
      "name": "Rock_Stone_Brick"
    },
    {
      "x": 6,
      "y": 1,
      "z": 0,
      "name": "Rock_Stone_Brick"
    },
    {
      "x": 6,
      "y": 2,
      "z": 0,
      "name": "Rock_Stone_Brick"
    },
    {
      "x": 6,
      "y": 3,
      "z": 0,
      "name": "Deco_Lantern"
    },
    {
      "x": 6,
      "y": 6,
      "z": 0,
      "name": "Wood_Beech_Branch_Long",
      "support": 15,
      "rotation": 4
    },
    {
      "x": 6,
      "y": 7,
      "z": 0,
      "name": "Rock_Stone_Cobble_Roof_Shallow",
      "filler": 31,
      "rotation": 1
    },
    {
      "x": 6,
      "y": 0,
      "z": 1,
      "name": "Rock_Stone_Brick"
    },
    {
      "x": 6,
      "y": 1,
      "z": 1,
      "name": "Rock_Stone_Brick"
    },
    {
      "x": 6,
      "y": 2,
      "z": 1,
      "name": "Rock_Stone_Brick"
    },
    {
      "x": 6,
      "y": 3,
      "z": 1,
      "name": "Rock_Stone_Brick"
    },
    {
      "x": 6,
      "y": 4,
      "z": 1,
      "name": "Rubble_Stone_Medium",
      "support": 15
    },
    {
      "x": 6,
      "y": 6,
      "z": 1,
      "name": "Wood_Beech_Branch_Long",
      "support": 15,
      "rotation": 4
    },
    {
      "x": 6,
      "y": 7,
      "z": 1,
      "name": "Rock_Stone_Cobble_Roof_Shallow",
      "filler": 31,
      "rotation": 1
    },
    {
      "x": 6,
      "y": 0,
      "z": 2,
      "name": "Rock_Stone_Brick"
    },
    {
      "x": 6,
      "y": 1,
      "z": 2,
      "name": "Rock_Stone_Brick"
    },
    {
      "x": 6,
      "y": 2,
      "z": 2,
      "name": "Rock_Stone_Brick"
    },
    {
      "x": 6,
      "y": 3,
      "z": 2,
      "name": "Rock_Stone_Brick"
    },
    {
      "x": 6,
      "y": 4,
      "z": 2,
      "name": "Rock_Stone_Brick"
    },
    {
      "x": 6,
      "y": 6,
      "z": 2,
      "name": "Wood_Beech_Branch_Long",
      "support": 15,
      "rotation": 4
    },
    {
      "x": 6,
      "y": 7,
      "z": 2,
      "name": "Rock_Stone_Cobble_Roof_Shallow",
      "filler": 31,
      "rotation": 1
    },
    {
      "x": 6,
      "y": 0,
      "z": 3,
      "name": "Rock_Stone_Brick"
    },
    {
      "x": 6,
      "y": 1,
      "z": 3,
      "name": "Wood_Beech_Trunk",
      "support": 15
    },
    {
      "x": 6,
      "y": 2,
      "z": 3,
      "name": "Wood_Beech_Trunk",
      "support": 15
    },
    {
      "x": 6,
      "y": 3,
      "z": 3,
      "name": "Wood_Beech_Trunk",
      "support": 15
    },
    {
      "x": 6,
      "y": 4,
      "z": 3,
      "name": "Wood_Beech_Trunk",
      "support": 15
    },
    {
      "x": 6,
      "y": 5,
      "z": 3,
      "name": "Wood_Beech_Trunk",
      "support": 15
    },
    {
      "x": 6,
      "y": 6,
      "z": 3,
      "name": "Wood_Beech_Trunk",
      "support": 15,
      "rotation": 4
    },
    {
      "x": 6,
      "y": 7,
      "z": 3,
      "name": "Rock_Stone_Cobble_Roof_Shallow",
      "filler": 31,
      "rotation": 1
    },
    {
      "x": 7,
      "y": 7,
      "z": -3,
      "name": "Rock_Stone_Cobble_Roof_Shallow",
      "rotation": 1
    },
    {
      "x": 7,
      "y": 7,
      "z": -2,
      "name": "Rock_Stone_Cobble_Roof_Shallow",
      "rotation": 1
    },
    {
      "x": 7,
      "y": 7,
      "z": -1,
      "name": "Rock_Stone_Cobble_Roof_Shallow",
      "rotation": 1
    },
    {
      "x": 7,
      "y": 7,
      "z": 0,
      "name": "Rock_Stone_Cobble_Roof_Shallow",
      "rotation": 1
    },
    {
      "x": 7,
      "y": 7,
      "z": 1,
      "name": "Rock_Stone_Cobble_Roof_Shallow",
      "rotation": 1
    },
    {
      "x": 7,
      "y": 7,
      "z": 2,
      "name": "Rock_Stone_Cobble_Roof_Shallow",
      "rotation": 1
    },
    {
      "x": 7,
      "y": 7,
      "z": 3,
      "name": "Rock_Stone_Cobble_Roof_Shallow",
      "rotation": 1
    }
  ],
  "fluids": [
    {
      "x": -7,
      "y": 7,
      "z": -3,
      "name": "Empty",
      "level": 0
    },
    {
      "x": -7,
      "y": 7,
      "z": -2,
      "name": "Empty",
      "level": 0
    },
    {
      "x": -7,
      "y": 7,
      "z": -1,
      "name": "Empty",
      "level": 0
    },
    {
      "x": -7,
      "y": 7,
      "z": 0,
      "name": "Empty",
      "level": 0
    },
    {
      "x": -7,
      "y": 7,
      "z": 1,
      "name": "Empty",
      "level": 0
    },
    {
      "x": -7,
      "y": 7,
      "z": 2,
      "name": "Empty",
      "level": 0
    },
    {
      "x": -7,
      "y": 7,
      "z": 3,
      "name": "Empty",
      "level": 0
    },
    {
      "x": -6,
      "y": 0,
      "z": -3,
      "name": "Empty",
      "level": 0
    },
    {
      "x": -6,
      "y": 1,
      "z": -3,
      "name": "Empty",
      "level": 0
    },
    {
      "x": -6,
      "y": 2,
      "z": -3,
      "name": "Empty",
      "level": 0
    },
    {
      "x": -6,
      "y": 3,
      "z": -3,
      "name": "Empty",
      "level": 0
    },
    {
      "x": -6,
      "y": 4,
      "z": -3,
      "name": "Empty",
      "level": 0
    },
    {
      "x": -6,
      "y": 5,
      "z": -3,
      "name": "Empty",
      "level": 0
    },
    {
      "x": -6,
      "y": 6,
      "z": -3,
      "name": "Empty",
      "level": 0
    },
    {
      "x": -6,
      "y": 7,
      "z": -3,
      "name": "Empty",
      "level": 0
    },
    {
      "x": -6,
      "y": 0,
      "z": -2,
      "name": "Empty",
      "level": 0
    },
    {
      "x": -6,
      "y": 1,
      "z": -2,
      "name": "Empty",
      "level": 0
    },
    {
      "x": -6,
      "y": 2,
      "z": -2,
      "name": "Empty",
      "level": 0
    },
    {
      "x": -6,
      "y": 6,
      "z": -2,
      "name": "Empty",
      "level": 0
    },
    {
      "x": -6,
      "y": 7,
      "z": -2,
      "name": "Empty",
      "level": 0
    },
    {
      "x": -6,
      "y": 0,
      "z": -1,
      "name": "Empty",
      "level": 0
    },
    {
      "x": -6,
      "y": 1,
      "z": -1,
      "name": "Empty",
      "level": 0
    },
    {
      "x": -6,
      "y": 2,
      "z": -1,
      "name": "Empty",
      "level": 0
    },
    {
      "x": -6,
      "y": 3,
      "z": -1,
      "name": "Empty",
      "level": 0
    },
    {
      "x": -6,
      "y": 6,
      "z": -1,
      "name": "Empty",
      "level": 0
    },
    {
      "x": -6,
      "y": 7,
      "z": -1,
      "name": "Empty",
      "level": 0
    },
    {
      "x": -6,
      "y": 0,
      "z": 0,
      "name": "Empty",
      "level": 0
    },
    {
      "x": -6,
      "y": 1,
      "z": 0,
      "name": "Empty",
      "level": 0
    },
    {
      "x": -6,
      "y": 2,
      "z": 0,
      "name": "Empty",
      "level": 0
    },
    {
      "x": -6,
      "y": 6,
      "z": 0,
      "name": "Empty",
      "level": 0
    },
    {
      "x": -6,
      "y": 7,
      "z": 0,
      "name": "Empty",
      "level": 0
    },
    {
      "x": -6,
      "y": 0,
      "z": 1,
      "name": "Empty",
      "level": 0
    },
    {
      "x": -6,
      "y": 1,
      "z": 1,
      "name": "Empty",
      "level": 0
    },
    {
      "x": -6,
      "y": 2,
      "z": 1,
      "name": "Empty",
      "level": 0
    },
    {
      "x": -6,
      "y": 3,
      "z": 1,
      "name": "Empty",
      "level": 0
    },
    {
      "x": -6,
      "y": 4,
      "z": 1,
      "name": "Empty",
      "level": 0
    },
    {
      "x": -6,
      "y": 6,
      "z": 1,
      "name": "Empty",
      "level": 0
    },
    {
      "x": -6,
      "y": 7,
      "z": 1,
      "name": "Empty",
      "level": 0
    },
    {
      "x": -6,
      "y": 0,
      "z": 2,
      "name": "Empty",
      "level": 0
    },
    {
      "x": -6,
      "y": 1,
      "z": 2,
      "name": "Empty",
      "level": 0
    },
    {
      "x": -6,
      "y": 2,
      "z": 2,
      "name": "Empty",
      "level": 0
    },
    {
      "x": -6,
      "y": 3,
      "z": 2,
      "name": "Empty",
      "level": 0
    },
    {
      "x": -6,
      "y": 4,
      "z": 2,
      "name": "Empty",
      "level": 0
    },
    {
      "x": -6,
      "y": 6,
      "z": 2,
      "name": "Empty",
      "level": 0
    },
    {
      "x": -6,
      "y": 7,
      "z": 2,
      "name": "Empty",
      "level": 0
    },
    {
      "x": -6,
      "y": 0,
      "z": 3,
      "name": "Empty",
      "level": 0
    },
    {
      "x": -6,
      "y": 1,
      "z": 3,
      "name": "Empty",
      "level": 0
    },
    {
      "x": -6,
      "y": 2,
      "z": 3,
      "name": "Empty",
      "level": 0
    },
    {
      "x": -6,
      "y": 3,
      "z": 3,
      "name": "Empty",
      "level": 0
    },
    {
      "x": -6,
      "y": 4,
      "z": 3,
      "name": "Empty",
      "level": 0
    },
    {
      "x": -6,
      "y": 5,
      "z": 3,
      "name": "Empty",
      "level": 0
    },
    {
      "x": -6,
      "y": 6,
      "z": 3,
      "name": "Empty",
      "level": 0
    },
    {
      "x": -6,
      "y": 7,
      "z": 3,
      "name": "Empty",
      "level": 0
    },
    {
      "x": -5,
      "y": 0,
      "z": -3,
      "name": "Empty",
      "level": 0
    },
    {
      "x": -5,
      "y": 6,
      "z": -3,
      "name": "Empty",
      "level": 0
    },
    {
      "x": -5,
      "y": 7,
      "z": -3,
      "name": "Empty",
      "level": 0
    },
    {
      "x": -5,
      "y": 8,
      "z": -3,
      "name": "Empty",
      "level": 0
    },
    {
      "x": -5,
      "y": 0,
      "z": -2,
      "name": "Empty",
      "level": 0
    },
    {
      "x": -5,
      "y": 1,
      "z": -2,
      "name": "Empty",
      "level": 0
    },
    {
      "x": -5,
      "y": 7,
      "z": -2,
      "name": "Empty",
      "level": 0
    },
    {
      "x": -5,
      "y": 8,
      "z": -2,
      "name": "Empty",
      "level": 0
    },
    {
      "x": -5,
      "y": 0,
      "z": -1,
      "name": "Empty",
      "level": 0
    },
    {
      "x": -5,
      "y": 1,
      "z": -1,
      "name": "Empty",
      "level": 0
    },
    {
      "x": -5,
      "y": 7,
      "z": -1,
      "name": "Empty",
      "level": 0
    },
    {
      "x": -5,
      "y": 8,
      "z": -1,
      "name": "Empty",
      "level": 0
    },
    {
      "x": -5,
      "y": 0,
      "z": 0,
      "name": "Empty",
      "level": 0
    },
    {
      "x": -5,
      "y": 1,
      "z": 0,
      "name": "Empty",
      "level": 0
    },
    {
      "x": -5,
      "y": 4,
      "z": 0,
      "name": "Empty",
      "level": 0
    },
    {
      "x": -5,
      "y": 7,
      "z": 0,
      "name": "Empty",
      "level": 0
    },
    {
      "x": -5,
      "y": 8,
      "z": 0,
      "name": "Empty",
      "level": 0
    },
    {
      "x": -5,
      "y": 0,
      "z": 1,
      "name": "Empty",
      "level": 0
    },
    {
      "x": -5,
      "y": 1,
      "z": 1,
      "name": "Empty",
      "level": 0
    },
    {
      "x": -5,
      "y": 2,
      "z": 1,
      "name": "Empty",
      "level": 0
    },
    {
      "x": -5,
      "y": 3,
      "z": 1,
      "name": "Empty",
      "level": 0
    },
    {
      "x": -5,
      "y": 4,
      "z": 1,
      "name": "Empty",
      "level": 0
    },
    {
      "x": -5,
      "y": 7,
      "z": 1,
      "name": "Empty",
      "level": 0
    },
    {
      "x": -5,
      "y": 8,
      "z": 1,
      "name": "Empty",
      "level": 0
    },
    {
      "x": -5,
      "y": 0,
      "z": 2,
      "name": "Empty",
      "level": 0
    },
    {
      "x": -5,
      "y": 1,
      "z": 2,
      "name": "Empty",
      "level": 0
    },
    {
      "x": -5,
      "y": 2,
      "z": 2,
      "name": "Empty",
      "level": 0
    },
    {
      "x": -5,
      "y": 3,
      "z": 2,
      "name": "Empty",
      "level": 0
    },
    {
      "x": -5,
      "y": 4,
      "z": 2,
      "name": "Empty",
      "level": 0
    },
    {
      "x": -5,
      "y": 7,
      "z": 2,
      "name": "Empty",
      "level": 0
    },
    {
      "x": -5,
      "y": 8,
      "z": 2,
      "name": "Empty",
      "level": 0
    },
    {
      "x": -5,
      "y": 0,
      "z": 3,
      "name": "Empty",
      "level": 0
    },
    {
      "x": -5,
      "y": 1,
      "z": 3,
      "name": "Empty",
      "level": 0
    },
    {
      "x": -5,
      "y": 2,
      "z": 3,
      "name": "Empty",
      "level": 0
    },
    {
      "x": -5,
      "y": 3,
      "z": 3,
      "name": "Empty",
      "level": 0
    },
    {
      "x": -5,
      "y": 4,
      "z": 3,
      "name": "Empty",
      "level": 0
    },
    {
      "x": -5,
      "y": 5,
      "z": 3,
      "name": "Empty",
      "level": 0
    },
    {
      "x": -5,
      "y": 6,
      "z": 3,
      "name": "Empty",
      "level": 0
    },
    {
      "x": -5,
      "y": 7,
      "z": 3,
      "name": "Empty",
      "level": 0
    },
    {
      "x": -5,
      "y": 8,
      "z": 3,
      "name": "Empty",
      "level": 0
    },
    {
      "x": -4,
      "y": 0,
      "z": -3,
      "name": "Empty",
      "level": 0
    },
    {
      "x": -4,
      "y": 6,
      "z": -3,
      "name": "Empty",
      "level": 0
    },
    {
      "x": -4,
      "y": 7,
      "z": -3,
      "name": "Empty",
      "level": 0
    },
    {
      "x": -4,
      "y": 8,
      "z": -3,
      "name": "Empty",
      "level": 0
    },
    {
      "x": -4,
      "y": 9,
      "z": -3,
      "name": "Empty",
      "level": 0
    },
    {
      "x": -4,
      "y": 0,
      "z": -2,
      "name": "Empty",
      "level": 0
    },
    {
      "x": -4,
      "y": 1,
      "z": -2,
      "name": "Empty",
      "level": 0
    },
    {
      "x": -4,
      "y": 7,
      "z": -2,
      "name": "Empty",
      "level": 0
    },
    {
      "x": -4,
      "y": 8,
      "z": -2,
      "name": "Empty",
      "level": 0
    },
    {
      "x": -4,
      "y": 9,
      "z": -2,
      "name": "Empty",
      "level": 0
    },
    {
      "x": -4,
      "y": 0,
      "z": -1,
      "name": "Empty",
      "level": 0
    },
    {
      "x": -4,
      "y": 1,
      "z": -1,
      "name": "Empty",
      "level": 0
    },
    {
      "x": -4,
      "y": 7,
      "z": -1,
      "name": "Empty",
      "level": 0
    },
    {
      "x": -4,
      "y": 8,
      "z": -1,
      "name": "Empty",
      "level": 0
    },
    {
      "x": -4,
      "y": 9,
      "z": -1,
      "name": "Empty",
      "level": 0
    },
    {
      "x": -4,
      "y": 0,
      "z": 0,
      "name": "Empty",
      "level": 0
    },
    {
      "x": -4,
      "y": 1,
      "z": 0,
      "name": "Empty",
      "level": 0
    },
    {
      "x": -4,
      "y": 4,
      "z": 0,
      "name": "Empty",
      "level": 0
    },
    {
      "x": -4,
      "y": 7,
      "z": 0,
      "name": "Empty",
      "level": 0
    },
    {
      "x": -4,
      "y": 8,
      "z": 0,
      "name": "Empty",
      "level": 0
    },
    {
      "x": -4,
      "y": 9,
      "z": 0,
      "name": "Empty",
      "level": 0
    },
    {
      "x": -4,
      "y": 0,
      "z": 1,
      "name": "Empty",
      "level": 0
    },
    {
      "x": -4,
      "y": 1,
      "z": 1,
      "name": "Empty",
      "level": 0
    },
    {
      "x": -4,
      "y": 2,
      "z": 1,
      "name": "Empty",
      "level": 0
    },
    {
      "x": -4,
      "y": 3,
      "z": 1,
      "name": "Empty",
      "level": 0
    },
    {
      "x": -4,
      "y": 4,
      "z": 1,
      "name": "Empty",
      "level": 0
    },
    {
      "x": -4,
      "y": 5,
      "z": 1,
      "name": "Empty",
      "level": 0
    },
    {
      "x": -4,
      "y": 6,
      "z": 1,
      "name": "Empty",
      "level": 0
    },
    {
      "x": -4,
      "y": 7,
      "z": 1,
      "name": "Empty",
      "level": 0
    },
    {
      "x": -4,
      "y": 8,
      "z": 1,
      "name": "Empty",
      "level": 0
    },
    {
      "x": -4,
      "y": 9,
      "z": 1,
      "name": "Empty",
      "level": 0
    },
    {
      "x": -4,
      "y": 10,
      "z": 1,
      "name": "Empty",
      "level": 0
    },
    {
      "x": -4,
      "y": 11,
      "z": 1,
      "name": "Empty",
      "level": 0
    },
    {
      "x": -4,
      "y": 12,
      "z": 1,
      "name": "Empty",
      "level": 0
    },
    {
      "x": -4,
      "y": 0,
      "z": 2,
      "name": "Empty",
      "level": 0
    },
    {
      "x": -4,
      "y": 1,
      "z": 2,
      "name": "Empty",
      "level": 0
    },
    {
      "x": -4,
      "y": 2,
      "z": 2,
      "name": "Empty",
      "level": 0
    },
    {
      "x": -4,
      "y": 3,
      "z": 2,
      "name": "Empty",
      "level": 0
    },
    {
      "x": -4,
      "y": 4,
      "z": 2,
      "name": "Empty",
      "level": 0
    },
    {
      "x": -4,
      "y": 7,
      "z": 2,
      "name": "Empty",
      "level": 0
    },
    {
      "x": -4,
      "y": 8,
      "z": 2,
      "name": "Empty",
      "level": 0
    },
    {
      "x": -4,
      "y": 9,
      "z": 2,
      "name": "Empty",
      "level": 0
    },
    {
      "x": -4,
      "y": 0,
      "z": 3,
      "name": "Empty",
      "level": 0
    },
    {
      "x": -4,
      "y": 1,
      "z": 3,
      "name": "Empty",
      "level": 0
    },
    {
      "x": -4,
      "y": 2,
      "z": 3,
      "name": "Empty",
      "level": 0
    },
    {
      "x": -4,
      "y": 3,
      "z": 3,
      "name": "Empty",
      "level": 0
    },
    {
      "x": -4,
      "y": 4,
      "z": 3,
      "name": "Empty",
      "level": 0
    },
    {
      "x": -4,
      "y": 5,
      "z": 3,
      "name": "Empty",
      "level": 0
    },
    {
      "x": -4,
      "y": 6,
      "z": 3,
      "name": "Empty",
      "level": 0
    },
    {
      "x": -4,
      "y": 7,
      "z": 3,
      "name": "Empty",
      "level": 0
    },
    {
      "x": -4,
      "y": 8,
      "z": 3,
      "name": "Empty",
      "level": 0
    },
    {
      "x": -4,
      "y": 9,
      "z": 3,
      "name": "Empty",
      "level": 0
    },
    {
      "x": -3,
      "y": 0,
      "z": -3,
      "name": "Empty",
      "level": 0
    },
    {
      "x": -3,
      "y": 6,
      "z": -3,
      "name": "Empty",
      "level": 0
    },
    {
      "x": -3,
      "y": 7,
      "z": -3,
      "name": "Empty",
      "level": 0
    },
    {
      "x": -3,
      "y": 8,
      "z": -3,
      "name": "Empty",
      "level": 0
    },
    {
      "x": -3,
      "y": 9,
      "z": -3,
      "name": "Empty",
      "level": 0
    },
    {
      "x": -3,
      "y": 10,
      "z": -3,
      "name": "Empty",
      "level": 0
    },
    {
      "x": -3,
      "y": 0,
      "z": -2,
      "name": "Empty",
      "level": 0
    },
    {
      "x": -3,
      "y": 1,
      "z": -2,
      "name": "Empty",
      "level": 0
    },
    {
      "x": -3,
      "y": 7,
      "z": -2,
      "name": "Empty",
      "level": 0
    },
    {
      "x": -3,
      "y": 8,
      "z": -2,
      "name": "Empty",
      "level": 0
    },
    {
      "x": -3,
      "y": 9,
      "z": -2,
      "name": "Empty",
      "level": 0
    },
    {
      "x": -3,
      "y": 10,
      "z": -2,
      "name": "Empty",
      "level": 0
    },
    {
      "x": -3,
      "y": 0,
      "z": -1,
      "name": "Empty",
      "level": 0
    },
    {
      "x": -3,
      "y": 1,
      "z": -1,
      "name": "Empty",
      "level": 0
    },
    {
      "x": -3,
      "y": 7,
      "z": -1,
      "name": "Empty",
      "level": 0
    },
    {
      "x": -3,
      "y": 8,
      "z": -1,
      "name": "Empty",
      "level": 0
    },
    {
      "x": -3,
      "y": 9,
      "z": -1,
      "name": "Empty",
      "level": 0
    },
    {
      "x": -3,
      "y": 10,
      "z": -1,
      "name": "Empty",
      "level": 0
    },
    {
      "x": -3,
      "y": 0,
      "z": 0,
      "name": "Empty",
      "level": 0
    },
    {
      "x": -3,
      "y": 1,
      "z": 0,
      "name": "Empty",
      "level": 0
    },
    {
      "x": -3,
      "y": 4,
      "z": 0,
      "name": "Empty",
      "level": 0
    },
    {
      "x": -3,
      "y": 7,
      "z": 0,
      "name": "Empty",
      "level": 0
    },
    {
      "x": -3,
      "y": 8,
      "z": 0,
      "name": "Empty",
      "level": 0
    },
    {
      "x": -3,
      "y": 9,
      "z": 0,
      "name": "Empty",
      "level": 0
    },
    {
      "x": -3,
      "y": 10,
      "z": 0,
      "name": "Empty",
      "level": 0
    },
    {
      "x": -3,
      "y": 0,
      "z": 1,
      "name": "Empty",
      "level": 0
    },
    {
      "x": -3,
      "y": 1,
      "z": 1,
      "name": "Empty",
      "level": 0
    },
    {
      "x": -3,
      "y": 2,
      "z": 1,
      "name": "Empty",
      "level": 0
    },
    {
      "x": -3,
      "y": 3,
      "z": 1,
      "name": "Empty",
      "level": 0
    },
    {
      "x": -3,
      "y": 4,
      "z": 1,
      "name": "Empty",
      "level": 0
    },
    {
      "x": -3,
      "y": 5,
      "z": 1,
      "name": "Empty",
      "level": 0
    },
    {
      "x": -3,
      "y": 6,
      "z": 1,
      "name": "Empty",
      "level": 0
    },
    {
      "x": -3,
      "y": 7,
      "z": 1,
      "name": "Empty",
      "level": 0
    },
    {
      "x": -3,
      "y": 8,
      "z": 1,
      "name": "Empty",
      "level": 0
    },
    {
      "x": -3,
      "y": 9,
      "z": 1,
      "name": "Empty",
      "level": 0
    },
    {
      "x": -3,
      "y": 10,
      "z": 1,
      "name": "Empty",
      "level": 0
    },
    {
      "x": -3,
      "y": 11,
      "z": 1,
      "name": "Empty",
      "level": 0
    },
    {
      "x": -3,
      "y": 12,
      "z": 1,
      "name": "Empty",
      "level": 0
    },
    {
      "x": -3,
      "y": 0,
      "z": 2,
      "name": "Empty",
      "level": 0
    },
    {
      "x": -3,
      "y": 1,
      "z": 2,
      "name": "Empty",
      "level": 0
    },
    {
      "x": -3,
      "y": 2,
      "z": 2,
      "name": "Empty",
      "level": 0
    },
    {
      "x": -3,
      "y": 3,
      "z": 2,
      "name": "Empty",
      "level": 0
    },
    {
      "x": -3,
      "y": 4,
      "z": 2,
      "name": "Empty",
      "level": 0
    },
    {
      "x": -3,
      "y": 7,
      "z": 2,
      "name": "Empty",
      "level": 0
    },
    {
      "x": -3,
      "y": 8,
      "z": 2,
      "name": "Empty",
      "level": 0
    },
    {
      "x": -3,
      "y": 9,
      "z": 2,
      "name": "Empty",
      "level": 0
    },
    {
      "x": -3,
      "y": 10,
      "z": 2,
      "name": "Empty",
      "level": 0
    },
    {
      "x": -3,
      "y": 0,
      "z": 3,
      "name": "Empty",
      "level": 0
    },
    {
      "x": -3,
      "y": 1,
      "z": 3,
      "name": "Empty",
      "level": 0
    },
    {
      "x": -3,
      "y": 2,
      "z": 3,
      "name": "Empty",
      "level": 0
    },
    {
      "x": -3,
      "y": 3,
      "z": 3,
      "name": "Empty",
      "level": 0
    },
    {
      "x": -3,
      "y": 4,
      "z": 3,
      "name": "Empty",
      "level": 0
    },
    {
      "x": -3,
      "y": 5,
      "z": 3,
      "name": "Empty",
      "level": 0
    },
    {
      "x": -3,
      "y": 6,
      "z": 3,
      "name": "Empty",
      "level": 0
    },
    {
      "x": -3,
      "y": 7,
      "z": 3,
      "name": "Empty",
      "level": 0
    },
    {
      "x": -3,
      "y": 8,
      "z": 3,
      "name": "Empty",
      "level": 0
    },
    {
      "x": -3,
      "y": 9,
      "z": 3,
      "name": "Empty",
      "level": 0
    },
    {
      "x": -3,
      "y": 10,
      "z": 3,
      "name": "Empty",
      "level": 0
    },
    {
      "x": -2,
      "y": 0,
      "z": -3,
      "name": "Empty",
      "level": 0
    },
    {
      "x": -2,
      "y": 6,
      "z": -3,
      "name": "Empty",
      "level": 0
    },
    {
      "x": -2,
      "y": 7,
      "z": -3,
      "name": "Empty",
      "level": 0
    },
    {
      "x": -2,
      "y": 8,
      "z": -3,
      "name": "Empty",
      "level": 0
    },
    {
      "x": -2,
      "y": 9,
      "z": -3,
      "name": "Empty",
      "level": 0
    },
    {
      "x": -2,
      "y": 10,
      "z": -3,
      "name": "Empty",
      "level": 0
    },
    {
      "x": -2,
      "y": 11,
      "z": -3,
      "name": "Empty",
      "level": 0
    },
    {
      "x": -2,
      "y": 0,
      "z": -2,
      "name": "Empty",
      "level": 0
    },
    {
      "x": -2,
      "y": 7,
      "z": -2,
      "name": "Empty",
      "level": 0
    },
    {
      "x": -2,
      "y": 8,
      "z": -2,
      "name": "Empty",
      "level": 0
    },
    {
      "x": -2,
      "y": 9,
      "z": -2,
      "name": "Empty",
      "level": 0
    },
    {
      "x": -2,
      "y": 10,
      "z": -2,
      "name": "Empty",
      "level": 0
    },
    {
      "x": -2,
      "y": 11,
      "z": -2,
      "name": "Empty",
      "level": 0
    },
    {
      "x": -2,
      "y": 0,
      "z": -1,
      "name": "Empty",
      "level": 0
    },
    {
      "x": -2,
      "y": 1,
      "z": -1,
      "name": "Empty",
      "level": 0
    },
    {
      "x": -2,
      "y": 7,
      "z": -1,
      "name": "Empty",
      "level": 0
    },
    {
      "x": -2,
      "y": 8,
      "z": -1,
      "name": "Empty",
      "level": 0
    },
    {
      "x": -2,
      "y": 9,
      "z": -1,
      "name": "Empty",
      "level": 0
    },
    {
      "x": -2,
      "y": 10,
      "z": -1,
      "name": "Empty",
      "level": 0
    },
    {
      "x": -2,
      "y": 11,
      "z": -1,
      "name": "Empty",
      "level": 0
    },
    {
      "x": -2,
      "y": 0,
      "z": 0,
      "name": "Empty",
      "level": 0
    },
    {
      "x": -2,
      "y": 1,
      "z": 0,
      "name": "Empty",
      "level": 0
    },
    {
      "x": -2,
      "y": 4,
      "z": 0,
      "name": "Empty",
      "level": 0
    },
    {
      "x": -2,
      "y": 7,
      "z": 0,
      "name": "Empty",
      "level": 0
    },
    {
      "x": -2,
      "y": 8,
      "z": 0,
      "name": "Empty",
      "level": 0
    },
    {
      "x": -2,
      "y": 9,
      "z": 0,
      "name": "Empty",
      "level": 0
    },
    {
      "x": -2,
      "y": 10,
      "z": 0,
      "name": "Empty",
      "level": 0
    },
    {
      "x": -2,
      "y": 11,
      "z": 0,
      "name": "Empty",
      "level": 0
    },
    {
      "x": -2,
      "y": 0,
      "z": 1,
      "name": "Empty",
      "level": 0
    },
    {
      "x": -2,
      "y": 1,
      "z": 1,
      "name": "Empty",
      "level": 0
    },
    {
      "x": -2,
      "y": 2,
      "z": 1,
      "name": "Empty",
      "level": 0
    },
    {
      "x": -2,
      "y": 3,
      "z": 1,
      "name": "Empty",
      "level": 0
    },
    {
      "x": -2,
      "y": 4,
      "z": 1,
      "name": "Empty",
      "level": 0
    },
    {
      "x": -2,
      "y": 7,
      "z": 1,
      "name": "Empty",
      "level": 0
    },
    {
      "x": -2,
      "y": 8,
      "z": 1,
      "name": "Empty",
      "level": 0
    },
    {
      "x": -2,
      "y": 9,
      "z": 1,
      "name": "Empty",
      "level": 0
    },
    {
      "x": -2,
      "y": 10,
      "z": 1,
      "name": "Empty",
      "level": 0
    },
    {
      "x": -2,
      "y": 11,
      "z": 1,
      "name": "Empty",
      "level": 0
    },
    {
      "x": -2,
      "y": 0,
      "z": 2,
      "name": "Empty",
      "level": 0
    },
    {
      "x": -2,
      "y": 1,
      "z": 2,
      "name": "Empty",
      "level": 0
    },
    {
      "x": -2,
      "y": 2,
      "z": 2,
      "name": "Empty",
      "level": 0
    },
    {
      "x": -2,
      "y": 3,
      "z": 2,
      "name": "Empty",
      "level": 0
    },
    {
      "x": -2,
      "y": 4,
      "z": 2,
      "name": "Empty",
      "level": 0
    },
    {
      "x": -2,
      "y": 7,
      "z": 2,
      "name": "Empty",
      "level": 0
    },
    {
      "x": -2,
      "y": 8,
      "z": 2,
      "name": "Empty",
      "level": 0
    },
    {
      "x": -2,
      "y": 9,
      "z": 2,
      "name": "Empty",
      "level": 0
    },
    {
      "x": -2,
      "y": 10,
      "z": 2,
      "name": "Empty",
      "level": 0
    },
    {
      "x": -2,
      "y": 11,
      "z": 2,
      "name": "Empty",
      "level": 0
    },
    {
      "x": -2,
      "y": 0,
      "z": 3,
      "name": "Empty",
      "level": 0
    },
    {
      "x": -2,
      "y": 1,
      "z": 3,
      "name": "Empty",
      "level": 0
    },
    {
      "x": -2,
      "y": 2,
      "z": 3,
      "name": "Empty",
      "level": 0
    },
    {
      "x": -2,
      "y": 3,
      "z": 3,
      "name": "Empty",
      "level": 0
    },
    {
      "x": -2,
      "y": 4,
      "z": 3,
      "name": "Empty",
      "level": 0
    },
    {
      "x": -2,
      "y": 5,
      "z": 3,
      "name": "Empty",
      "level": 0
    },
    {
      "x": -2,
      "y": 6,
      "z": 3,
      "name": "Empty",
      "level": 0
    },
    {
      "x": -2,
      "y": 7,
      "z": 3,
      "name": "Empty",
      "level": 0
    },
    {
      "x": -2,
      "y": 8,
      "z": 3,
      "name": "Empty",
      "level": 0
    },
    {
      "x": -2,
      "y": 9,
      "z": 3,
      "name": "Empty",
      "level": 0
    },
    {
      "x": -2,
      "y": 10,
      "z": 3,
      "name": "Empty",
      "level": 0
    },
    {
      "x": -2,
      "y": 11,
      "z": 3,
      "name": "Empty",
      "level": 0
    },
    {
      "x": -1,
      "y": 0,
      "z": -3,
      "name": "Empty",
      "level": 0
    },
    {
      "x": -1,
      "y": 6,
      "z": -3,
      "name": "Empty",
      "level": 0
    },
    {
      "x": -1,
      "y": 7,
      "z": -3,
      "name": "Empty",
      "level": 0
    },
    {
      "x": -1,
      "y": 8,
      "z": -3,
      "name": "Empty",
      "level": 0
    },
    {
      "x": -1,
      "y": 9,
      "z": -3,
      "name": "Empty",
      "level": 0
    },
    {
      "x": -1,
      "y": 10,
      "z": -3,
      "name": "Empty",
      "level": 0
    },
    {
      "x": -1,
      "y": 11,
      "z": -3,
      "name": "Empty",
      "level": 0
    },
    {
      "x": -1,
      "y": 0,
      "z": -2,
      "name": "Empty",
      "level": 0
    },
    {
      "x": -1,
      "y": 7,
      "z": -2,
      "name": "Empty",
      "level": 0
    },
    {
      "x": -1,
      "y": 8,
      "z": -2,
      "name": "Empty",
      "level": 0
    },
    {
      "x": -1,
      "y": 9,
      "z": -2,
      "name": "Empty",
      "level": 0
    },
    {
      "x": -1,
      "y": 10,
      "z": -2,
      "name": "Empty",
      "level": 0
    },
    {
      "x": -1,
      "y": 11,
      "z": -2,
      "name": "Empty",
      "level": 0
    },
    {
      "x": -1,
      "y": 0,
      "z": -1,
      "name": "Empty",
      "level": 0
    },
    {
      "x": -1,
      "y": 7,
      "z": -1,
      "name": "Empty",
      "level": 0
    },
    {
      "x": -1,
      "y": 8,
      "z": -1,
      "name": "Empty",
      "level": 0
    },
    {
      "x": -1,
      "y": 9,
      "z": -1,
      "name": "Empty",
      "level": 0
    },
    {
      "x": -1,
      "y": 10,
      "z": -1,
      "name": "Empty",
      "level": 0
    },
    {
      "x": -1,
      "y": 11,
      "z": -1,
      "name": "Empty",
      "level": 0
    },
    {
      "x": -1,
      "y": 0,
      "z": 0,
      "name": "Empty",
      "level": 0
    },
    {
      "x": -1,
      "y": 7,
      "z": 0,
      "name": "Empty",
      "level": 0
    },
    {
      "x": -1,
      "y": 8,
      "z": 0,
      "name": "Empty",
      "level": 0
    },
    {
      "x": -1,
      "y": 9,
      "z": 0,
      "name": "Empty",
      "level": 0
    },
    {
      "x": -1,
      "y": 10,
      "z": 0,
      "name": "Empty",
      "level": 0
    },
    {
      "x": -1,
      "y": 11,
      "z": 0,
      "name": "Empty",
      "level": 0
    },
    {
      "x": -1,
      "y": 0,
      "z": 1,
      "name": "Empty",
      "level": 0
    },
    {
      "x": -1,
      "y": 7,
      "z": 1,
      "name": "Empty",
      "level": 0
    },
    {
      "x": -1,
      "y": 8,
      "z": 1,
      "name": "Empty",
      "level": 0
    },
    {
      "x": -1,
      "y": 9,
      "z": 1,
      "name": "Empty",
      "level": 0
    },
    {
      "x": -1,
      "y": 10,
      "z": 1,
      "name": "Empty",
      "level": 0
    },
    {
      "x": -1,
      "y": 11,
      "z": 1,
      "name": "Empty",
      "level": 0
    },
    {
      "x": -1,
      "y": 0,
      "z": 2,
      "name": "Empty",
      "level": 0
    },
    {
      "x": -1,
      "y": 7,
      "z": 2,
      "name": "Empty",
      "level": 0
    },
    {
      "x": -1,
      "y": 8,
      "z": 2,
      "name": "Empty",
      "level": 0
    },
    {
      "x": -1,
      "y": 9,
      "z": 2,
      "name": "Empty",
      "level": 0
    },
    {
      "x": -1,
      "y": 10,
      "z": 2,
      "name": "Empty",
      "level": 0
    },
    {
      "x": -1,
      "y": 11,
      "z": 2,
      "name": "Empty",
      "level": 0
    },
    {
      "x": -1,
      "y": 0,
      "z": 3,
      "name": "Empty",
      "level": 0
    },
    {
      "x": -1,
      "y": 1,
      "z": 3,
      "name": "Empty",
      "level": 0
    },
    {
      "x": -1,
      "y": 2,
      "z": 3,
      "name": "Empty",
      "level": 0
    },
    {
      "x": -1,
      "y": 3,
      "z": 3,
      "name": "Empty",
      "level": 0
    },
    {
