{
  "version": 8,
  "blockIdVersion": 11,
  "anchorX": 0,
  "anchorY": 0,
  "anchorZ": 0,
  "blocks": [
    {
      "x": -10,
      "y": 0,
      "z": -8,
      "name": "Cloth_Block_Wool_Blue_Light"
    },
    {
      "x": -10,
      "y": 1,
      "z": -8,
      "name": "Cloth_Block_Wool_Blue_Light"
    },
    {
      "x": -10,
      "y": 2,
      "z": -8,
      "name": "Cloth_Block_Wool_Blue_Light"
    },
    {
      "x": -10,
      "y": 0,
      "z": -7,
      "name": "Cloth_Block_Wool_Blue_Light"
    },
    {
      "x": -10,
      "y": 1,
      "z": -7,
      "name": "Cloth_Block_Wool_Blue_Light"
    },
    {
      "x": -10,
      "y": 2,
      "z": -7,
      "name": "Cloth_Block_Wool_Blue_Light"
    },
    {
      "x": -10,
      "y": 3,
      "z": -7,
      "name": "Cloth_Block_Wool_Blue_Light"
    },
    {
      "x": -10,
      "y": 0,
      "z": -6,
      "name": "Cloth_Block_Wool_Blue_Light"
    },
    {
      "x": -10,
      "y": 1,
      "z": -6,
      "name": "Cloth_Block_Wool_Blue_Light"
    },
    {
      "x": -10,
      "y": 2,
      "z": -6,
      "name": "Cloth_Block_Wool_Blue_Light"
    },
    {
      "x": -10,
      "y": 3,
      "z": -6,
      "name": "Cloth_Block_Wool_Blue_Light"
    },
    {
      "x": -10,
      "y": 0,
      "z": -5,
      "name": "Cloth_Block_Wool_Blue_Light"
    },
    {
      "x": -10,
      "y": 1,
      "z": -5,
      "name": "Cloth_Block_Wool_Blue_Light"
    },
    {
      "x": -10,
      "y": 2,
      "z": -5,
      "name": "Cloth_Block_Wool_Blue_Light"
    },
    {
      "x": -10,
      "y": 3,
      "z": -5,
      "name": "Cloth_Block_Wool_Blue_Light"
    },
    {
      "x": -10,
      "y": 0,
      "z": -4,
      "name": "Cloth_Block_Wool_Blue_Light"
    },
    {
      "x": -10,
      "y": 1,
      "z": -4,
      "name": "Cloth_Block_Wool_Blue_Light"
    },
    {
      "x": -10,
      "y": 2,
      "z": -4,
      "name": "Cloth_Block_Wool_Blue_Light"
    },
    {
      "x": -10,
      "y": 3,
      "z": -4,
      "name": "Cloth_Block_Wool_Blue_Light"
    },
    {
      "x": -10,
      "y": 0,
      "z": -3,
      "name": "Cloth_Block_Wool_Blue_Light"
    },
    {
      "x": -10,
      "y": 1,
      "z": -3,
      "name": "Cloth_Block_Wool_Blue_Light"
    },
    {
      "x": -10,
      "y": 2,
      "z": -3,
      "name": "Cloth_Block_Wool_Blue_Light"
    },
    {
      "x": -10,
      "y": 3,
      "z": -3,
      "name": "Cloth_Block_Wool_Blue_Light"
    },
    {
      "x": -10,
      "y": 0,
      "z": -2,
      "name": "Cloth_Block_Wool_Blue_Light"
    },
    {
      "x": -10,
      "y": 1,
      "z": -2,
      "name": "Cloth_Block_Wool_Blue_Light"
    },
    {
      "x": -10,
      "y": 2,
      "z": -2,
      "name": "Cloth_Block_Wool_Blue_Light"
    },
    {
      "x": -10,
      "y": 3,
      "z": -2,
      "name": "Cloth_Block_Wool_Blue_Light"
    },
    {
      "x": -10,
      "y": 0,
      "z": -1,
      "name": "Cloth_Block_Wool_Blue_Light"
    },
    {
      "x": -10,
      "y": 1,
      "z": -1,
      "name": "Cloth_Block_Wool_Blue_Light"
    },
    {
      "x": -10,
      "y": 2,
      "z": -1,
      "name": "Cloth_Block_Wool_Blue_Light"
    },
    {
      "x": -10,
      "y": 3,
      "z": -1,
      "name": "Cloth_Block_Wool_Blue_Light"
    },
    {
      "x": -10,
      "y": 0,
      "z": 0,
      "name": "Cloth_Block_Wool_Blue_Light"
    },
    {
      "x": -10,
      "y": 1,
      "z": 0,
      "name": "Cloth_Block_Wool_Blue_Light"
    },
    {
      "x": -10,
      "y": 2,
      "z": 0,
      "name": "Cloth_Block_Wool_Blue_Light"
    },
    {
      "x": -10,
      "y": 3,
      "z": 0,
      "name": "Cloth_Block_Wool_Blue_Light"
    },
    {
      "x": -10,
      "y": 0,
      "z": 1,
      "name": "Cloth_Block_Wool_Blue_Light"
    },
    {
      "x": -10,
      "y": 1,
      "z": 1,
      "name": "Cloth_Block_Wool_Blue_Light"
    },
    {
      "x": -10,
      "y": 2,
      "z": 1,
      "name": "Cloth_Block_Wool_Blue_Light"
    },
    {
      "x": -10,
      "y": 3,
      "z": 1,
      "name": "Cloth_Block_Wool_Blue_Light"
    },
    {
      "x": -10,
      "y": 4,
      "z": 1,
      "name": "Cloth_Block_Wool_Blue_Light"
    },
    {
      "x": -10,
      "y": 0,
      "z": 2,
      "name": "Cloth_Block_Wool_Blue_Light"
    },
    {
      "x": -10,
      "y": 1,
      "z": 2,
      "name": "Cloth_Block_Wool_Blue_Light"
    },
    {
      "x": -10,
      "y": 2,
      "z": 2,
      "name": "Cloth_Block_Wool_Blue_Light"
    },
    {
      "x": -10,
      "y": 3,
      "z": 2,
      "name": "Cloth_Block_Wool_Blue_Light"
    },
    {
      "x": -10,
      "y": 0,
      "z": 3,
      "name": "Cloth_Block_Wool_Blue_Light"
    },
    {
      "x": -10,
      "y": 1,
      "z": 3,
      "name": "Cloth_Block_Wool_Blue_Light"
    },
    {
      "x": -10,
      "y": 2,
      "z": 3,
      "name": "Cloth_Block_Wool_Blue_Light"
    },
    {
      "x": -10,
      "y": 3,
      "z": 3,
      "name": "Cloth_Block_Wool_Blue_Light"
    },
    {
      "x": -10,
      "y": 0,
      "z": 4,
      "name": "Cloth_Block_Wool_Blue_Light"
    },
    {
      "x": -10,
      "y": 1,
      "z": 4,
      "name": "Cloth_Block_Wool_Blue_Light"
    },
    {
      "x": -10,
      "y": 2,
      "z": 4,
      "name": "Cloth_Block_Wool_Blue_Light"
    },
    {
      "x": -10,
      "y": 3,
      "z": 4,
      "name": "Cloth_Block_Wool_Blue_Light"
    },
    {
      "x": -10,
      "y": 0,
      "z": 5,
      "name": "Cloth_Block_Wool_Blue_Light"
    },
    {
      "x": -10,
      "y": 1,
      "z": 5,
      "name": "Cloth_Block_Wool_Blue_Light"
    },
    {
      "x": -10,
      "y": 2,
      "z": 5,
      "name": "Cloth_Block_Wool_Blue_Light"
    },
    {
      "x": -10,
      "y": 3,
      "z": 5,
      "name": "Cloth_Block_Wool_Blue_Light"
    },
    {
      "x": -10,
      "y": 0,
      "z": 6,
      "name": "Cloth_Block_Wool_Blue_Light"
    },
    {
      "x": -10,
      "y": 1,
      "z": 6,
      "name": "Cloth_Block_Wool_Blue_Light"
    },
    {
      "x": -10,
      "y": 2,
      "z": 6,
      "name": "Cloth_Block_Wool_Blue_Light"
    },
    {
      "x": -10,
      "y": 3,
      "z": 6,
      "name": "Cloth_Block_Wool_Blue_Light"
    },
    {
      "x": -10,
      "y": 0,
      "z": 7,
      "name": "Cloth_Block_Wool_Blue_Light"
    },
    {
      "x": -10,
      "y": 1,
      "z": 7,
      "name": "Cloth_Block_Wool_Blue_Light"
    },
    {
      "x": -10,
      "y": 2,
      "z": 7,
      "name": "Cloth_Block_Wool_Blue_Light"
    },
    {
      "x": -10,
      "y": 3,
      "z": 7,
      "name": "Cloth_Block_Wool_Blue_Light"
    },
    {
      "x": -10,
      "y": 0,
      "z": 8,
      "name": "Cloth_Block_Wool_Blue_Light"
    },
    {
      "x": -10,
      "y": 1,
      "z": 8,
      "name": "Cloth_Block_Wool_Blue_Light"
    },
    {
      "x": -10,
      "y": 2,
      "z": 8,
      "name": "Cloth_Block_Wool_Blue_Light"
    },
    {
      "x": -10,
      "y": 3,
      "z": 8,
      "name": "Cloth_Block_Wool_Blue_Light"
    },
    {
      "x": -10,
      "y": 0,
      "z": 9,
      "name": "Cloth_Block_Wool_Blue_Light"
    },
    {
      "x": -10,
      "y": 1,
      "z": 9,
      "name": "Cloth_Block_Wool_Blue_Light"
    },
    {
      "x": -10,
      "y": 2,
      "z": 9,
      "name": "Cloth_Block_Wool_Blue_Light"
    },
    {
      "x": -10,
      "y": 3,
      "z": 9,
      "name": "Cloth_Block_Wool_Blue_Light"
    },
    {
      "x": -9,
      "y": 0,
      "z": -8,
      "name": "Cloth_Block_Wool_Blue_Light"
    },
    {
      "x": -9,
      "y": 1,
      "z": -8,
      "name": "Cloth_Block_Wool_Blue_Light"
    },
    {
      "x": -9,
      "y": 2,
      "z": -8,
      "name": "Cloth_Block_Wool_Blue_Light"
    },
    {
      "x": -9,
      "y": 3,
      "z": -8,
      "name": "Cloth_Block_Wool_Blue_Light"
    },
    {
      "x": -9,
      "y": 0,
      "z": -7,
      "name": "Cloth_Block_Wool_Blue_Light"
    },
    {
      "x": -9,
      "y": 1,
      "z": -7,
      "name": "Cloth_Block_Wool_Blue_Light"
    },
    {
      "x": -9,
      "y": 2,
      "z": -7,
      "name": "Cloth_Block_Wool_Blue_Light"
    },
    {
      "x": -9,
      "y": 3,
      "z": -7,
      "name": "Cloth_Block_Wool_Blue_Light"
    },
    {
      "x": -9,
      "y": 0,
      "z": -6,
      "name": "Cloth_Block_Wool_Blue_Light"
    },
    {
      "x": -9,
      "y": 1,
      "z": -6,
      "name": "Cloth_Block_Wool_Blue_Light"
    },
    {
      "x": -9,
      "y": 2,
      "z": -6,
      "name": "Cloth_Block_Wool_Blue_Light"
    },
    {
      "x": -9,
      "y": 3,
      "z": -6,
      "name": "Cloth_Block_Wool_Blue_Light"
    },
    {
      "x": -9,
      "y": 0,
      "z": -5,
      "name": "Cloth_Block_Wool_Blue_Light"
    },
    {
      "x": -9,
      "y": 1,
      "z": -5,
      "name": "Cloth_Block_Wool_Blue_Light"
    },
    {
      "x": -9,
      "y": 2,
      "z": -5,
      "name": "Cloth_Block_Wool_Blue_Light"
    },
    {
      "x": -9,
      "y": 3,
      "z": -5,
      "name": "Cloth_Block_Wool_Blue_Light"
    },
    {
      "x": -9,
      "y": 0,
      "z": -4,
      "name": "Cloth_Block_Wool_Blue_Light"
    },
    {
      "x": -9,
      "y": 1,
      "z": -4,
      "name": "Cloth_Block_Wool_Blue_Light"
    },
    {
      "x": -9,
      "y": 2,
      "z": -4,
      "name": "Cloth_Block_Wool_Blue_Light"
    },
    {
      "x": -9,
      "y": 3,
      "z": -4,
      "name": "Cloth_Block_Wool_Blue_Light"
    },
    {
      "x": -9,
      "y": 0,
      "z": -3,
      "name": "Cloth_Block_Wool_Blue_Light"
    },
    {
      "x": -9,
      "y": 1,
      "z": -3,
      "name": "Cloth_Block_Wool_Blue_Light"
    },
    {
      "x": -9,
      "y": 2,
      "z": -3,
      "name": "Cloth_Block_Wool_Blue_Light"
    },
    {
      "x": -9,
      "y": 3,
      "z": -3,
      "name": "Cloth_Block_Wool_Blue_Light"
    },
    {
      "x": -9,
      "y": 0,
      "z": -2,
      "name": "Cloth_Block_Wool_Blue_Light"
    },
    {
      "x": -9,
      "y": 1,
      "z": -2,
      "name": "Cloth_Block_Wool_Blue_Light"
    },
    {
      "x": -9,
      "y": 2,
      "z": -2,
      "name": "Cloth_Block_Wool_Blue_Light"
    },
    {
      "x": -9,
      "y": 3,
      "z": -2,
      "name": "Cloth_Block_Wool_Blue_Light"
    },
    {
      "x": -9,
      "y": 0,
      "z": -1,
      "name": "Cloth_Block_Wool_Blue_Light"
    },
    {
      "x": -9,
      "y": 1,
      "z": -1,
      "name": "Cloth_Block_Wool_Blue_Light"
    },
    {
      "x": -9,
      "y": 2,
      "z": -1,
      "name": "Cloth_Block_Wool_Blue_Light"
    },
    {
      "x": -9,
      "y": 3,
      "z": -1,
      "name": "Cloth_Block_Wool_Blue_Light"
    },
    {
      "x": -9,
      "y": 0,
      "z": 0,
      "name": "Cloth_Block_Wool_Blue_Light"
    },
    {
      "x": -9,
      "y": 1,
      "z": 0,
      "name": "Cloth_Block_Wool_Blue_Light"
    },
    {
      "x": -9,
      "y": 2,
      "z": 0,
      "name": "Cloth_Block_Wool_Blue_Light"
    },
    {
      "x": -9,
      "y": 3,
      "z": 0,
      "name": "Cloth_Block_Wool_Blue_Light"
    },
    {
      "x": -9,
      "y": 0,
      "z": 1,
      "name": "Cloth_Block_Wool_Blue_Light"
    },
    {
      "x": -9,
      "y": 1,
      "z": 1,
      "name": "Cloth_Block_Wool_Blue_Light"
    },
    {
      "x": -9,
      "y": 2,
      "z": 1,
      "name": "Cloth_Block_Wool_Blue_Light"
    },
    {
      "x": -9,
      "y": 3,
      "z": 1,
      "name": "Cloth_Block_Wool_Blue_Light"
    },
    {
      "x": -9,
      "y": 0,
      "z": 2,
      "name": "Cloth_Block_Wool_Blue_Light"
    },
    {
      "x": -9,
      "y": 1,
      "z": 2,
      "name": "Cloth_Block_Wool_Blue_Light"
    },
    {
      "x": -9,
      "y": 2,
      "z": 2,
      "name": "Cloth_Block_Wool_Blue_Light"
    },
    {
      "x": -9,
      "y": 3,
      "z": 2,
      "name": "Cloth_Block_Wool_Blue_Light"
    },
    {
      "x": -9,
      "y": 0,
      "z": 3,
      "name": "Cloth_Block_Wool_Blue_Light"
    },
    {
      "x": -9,
      "y": 1,
      "z": 3,
      "name": "Cloth_Block_Wool_Blue_Light"
    },
    {
      "x": -9,
      "y": 2,
      "z": 3,
      "name": "Cloth_Block_Wool_Blue_Light"
    },
    {
      "x": -9,
      "y": 3,
      "z": 3,
      "name": "Cloth_Block_Wool_Blue_Light"
    },
    {
      "x": -9,
      "y": 0,
      "z": 4,
      "name": "Cloth_Block_Wool_Blue_Light"
    },
    {
      "x": -9,
      "y": 1,
      "z": 4,
      "name": "Cloth_Block_Wool_Blue_Light"
    },
    {
      "x": -9,
      "y": 2,
      "z": 4,
      "name": "Cloth_Block_Wool_Blue_Light"
    },
    {
      "x": -9,
      "y": 3,
      "z": 4,
      "name": "Cloth_Block_Wool_Blue_Light"
    },
    {
      "x": -9,
      "y": 0,
      "z": 5,
      "name": "Cloth_Block_Wool_Blue_Light"
    },
    {
      "x": -9,
      "y": 1,
      "z": 5,
      "name": "Cloth_Block_Wool_Blue_Light"
    },
    {
      "x": -9,
      "y": 2,
      "z": 5,
      "name": "Cloth_Block_Wool_Blue_Light"
    },
    {
      "x": -9,
      "y": 3,
      "z": 5,
      "name": "Cloth_Block_Wool_Blue_Light"
    },
    {
      "x": -9,
      "y": 0,
      "z": 6,
      "name": "Cloth_Block_Wool_Blue_Light"
    },
    {
      "x": -9,
      "y": 1,
      "z": 6,
      "name": "Cloth_Block_Wool_Blue_Light"
    },
    {
      "x": -9,
      "y": 2,
      "z": 6,
      "name": "Cloth_Block_Wool_Blue_Light"
    },
    {
      "x": -9,
      "y": 3,
      "z": 6,
      "name": "Cloth_Block_Wool_Blue_Light"
    },
    {
      "x": -9,
      "y": 0,
      "z": 7,
      "name": "Cloth_Block_Wool_Blue_Light"
    },
    {
      "x": -9,
      "y": 1,
      "z": 7,
      "name": "Cloth_Block_Wool_Blue_Light"
    },
    {
      "x": -9,
      "y": 2,
      "z": 7,
      "name": "Cloth_Block_Wool_Blue_Light"
    },
    {
      "x": -9,
      "y": 3,
      "z": 7,
      "name": "Cloth_Block_Wool_Blue_Light"
    },
    {
      "x": -9,
      "y": 0,
      "z": 8,
      "name": "Cloth_Block_Wool_Blue_Light"
    },
    {
      "x": -9,
      "y": 1,
      "z": 8,
      "name": "Cloth_Block_Wool_Blue_Light"
    },
    {
      "x": -9,
      "y": 2,
      "z": 8,
      "name": "Cloth_Block_Wool_Blue_Light"
    },
    {
      "x": -9,
      "y": 3,
      "z": 8,
      "name": "Cloth_Block_Wool_Blue_Light"
    },
    {
      "x": -9,
      "y": 0,
      "z": 9,
      "name": "Cloth_Block_Wool_Blue_Light"
    },
    {
      "x": -9,
      "y": 1,
      "z": 9,
      "name": "Cloth_Block_Wool_Blue_Light"
    },
    {
      "x": -9,
      "y": 2,
      "z": 9,
      "name": "Cloth_Block_Wool_Blue_Light"
    },
    {
      "x": -9,
      "y": 3,
      "z": 9,
      "name": "Cloth_Block_Wool_Blue_Light"
    },
    {
      "x": -8,
      "y": 0,
      "z": -8,
      "name": "Cloth_Block_Wool_Blue_Light"
    },
    {
      "x": -8,
      "y": 1,
      "z": -8,
      "name": "Cloth_Block_Wool_Blue_Light"
    },
    {
      "x": -8,
      "y": 2,
      "z": -8,
      "name": "Cloth_Block_Wool_Blue_Light"
    },
    {
      "x": -8,
      "y": 3,
      "z": -8,
      "name": "Cloth_Block_Wool_Blue_Light"
    },
    {
      "x": -8,
      "y": 0,
      "z": -7,
      "name": "Cloth_Block_Wool_Blue_Light"
    },
    {
      "x": -8,
      "y": 1,
      "z": -7,
      "name": "Cloth_Block_Wool_Blue_Light"
    },
    {
      "x": -8,
      "y": 2,
      "z": -7,
      "name": "Cloth_Block_Wool_Blue_Light"
    },
    {
      "x": -8,
      "y": 3,
      "z": -7,
      "name": "Cloth_Block_Wool_Blue_Light"
    },
    {
      "x": -8,
      "y": 0,
      "z": -6,
      "name": "Cloth_Block_Wool_Blue_Light"
    },
    {
      "x": -8,
      "y": 1,
      "z": -6,
      "name": "Cloth_Block_Wool_Blue_Light"
    },
    {
      "x": -8,
      "y": 2,
      "z": -6,
      "name": "Cloth_Block_Wool_Blue_Light"
    },
    {
      "x": -8,
      "y": 3,
      "z": -6,
      "name": "Cloth_Block_Wool_Blue_Light"
    },
    {
      "x": -8,
      "y": 0,
      "z": -5,
      "name": "Cloth_Block_Wool_Blue_Light"
    },
    {
      "x": -8,
      "y": 1,
      "z": -5,
      "name": "Cloth_Block_Wool_Blue_Light"
    },
    {
      "x": -8,
      "y": 2,
      "z": -5,
      "name": "Cloth_Block_Wool_Blue_Light"
    },
    {
      "x": -8,
      "y": 3,
      "z": -5,
      "name": "Cloth_Block_Wool_Blue_Light"
    },
    {
      "x": -8,
      "y": 0,
      "z": -4,
      "name": "Cloth_Block_Wool_Blue_Light"
    },
    {
      "x": -8,
      "y": 1,
      "z": -4,
      "name": "Cloth_Block_Wool_Blue_Light"
    },
    {
      "x": -8,
      "y": 2,
      "z": -4,
      "name": "Cloth_Block_Wool_Blue_Light"
    },
    {
      "x": -8,
      "y": 3,
      "z": -4,
      "name": "Cloth_Block_Wool_Blue_Light"
    },
    {
      "x": -8,
      "y": 0,
      "z": -3,
      "name": "Cloth_Block_Wool_Blue_Light"
    },
    {
      "x": -8,
      "y": 1,
      "z": -3,
      "name": "Cloth_Block_Wool_Blue_Light"
    },
    {
      "x": -8,
      "y": 2,
      "z": -3,
      "name": "Cloth_Block_Wool_Blue_Light"
    },
    {
      "x": -8,
      "y": 3,
      "z": -3,
      "name": "Cloth_Block_Wool_Blue_Light"
    },
    {
      "x": -8,
      "y": 0,
      "z": -2,
      "name": "Cloth_Block_Wool_Blue_Light"
    },
    {
      "x": -8,
      "y": 1,
      "z": -2,
      "name": "Cloth_Block_Wool_Blue_Light"
    },
    {
      "x": -8,
      "y": 2,
      "z": -2,
      "name": "Cloth_Block_Wool_Blue_Light"
    },
    {
      "x": -8,
      "y": 3,
      "z": -2,
      "name": "Cloth_Block_Wool_Blue_Light"
    },
    {
      "x": -8,
      "y": 0,
      "z": -1,
      "name": "Cloth_Block_Wool_Blue_Light"
    },
    {
      "x": -8,
      "y": 1,
      "z": -1,
      "name": "Cloth_Block_Wool_Blue_Light"
    },
    {
      "x": -8,
      "y": 2,
      "z": -1,
      "name": "Cloth_Block_Wool_Blue_Light"
    },
    {
      "x": -8,
      "y": 3,
      "z": -1,
      "name": "Cloth_Block_Wool_Blue_Light"
    },
    {
      "x": -8,
      "y": 4,
      "z": -1,
      "name": "Cloth_Block_Wool_Blue_Light"
    },
    {
      "x": -8,
      "y": 0,
      "z": 0,
      "name": "Cloth_Block_Wool_Blue_Light"
    },
    {
      "x": -8,
      "y": 1,
      "z": 0,
      "name": "Cloth_Block_Wool_Blue_Light"
    },
    {
      "x": -8,
      "y": 2,
      "z": 0,
      "name": "Cloth_Block_Wool_Blue_Light"
    },
    {
      "x": -8,
      "y": 3,
      "z": 0,
      "name": "Cloth_Block_Wool_Blue_Light"
    },
    {
      "x": -8,
      "y": 4,
      "z": 0,
      "name": "Cloth_Block_Wool_Blue_Light"
    },
    {
      "x": -8,
      "y": 0,
      "z": 1,
      "name": "Cloth_Block_Wool_Blue_Light"
    },
    {
      "x": -8,
      "y": 1,
      "z": 1,
      "name": "Cloth_Block_Wool_Blue_Light"
    },
    {
      "x": -8,
      "y": 2,
      "z": 1,
      "name": "Cloth_Block_Wool_Blue_Light"
    },
    {
      "x": -8,
      "y": 3,
      "z": 1,
      "name": "Cloth_Block_Wool_Blue_Light"
    },
    {
      "x": -8,
      "y": 4,
      "z": 1,
      "name": "Cloth_Block_Wool_Blue_Light"
    },
    {
      "x": -8,
      "y": 0,
      "z": 2,
      "name": "Cloth_Block_Wool_Blue_Light"
    },
    {
      "x": -8,
      "y": 1,
      "z": 2,
      "name": "Cloth_Block_Wool_Blue_Light"
    },
    {
      "x": -8,
      "y": 2,
      "z": 2,
      "name": "Cloth_Block_Wool_Blue_Light"
    },
    {
      "x": -8,
      "y": 3,
      "z": 2,
      "name": "Cloth_Block_Wool_Blue_Light"
    },
    {
      "x": -8,
      "y": 4,
      "z": 2,
      "name": "Cloth_Block_Wool_Blue_Light"
    },
    {
      "x": -8,
      "y": 0,
      "z": 3,
      "name": "Cloth_Block_Wool_Blue_Light"
    },
    {
      "x": -8,
      "y": 1,
      "z": 3,
      "name": "Cloth_Block_Wool_Blue_Light"
    },
    {
      "x": -8,
      "y": 2,
      "z": 3,
      "name": "Cloth_Block_Wool_Blue_Light"
    },
    {
      "x": -8,
      "y": 3,
      "z": 3,
      "name": "Cloth_Block_Wool_Blue_Light"
    },
    {
      "x": -8,
      "y": 4,
      "z": 3,
      "name": "Cloth_Block_Wool_Blue_Light"
    },
    {
      "x": -8,
      "y": 0,
      "z": 4,
      "name": "Cloth_Block_Wool_Blue_Light"
    },
    {
      "x": -8,
      "y": 1,
      "z": 4,
      "name": "Cloth_Block_Wool_Blue_Light"
    },
    {
      "x": -8,
      "y": 2,
      "z": 4,
      "name": "Cloth_Block_Wool_Blue_Light"
    },
    {
      "x": -8,
      "y": 3,
      "z": 4,
      "name": "Cloth_Block_Wool_Blue_Light"
    },
    {
      "x": -8,
      "y": 0,
      "z": 5,
      "name": "Cloth_Block_Wool_Blue_Light"
    },
    {
      "x": -8,
      "y": 1,
      "z": 5,
      "name": "Cloth_Block_Wool_Blue_Light"
    },
    {
      "x": -8,
      "y": 2,
      "z": 5,
      "name": "Cloth_Block_Wool_Blue_Light"
    },
    {
      "x": -8,
      "y": 3,
      "z": 5,
      "name": "Cloth_Block_Wool_Blue_Light"
    },
    {
      "x": -8,
      "y": 0,
      "z": 6,
      "name": "Cloth_Block_Wool_Blue_Light"
    },
    {
      "x": -8,
      "y": 1,
      "z": 6,
      "name": "Cloth_Block_Wool_Blue_Light"
    },
    {
      "x": -8,
      "y": 2,
      "z": 6,
      "name": "Cloth_Block_Wool_Blue_Light"
    },
    {
      "x": -8,
      "y": 3,
      "z": 6,
      "name": "Cloth_Block_Wool_Blue_Light"
    },
    {
      "x": -8,
      "y": 0,
      "z": 7,
      "name": "Cloth_Block_Wool_Blue_Light"
    },
    {
      "x": -8,
      "y": 1,
      "z": 7,
      "name": "Cloth_Block_Wool_Blue_Light"
    },
    {
      "x": -8,
      "y": 2,
      "z": 7,
      "name": "Cloth_Block_Wool_Blue_Light"
    },
    {
      "x": -8,
      "y": 3,
      "z": 7,
      "name": "Cloth_Block_Wool_Blue_Light"
    },
    {
      "x": -8,
      "y": 0,
      "z": 8,
      "name": "Cloth_Block_Wool_Blue_Light"
    },
    {
      "x": -8,
      "y": 1,
      "z": 8,
      "name": "Cloth_Block_Wool_Blue_Light"
    },
    {
      "x": -8,
      "y": 2,
      "z": 8,
      "name": "Cloth_Block_Wool_Blue_Light"
    },
    {
      "x": -8,
      "y": 3,
      "z": 8,
      "name": "Cloth_Block_Wool_Blue_Light"
    },
    {
      "x": -8,
      "y": 0,
      "z": 9,
      "name": "Cloth_Block_Wool_Blue_Light"
    },
    {
      "x": -8,
      "y": 1,
      "z": 9,
      "name": "Cloth_Block_Wool_Blue_Light"
    },
    {
      "x": -8,
      "y": 2,
      "z": 9,
      "name": "Cloth_Block_Wool_Blue_Light"
    },
    {
      "x": -8,
      "y": 3,
      "z": 9,
      "name": "Cloth_Block_Wool_Blue_Light"
    },
    {
      "x": -7,
      "y": 0,
      "z": -8,
      "name": "Cloth_Block_Wool_Blue_Light"
    },
    {
      "x": -7,
      "y": 1,
      "z": -8,
      "name": "Cloth_Block_Wool_Blue_Light"
    },
    {
      "x": -7,
      "y": 2,
      "z": -8,
      "name": "Cloth_Block_Wool_Blue_Light"
    },
    {
      "x": -7,
      "y": 3,
      "z": -8,
      "name": "Cloth_Block_Wool_Blue_Light"
    },
    {
      "x": -7,
      "y": 0,
      "z": -7,
      "name": "Cloth_Block_Wool_Blue_Light"
    },
    {
      "x": -7,
      "y": 1,
      "z": -7,
      "name": "Cloth_Block_Wool_Blue_Light"
    },
    {
      "x": -7,
      "y": 2,
      "z": -7,
      "name": "Cloth_Block_Wool_Blue_Light"
    },
    {
      "x": -7,
      "y": 3,
      "z": -7,
      "name": "Cloth_Block_Wool_Blue_Light"
    },
    {
      "x": -7,
      "y": 0,
      "z": -6,
      "name": "Cloth_Block_Wool_Blue_Light"
    },
    {
      "x": -7,
      "y": 1,
      "z": -6,
      "name": "Cloth_Block_Wool_Blue_Light"
    },
    {
      "x": -7,
      "y": 2,
      "z": -6,
      "name": "Cloth_Block_Wool_Blue_Light"
    },
    {
      "x": -7,
      "y": 3,
      "z": -6,
      "name": "Cloth_Block_Wool_Blue_Light"
    },
    {
      "x": -7,
      "y": 0,
      "z": -5,
      "name": "Cloth_Block_Wool_Blue_Light"
    },
    {
      "x": -7,
      "y": 1,
      "z": -5,
      "name": "Cloth_Block_Wool_Blue_Light"
    },
    {
      "x": -7,
      "y": 2,
      "z": -5,
      "name": "Cloth_Block_Wool_Blue_Light"
    },
    {
      "x": -7,
      "y": 3,
      "z": -5,
      "name": "Cloth_Block_Wool_Blue_Light"
    },
    {
      "x": -7,
      "y": 0,
      "z": -4,
      "name": "Cloth_Block_Wool_Blue_Light"
    },
    {
      "x": -7,
      "y": 1,
      "z": -4,
      "name": "Cloth_Block_Wool_Blue_Light"
    },
    {
      "x": -7,
      "y": 2,
      "z": -4,
      "name": "Cloth_Block_Wool_Blue_Light"
    },
    {
      "x": -7,
      "y": 3,
      "z": -4,
      "name": "Cloth_Block_Wool_Blue_Light"
    },
    {
      "x": -7,
      "y": 0,
      "z": -3,
      "name": "Cloth_Block_Wool_Blue_Light"
    },
    {
      "x": -7,
      "y": 1,
      "z": -3,
      "name": "Cloth_Block_Wool_Blue_Light"
    },
    {
      "x": -7,
      "y": 2,
      "z": -3,
      "name": "Cloth_Block_Wool_Blue_Light"
    },
    {
      "x": -7,
      "y": 3,
      "z": -3,
      "name": "Cloth_Block_Wool_Blue_Light"
    },
    {
      "x": -7,
      "y": 4,
      "z": -3,
      "name": "Cloth_Block_Wool_Blue_Light"
    },
    {
      "x": -7,
      "y": 0,
      "z": -2,
      "name": "Cloth_Block_Wool_Blue_Light"
    },
    {
      "x": -7,
      "y": 1,
      "z": -2,
      "name": "Cloth_Block_Wool_Blue_Light"
    },
    {
      "x": -7,
      "y": 2,
      "z": -2,
      "name": "Cloth_Block_Wool_Blue_Light"
    },
    {
      "x": -7,
      "y": 3,
      "z": -2,
      "name": "Cloth_Block_Wool_Blue_Light"
    },
    {
      "x": -7,
      "y": 4,
      "z": -2,
      "name": "Cloth_Block_Wool_Blue_Light"
    },
    {
      "x": -7,
      "y": 0,
      "z": -1,
      "name": "Cloth_Block_Wool_Blue_Light"
    },
    {
      "x": -7,
      "y": 1,
      "z": -1,
      "name": "Cloth_Block_Wool_Blue_Light"
    },
    {
      "x": -7,
      "y": 2,
      "z": -1,
      "name": "Cloth_Block_Wool_Blue_Light"
    },
    {
      "x": -7,
      "y": 3,
      "z": -1,
      "name": "Cloth_Block_Wool_Blue_Light"
    },
    {
      "x": -7,
      "y": 9,
      "z": -1,
      "name": "Cloth_Block_Wool_Orange"
    },
    {
      "x": -7,
      "y": 0,
      "z": 0,
      "name": "Cloth_Block_Wool_Blue_Light"
    },
    {
      "x": -7,
      "y": 1,
      "z": 0,
      "name": "Cloth_Block_Wool_Blue_Light"
    },
    {
      "x": -7,
      "y": 2,
      "z": 0,
      "name": "Cloth_Block_Wool_Blue_Light"
    },
    {
      "x": -7,
      "y": 8,
      "z": 0,
      "name": "Cloth_Block_Wool_Orange"
    },
    {
      "x": -7,
      "y": 9,
      "z": 0,
      "name": "Cloth_Block_Wool_Orange"
    },
    {
      "x": -7,
      "y": 0,
      "z": 1,
      "name": "Cloth_Block_Wool_Blue_Light"
    },
    {
      "x": -7,
      "y": 1,
      "z": 1,
      "name": "Cloth_Block_Wool_Blue_Light"
    },
    {
      "x": -7,
      "y": 2,
      "z": 1,
      "name": "Cloth_Block_Wool_Blue_Light"
    },
    {
      "x": -7,
      "y": 3,
      "z": 1,
      "name": "Cloth_Block_Wool_Blue_Light"
    },
    {
      "x": -7,
      "y": 9,
      "z": 1,
      "name": "Cloth_Block_Wool_Orange"
    },
    {
      "x": -7,
      "y": 0,
      "z": 2,
      "name": "Cloth_Block_Wool_Blue_Light"
    },
    {
      "x": -7,
      "y": 1,
      "z": 2,
      "name": "Cloth_Block_Wool_Blue_Light"
    },
    {
      "x": -7,
      "y": 2,
      "z": 2,
      "name": "Cloth_Block_Wool_Blue_Light"
    },
    {
      "x": -7,
      "y": 3,
      "z": 2,
      "name": "Cloth_Block_Wool_Blue_Light"
    },
    {
      "x": -7,
      "y": 4,
      "z": 2,
      "name": "Cloth_Block_Wool_Blue_Light"
    },
    {
      "x": -7,
      "y": 0,
      "z": 3,
      "name": "Cloth_Block_Wool_Blue_Light"
    },
    {
      "x": -7,
      "y": 1,
      "z": 3,
      "name": "Cloth_Block_Wool_Blue_Light"
    },
    {
      "x": -7,
      "y": 2,
      "z": 3,
      "name": "Cloth_Block_Wool_Blue_Light"
    },
    {
      "x": -7,
      "y": 3,
      "z": 3,
      "name": "Cloth_Block_Wool_Blue_Light"
    },
    {
      "x": -7,
      "y": 4,
      "z": 3,
      "name": "Cloth_Block_Wool_Blue_Light"
    },
    {
      "x": -7,
      "y": 0,
      "z": 4,
      "name": "Cloth_Block_Wool_Blue_Light"
    },
    {
      "x": -7,
      "y": 1,
      "z": 4,
      "name": "Cloth_Block_Wool_Blue_Light"
    },
    {
      "x": -7,
      "y": 2,
      "z": 4,
      "name": "Cloth_Block_Wool_Blue_Light"
    },
    {
      "x": -7,
      "y": 3,
      "z": 4,
      "name": "Cloth_Block_Wool_Blue_Light"
    },
    {
      "x": -7,
      "y": 4,
      "z": 4,
      "name": "Cloth_Block_Wool_Blue_Light"
    },
    {
      "x": -7,
      "y": 0,
      "z": 5,
      "name": "Cloth_Block_Wool_Blue_Light"
    },
    {
      "x": -7,
      "y": 1,
      "z": 5,
      "name": "Cloth_Block_Wool_Blue_Light"
    },
    {
      "x": -7,
      "y": 2,
      "z": 5,
      "name": "Cloth_Block_Wool_Blue_Light"
    },
    {
      "x": -7,
      "y": 3,
      "z": 5,
      "name": "Cloth_Block_Wool_Blue_Light"
    },
    {
      "x": -7,
      "y": 4,
      "z": 5,
      "name": "Cloth_Block_Wool_Blue_Light"
    },
    {
      "x": -7,
      "y": 0,
      "z": 6,
      "name": "Cloth_Block_Wool_Blue_Light"
    },
    {
      "x": -7,
      "y": 1,
      "z": 6,
      "name": "Cloth_Block_Wool_Blue_Light"
    },
    {
      "x": -7,
      "y": 2,
      "z": 6,
      "name": "Cloth_Block_Wool_Blue_Light"
    },
    {
      "x": -7,
      "y": 3,
      "z": 6,
      "name": "Cloth_Block_Wool_Blue_Light"
    },
    {
      "x": -7,
      "y": 0,
      "z": 7,
      "name": "Cloth_Block_Wool_Blue_Light"
    },
    {
      "x": -7,
      "y": 1,
      "z": 7,
      "name": "Cloth_Block_Wool_Blue_Light"
    },
    {
      "x": -7,
      "y": 2,
      "z": 7,
      "name": "Cloth_Block_Wool_Blue_Light"
    },
    {
      "x": -7,
      "y": 3,
      "z": 7,
      "name": "Cloth_Block_Wool_Blue_Light"
    },
    {
      "x": -7,
      "y": 0,
      "z": 8,
      "name": "Cloth_Block_Wool_Blue_Light"
    },
    {
      "x": -7,
      "y": 1,
      "z": 8,
      "name": "Cloth_Block_Wool_Blue_Light"
    },
    {
      "x": -7,
      "y": 2,
      "z": 8,
      "name": "Cloth_Block_Wool_Blue_Light"
    },
    {
      "x": -7,
      "y": 3,
      "z": 8,
      "name": "Cloth_Block_Wool_Blue_Light"
    },
    {
      "x": -7,
      "y": 0,
      "z": 9,
      "name": "Cloth_Block_Wool_Blue_Light"
    },
    {
      "x": -7,
      "y": 1,
      "z": 9,
      "name": "Cloth_Block_Wool_Blue_Light"
    },
    {
      "x": -7,
      "y": 2,
      "z": 9,
      "name": "Cloth_Block_Wool_Blue_Light"
    },
    {
      "x": -7,
      "y": 3,
      "z": 9,
      "name": "Cloth_Block_Wool_Blue_Light"
    },
    {
      "x": -6,
      "y": 0,
      "z": -8,
      "name": "Cloth_Block_Wool_Blue_Light"
    },
    {
      "x": -6,
      "y": 1,
      "z": -8,
      "name": "Cloth_Block_Wool_Blue_Light"
    },
    {
      "x": -6,
      "y": 2,
      "z": -8,
      "name": "Cloth_Block_Wool_Blue_Light"
    },
    {
      "x": -6,
      "y": 3,
      "z": -8,
      "name": "Cloth_Block_Wool_Blue_Light"
    },
    {
      "x": -6,
      "y": 0,
      "z": -7,
      "name": "Cloth_Block_Wool_Blue_Light"
    },
    {
      "x": -6,
      "y": 1,
      "z": -7,
      "name": "Cloth_Block_Wool_Blue_Light"
    },
    {
      "x": -6,
      "y": 2,
      "z": -7,
      "name": "Cloth_Block_Wool_Blue_Light"
    },
    {
      "x": -6,
      "y": 3,
      "z": -7,
      "name": "Cloth_Block_Wool_Blue_Light"
    },
    {
      "x": -6,
      "y": 0,
      "z": -6,
      "name": "Cloth_Block_Wool_Blue_Light"
    },
    {
      "x": -6,
      "y": 1,
      "z": -6,
      "name": "Cloth_Block_Wool_Blue_Light"
    },
    {
      "x": -6,
      "y": 2,
      "z": -6,
      "name": "Cloth_Block_Wool_Blue_Light"
    },
    {
      "x": -6,
      "y": 3,
      "z": -6,
      "name": "Cloth_Block_Wool_Blue_Light"
    },
    {
      "x": -6,
      "y": 0,
      "z": -5,
      "name": "Cloth_Block_Wool_Blue_Light"
    },
    {
      "x": -6,
      "y": 1,
      "z": -5,
      "name": "Cloth_Block_Wool_Blue_Light"
    },
    {
      "x": -6,
      "y": 2,
      "z": -5,
      "name": "Cloth_Block_Wool_Blue_Light"
    },
    {
      "x": -6,
      "y": 3,
      "z": -5,
      "name": "Cloth_Block_Wool_Blue_Light"
    },
    {
      "x": -6,
      "y": 0,
      "z": -4,
      "name": "Cloth_Block_Wool_Blue_Light"
    },
    {
      "x": -6,
      "y": 1,
      "z": -4,
      "name": "Cloth_Block_Wool_Blue_Light"
    },
    {
      "x": -6,
      "y": 2,
      "z": -4,
      "name": "Cloth_Block_Wool_Blue_Light"
    },
    {
      "x": -6,
      "y": 3,
      "z": -4,
      "name": "Cloth_Block_Wool_Blue_Light"
    },
    {
      "x": -6,
      "y": 4,
      "z": -4,
      "name": "Cloth_Block_Wool_Blue_Light"
    },
    {
      "x": -6,
      "y": 0,
      "z": -3,
      "name": "Cloth_Block_Wool_Blue_Light"
    },
    {
      "x": -6,
      "y": 1,
      "z": -3,
      "name": "Cloth_Block_Wool_Blue_Light"
    },
    {
      "x": -6,
      "y": 2,
      "z": -3,
      "name": "Cloth_Block_Wool_Blue_Light"
    },
    {
      "x": -6,
      "y": 3,
      "z": -3,
      "name": "Cloth_Block_Wool_Blue_Light"
    },
    {
      "x": -6,
      "y": 4,
      "z": -3,
      "name": "Cloth_Block_Wool_Blue_Light"
    },
    {
      "x": -6,
      "y": 0,
      "z": -2,
      "name": "Cloth_Block_Wool_Blue_Light"
    },
    {
      "x": -6,
      "y": 1,
      "z": -2,
      "name": "Cloth_Block_Wool_Blue_Light"
    },
    {
      "x": -6,
      "y": 2,
      "z": -2,
      "name": "Cloth_Block_Wool_Blue_Light"
    },
    {
      "x": -6,
      "y": 8,
      "z": -2,
      "name": "Cloth_Block_Wool_Orange"
    },
    {
      "x": -6,
      "y": 9,
      "z": -2,
      "name": "Cloth_Block_Wool_Orange"
    },
    {
      "x": -6,
      "y": 0,
      "z": -1,
      "name": "Cloth_Block_Wool_Blue_Light"
    },
    {
      "x": -6,
      "y": 1,
      "z": -1,
      "name": "Cloth_Block_Wool_Blue_Light"
    },
    {
      "x": -6,
      "y": 7,
      "z": -1,
      "name": "Cloth_Block_Wool_Orange"
    },
    {
      "x": -6,
      "y": 8,
      "z": -1,
      "name": "Cloth_Block_Wool_Orange"
    },
    {
      "x": -6,
      "y": 9,
      "z": -1,
      "name": "Cloth_Block_Wool_Orange"
    },
    {
      "x": -6,
      "y": 0,
      "z": 0,
      "name": "Cloth_Block_Wool_Blue_Light"
    },
    {
      "x": -6,
      "y": 1,
      "z": 0,
      "name": "Cloth_Block_Wool_Blue_Light"
    },
    {
      "x": -6,
      "y": 7,
      "z": 0,
      "name": "Cloth_Block_Wool_Orange"
    },
    {
      "x": -6,
      "y": 8,
      "z": 0,
      "name": "Cloth_Block_Wool_Orange"
    },
    {
      "x": -6,
      "y": 9,
      "z": 0,
      "name": "Cloth_Block_Wool_Orange"
    },
    {
      "x": -6,
      "y": 0,
      "z": 1,
      "name": "Cloth_Block_Wool_Blue_Light"
    },
    {
      "x": -6,
      "y": 1,
      "z": 1,
      "name": "Cloth_Block_Wool_Blue_Light"
    },
    {
      "x": -6,
      "y": 7,
      "z": 1,
      "name": "Cloth_Block_Wool_Orange"
    },
    {
      "x": -6,
      "y": 8,
      "z": 1,
      "name": "Cloth_Block_Wool_Orange"
    },
    {
      "x": -6,
      "y": 9,
      "z": 1,
      "name": "Cloth_Block_Wool_Orange"
    },
    {
      "x": -6,
      "y": 0,
      "z": 2,
      "name": "Cloth_Block_Wool_Blue_Light"
    },
    {
      "x": -6,
      "y": 1,
      "z": 2,
      "name": "Cloth_Block_Wool_Blue_Light"
    },
    {
      "x": -6,
      "y": 2,
      "z": 2,
      "name": "Cloth_Block_Wool_Blue_Light"
    },
    {
      "x": -6,
      "y": 8,
      "z": 2,
      "name": "Cloth_Block_Wool_Orange"
    },
    {
      "x": -6,
      "y": 9,
      "z": 2,
      "name": "Cloth_Block_Wool_Orange"
    },
    {
      "x": -6,
      "y": 0,
      "z": 3,
      "name": "Cloth_Block_Wool_Blue_Light"
    },
    {
      "x": -6,
      "y": 1,
      "z": 3,
      "name": "Cloth_Block_Wool_Blue_Light"
    },
    {
      "x": -6,
      "y": 2,
      "z": 3,
      "name": "Cloth_Block_Wool_Blue_Light"
    },
    {
      "x": -6,
      "y": 3,
      "z": 3,
      "name": "Cloth_Block_Wool_Blue_Light"
    },
    {
      "x": -6,
      "y": 4,
      "z": 3,
      "name": "Cloth_Block_Wool_Blue_Light"
    },
    {
      "x": -6,
      "y": 0,
      "z": 4,
      "name": "Cloth_Block_Wool_Blue_Light"
    },
    {
      "x": -6,
      "y": 1,
      "z": 4,
      "name": "Cloth_Block_Wool_Blue_Light"
    },
    {
      "x": -6,
      "y": 2,
      "z": 4,
      "name": "Cloth_Block_Wool_Blue_Light"
    },
    {
      "x": -6,
      "y": 3,
      "z": 4,
      "name": "Cloth_Block_Wool_Blue_Light"
    },
    {
      "x": -6,
      "y": 4,
      "z": 4,
      "name": "Cloth_Block_Wool_Blue_Light"
    },
    {
      "x": -6,
      "y": 0,
      "z": 5,
      "name": "Cloth_Block_Wool_Blue_Light"
    },
    {
      "x": -6,
      "y": 1,
      "z": 5,
      "name": "Cloth_Block_Wool_Blue_Light"
    },
    {
      "x": -6,
      "y": 2,
      "z": 5,
      "name": "Cloth_Block_Wool_Blue_Light"
    },
    {
      "x": -6,
      "y": 3,
      "z": 5,
      "name": "Cloth_Block_Wool_Blue_Light"
    },
    {
      "x": -6,
      "y": 4,
      "z": 5,
      "name": "Cloth_Block_Wool_Blue_Light"
    },
    {
      "x": -6,
      "y": 0,
      "z": 6,
      "name": "Cloth_Block_Wool_Blue_Light"
    },
    {
      "x": -6,
      "y": 1,
      "z": 6,
      "name": "Cloth_Block_Wool_Blue_Light"
    },
    {
      "x": -6,
      "y": 2,
      "z": 6,
      "name": "Cloth_Block_Wool_Blue_Light"
    },
    {
      "x": -6,
      "y": 3,
      "z": 6,
      "name": "Cloth_Block_Wool_Blue_Light"
    },
    {
      "x": -6,
      "y": 4,
      "z": 6,
      "name": "Cloth_Block_Wool_Blue_Light"
    },
    {
      "x": -6,
      "y": 0,
      "z": 7,
      "name": "Cloth_Block_Wool_Blue_Light"
    },
    {
      "x": -6,
      "y": 1,
      "z": 7,
      "name": "Cloth_Block_Wool_Blue_Light"
    },
    {
      "x": -6,
      "y": 2,
      "z": 7,
      "name": "Cloth_Block_Wool_Blue_Light"
    },
    {
      "x": -6,
      "y": 3,
      "z": 7,
      "name": "Cloth_Block_Wool_Blue_Light"
    },
    {
      "x": -6,
      "y": 0,
      "z": 8,
      "name": "Cloth_Block_Wool_Blue_Light"
    },
    {
      "x": -6,
      "y": 1,
      "z": 8,
      "name": "Cloth_Block_Wool_Blue_Light"
    },
    {
      "x": -6,
      "y": 2,
      "z": 8,
      "name": "Cloth_Block_Wool_Blue_Light"
    },
    {
      "x": -6,
      "y": 3,
      "z": 8,
      "name": "Cloth_Block_Wool_Blue_Light"
    },
    {
      "x": -6,
      "y": 0,
      "z": 9,
      "name": "Cloth_Block_Wool_Blue_Light"
    },
    {
      "x": -6,
      "y": 1,
      "z": 9,
      "name": "Cloth_Block_Wool_Blue_Light"
    },
    {
      "x": -6,
      "y": 2,
      "z": 9,
      "name": "Cloth_Block_Wool_Blue_Light"
    },
    {
      "x": -6,
      "y": 3,
      "z": 9,
      "name": "Cloth_Block_Wool_Blue_Light"
    },
    {
      "x": -5,
      "y": 0,
      "z": -8,
      "name": "Cloth_Block_Wool_Blue_Light"
    },
    {
      "x": -5,
      "y": 1,
      "z": -8,
      "name": "Cloth_Block_Wool_Blue_Light"
    },
    {
      "x": -5,
      "y": 2,
      "z": -8,
      "name": "Cloth_Block_Wool_Blue_Light"
    },
    {
      "x": -5,
      "y": 3,
      "z": -8,
      "name": "Cloth_Block_Wool_Blue_Light"
    },
    {
      "x": -5,
      "y": 0,
      "z": -7,
      "name": "Cloth_Block_Wool_Blue_Light"
    },
    {
      "x": -5,
      "y": 1,
      "z": -7,
      "name": "Cloth_Block_Wool_Blue_Light"
    },
    {
      "x": -5,
      "y": 2,
      "z": -7,
      "name": "Cloth_Block_Wool_Blue_Light"
    },
    {
      "x": -5,
      "y": 3,
      "z": -7,
      "name": "Cloth_Block_Wool_Blue_Light"
    },
    {
      "x": -5,
      "y": 0,
      "z": -6,
      "name": "Cloth_Block_Wool_Blue_Light"
    },
    {
      "x": -5,
      "y": 1,
      "z": -6,
      "name": "Cloth_Block_Wool_Blue_Light"
    },
    {
      "x": -5,
      "y": 2,
      "z": -6,
      "name": "Cloth_Block_Wool_Blue_Light"
    },
    {
      "x": -5,
      "y": 3,
      "z": -6,
      "name": "Cloth_Block_Wool_Blue_Light"
    },
    {
      "x": -5,
      "y": 0,
      "z": -5,
      "name": "Cloth_Block_Wool_Blue_Light"
    },
    {
      "x": -5,
      "y": 1,
      "z": -5,
      "name": "Cloth_Block_Wool_Blue_Light"
    },
    {
      "x": -5,
      "y": 2,
      "z": -5,
      "name": "Cloth_Block_Wool_Blue_Light"
    },
    {
      "x": -5,
      "y": 3,
      "z": -5,
      "name": "Cloth_Block_Wool_Blue_Light"
    },
    {
      "x": -5,
      "y": 4,
      "z": -5,
      "name": "Cloth_Block_Wool_Blue_Light"
    },
    {
      "x": -5,
      "y": 0,
      "z": -4,
      "name": "Cloth_Block_Wool_Blue_Light"
    },
    {
      "x": -5,
      "y": 1,
      "z": -4,
      "name": "Cloth_Block_Wool_Blue_Light"
    },
    {
      "x": -5,
      "y": 2,
      "z": -4,
      "name": "Cloth_Block_Wool_Blue_Light"
    },
    {
      "x": -5,
      "y": 3,
      "z": -4,
      "name": "Cloth_Block_Wool_Blue_Light"
    },
    {
      "x": -5,
      "y": 4,
      "z": -4,
      "name": "Cloth_Block_Wool_Blue_Light"
    },
    {
      "x": -5,
      "y": 0,
      "z": -3,
      "name": "Cloth_Block_Wool_Blue_Light"
    },
    {
      "x": -5,
      "y": 1,
      "z": -3,
      "name": "Cloth_Block_Wool_Blue_Light"
    },
    {
      "x": -5,
      "y": 2,
      "z": -3,
      "name": "Cloth_Block_Wool_Blue_Light"
    },
    {
      "x": -5,
      "y": 3,
      "z": -3,
      "name": "Cloth_Block_Wool_Blue_Light"
    },
    {
      "x": -5,
      "y": 9,
      "z": -3,
      "name": "Cloth_Block_Wool_Orange"
    },
    {
      "x": -5,
      "y": 0,
      "z": -2,
      "name": "Cloth_Block_Wool_Blue_Light"
    },
    {
      "x": -5,
      "y": 1,
      "z": -2,
      "name": "Cloth_Block_Wool_Blue_Light"
    },
    {
      "x": -5,
      "y": 7,
      "z": -2,
      "name": "Cloth_Block_Wool_Orange"
    },
    {
      "x": -5,
      "y": 8,
      "z": -2,
      "name": "Cloth_Block_Wool_Orange"
    },
    {
      "x": -5,
      "y": 9,
      "z": -2,
      "name": "Cloth_Block_Wool_Orange"
    },
    {
      "x": -5,
      "y": 0,
      "z": -1,
      "name": "Cloth_Block_Wool_Blue_Light"
    },
    {
      "x": -5,
      "y": 6,
      "z": -1,
      "name": "Cloth_Block_Wool_Orange"
    },
    {
      "x": -5,
      "y": 7,
      "z": -1,
      "name": "Cloth_Block_Wool_Orange"
    },
    {
      "x": -5,
      "y": 8,
      "z": -1,
      "name": "Cloth_Block_Wool_Orange"
    },
    {
      "x": -5,
      "y": 9,
      "z": -1,
      "name": "Cloth_Block_Wool_Orange"
    },
    {
      "x": -5,
      "y": 0,
      "z": 0,
      "name": "Cloth_Block_Wool_Blue_Light"
    },
    {
      "x": -5,
      "y": 6,
      "z": 0,
      "name": "Cloth_Block_Wool_Orange"
    },
    {
      "x": -5,
      "y": 7,
      "z": 0,
      "name": "Cloth_Block_Wool_Orange"
    },
    {
      "x": -5,
      "y": 8,
      "z": 0,
      "name": "Cloth_Block_Wool_Orange"
    },
    {
      "x": -5,
      "y": 9,
      "z": 0,
      "name": "Cloth_Block_Wool_Orange"
    },
    {
      "x": -5,
      "y": 10,
      "z": 0,
      "name": "Cloth_Block_Wool_Orange"
    },
    {
      "x": -5,
      "y": 0,
      "z": 1,
      "name": "Cloth_Block_Wool_Blue_Light"
    },
    {
      "x": -5,
      "y": 6,
      "z": 1,
      "name": "Cloth_Block_Wool_Orange"
    },
    {
      "x": -5,
      "y": 7,
      "z": 1,
      "name": "Cloth_Block_Wool_Orange"
    },
    {
      "x": -5,
      "y": 8,
      "z": 1,
      "name": "Cloth_Block_Wool_Orange"
    },
    {
      "x": -5,
      "y": 9,
      "z": 1,
      "name": "Cloth_Block_Wool_Orange"
    },
    {
      "x": -5,
      "y": 0,
      "z": 2,
      "name": "Cloth_Block_Wool_Blue_Light"
    },
    {
      "x": -5,
      "y": 1,
      "z": 2,
      "name": "Cloth_Block_Wool_Blue_Light"
    },
    {
      "x": -5,
      "y": 7,
      "z": 2,
      "name": "Cloth_Block_Wool_Orange"
    },
    {
      "x": -5,
      "y": 8,
      "z": 2,
      "name": "Cloth_Block_Wool_Orange"
    },
    {
      "x": -5,
      "y": 9,
      "z": 2,
      "name": "Cloth_Block_Wool_Orange"
    },
    {
      "x": -5,
      "y": 0,
      "z": 3,
      "name": "Cloth_Block_Wool_Blue_Light"
    },
    {
      "x": -5,
      "y": 1,
      "z": 3,
      "name": "Cloth_Block_Wool_Blue_Light"
    },
    {
      "x": -5,
      "y": 2,
      "z": 3,
      "name": "Cloth_Block_Wool_Blue_Light"
    },
    {
      "x": -5,
      "y": 3,
      "z": 3,
      "name": "Cloth_Block_Wool_Blue_Light"
    },
    {
      "x": -5,
      "y": 9,
      "z": 3,
      "name": "Cloth_Block_Wool_Orange"
    },
    {
      "x": -5,
      "y": 0,
      "z": 4,
      "name": "Cloth_Block_Wool_Blue_Light"
    },
    {
      "x": -5,
      "y": 1,
      "z": 4,
      "name": "Cloth_Block_Wool_Blue_Light"
    },
    {
      "x": -5,
      "y": 2,
      "z": 4,
      "name": "Cloth_Block_Wool_Blue_Light"
    },
    {
      "x": -5,
      "y": 3,
      "z": 4,
      "name": "Cloth_Block_Wool_Blue_Light"
    },
    {
      "x": -5,
      "y": 4,
      "z": 4,
      "name": "Cloth_Block_Wool_Blue_Light"
    },
    {
      "x": -5,
      "y": 0,
      "z": 5,
      "name": "Cloth_Block_Wool_Blue_Light"
    },
    {
      "x": -5,
      "y": 1,
      "z": 5,
      "name": "Cloth_Block_Wool_Blue_Light"
    },
    {
      "x": -5,
      "y": 2,
      "z": 5,
      "name": "Cloth_Block_Wool_Blue_Light"
    },
    {
      "x": -5,
      "y": 3,
      "z": 5,
      "name": "Cloth_Block_Wool_Blue_Light"
    },
    {
      "x": -5,
      "y": 4,
      "z": 5,
      "name": "Cloth_Block_Wool_Blue_Light"
    },
    {
      "x": -5,
      "y": 0,
      "z": 6,
      "name": "Cloth_Block_Wool_Blue_Light"
    },
    {
      "x": -5,
      "y": 1,
      "z": 6,
      "name": "Cloth_Block_Wool_Blue_Light"
    },
    {
      "x": -5,
      "y": 2,
      "z": 6,
      "name": "Cloth_Block_Wool_Blue_Light"
    },
    {
      "x": -5,
      "y": 3,
      "z": 6,
      "name": "Cloth_Block_Wool_Blue_Light"
    },
    {
      "x": -5,
      "y": 4,
      "z": 6,
      "name": "Cloth_Block_Wool_Blue_Light"
    },
    {
      "x": -5,
      "y": 0,
      "z": 7,
      "name": "Cloth_Block_Wool_Blue_Light"
    },
    {
      "x": -5,
      "y": 1,
      "z": 7,
      "name": "Cloth_Block_Wool_Blue_Light"
    },
    {
      "x": -5,
      "y": 2,
      "z": 7,
      "name": "Cloth_Block_Wool_Blue_Light"
    },
    {
      "x": -5,
      "y": 3,
      "z": 7,
      "name": "Cloth_Block_Wool_Blue_Light"
    },
    {
      "x": -5,
      "y": 4,
      "z": 7,
      "name": "Cloth_Block_Wool_Blue_Light"
    },
    {
      "x": -5,
      "y": 0,
      "z": 8,
      "name": "Cloth_Block_Wool_Blue_Light"
    },
    {
      "x": -5,
      "y": 1,
      "z": 8,
      "name": "Cloth_Block_Wool_Blue_Light"
    },
    {
      "x": -5,
      "y": 2,
      "z": 8,
      "name": "Cloth_Block_Wool_Blue_Light"
    },
    {
      "x": -5,
      "y": 3,
      "z": 8,
      "name": "Cloth_Block_Wool_Blue_Light"
    },
    {
      "x": -5,
      "y": 0,
      "z": 9,
      "name": "Cloth_Block_Wool_Blue_Light"
    },
    {
      "x": -5,
      "y": 1,
      "z": 9,
      "name": "Cloth_Block_Wool_Blue_Light"
    },
    {
      "x": -5,
      "y": 2,
      "z": 9,
      "name": "Cloth_Block_Wool_Blue_Light"
    },
    {
      "x": -5,
      "y": 3,
      "z": 9,
      "name": "Cloth_Block_Wool_Blue_Light"
    },
    {
      "x": -4,
      "y": 0,
      "z": -8,
      "name": "Cloth_Block_Wool_Blue_Light"
    },
    {
      "x": -4,
      "y": 1,
      "z": -8,
      "name": "Cloth_Block_Wool_Blue_Light"
    },
    {
      "x": -4,
      "y": 2,
      "z": -8,
      "name": "Cloth_Block_Wool_Blue_Light"
    },
    {
      "x": -4,
      "y": 3,
      "z": -8,
      "name": "Cloth_Block_Wool_Blue_Light"
    },
    {
      "x": -4,
      "y": 0,
      "z": -7,
      "name": "Cloth_Block_Wool_Blue_Light"
    },
    {
      "x": -4,
      "y": 1,
      "z": -7,
      "name": "Cloth_Block_Wool_Blue_Light"
    },
    {
      "x": -4,
      "y": 2,
      "z": -7,
      "name": "Cloth_Block_Wool_Blue_Light"
    },
    {
      "x": -4,
      "y": 3,
      "z": -7,
      "name": "Cloth_Block_Wool_Blue_Light"
    },
    {
      "x": -4,
      "y": 0,
      "z": -6,
      "name": "Cloth_Block_Wool_Blue_Light"
    },
    {
      "x": -4,
      "y": 1,
      "z": -6,
      "name": "Cloth_Block_Wool_Blue_Light"
    },
    {
      "x": -4,
      "y": 2,
      "z": -6,
      "name": "Cloth_Block_Wool_Blue_Light"
    },
    {
      "x": -4,
      "y": 3,
      "z": -6,
      "name": "Cloth_Block_Wool_Blue_Light"
    },
    {
      "x": -4,
      "y": 0,
      "z": -5,
      "name": "Cloth_Block_Wool_Blue_Light"
    },
    {
      "x": -4,
      "y": 1,
      "z": -5,
      "name": "Cloth_Block_Wool_Blue_Light"
    },
    {
      "x": -4,
      "y": 2,
      "z": -5,
      "name": "Cloth_Block_Wool_Blue_Light"
    },
    {
      "x": -4,
      "y": 3,
      "z": -5,
      "name": "Cloth_Block_Wool_Blue_Light"
    },
    {
      "x": -4,
      "y": 4,
      "z": -5,
      "name": "Cloth_Block_Wool_Blue_Light"
    },
    {
      "x": -4,
      "y": 0,
      "z": -4,
      "name": "Cloth_Block_Wool_Blue_Light"
    },
    {
      "x": -4,
      "y": 1,
      "z": -4,
      "name": "Cloth_Block_Wool_Blue_Light"
    },
    {
      "x": -4,
      "y": 2,
      "z": -4,
      "name": "Cloth_Block_Wool_Blue_Light"
    },
    {
      "x": -4,
      "y": 3,
      "z": -4,
      "name": "Cloth_Block_Wool_Blue_Light"
    },
    {
      "x": -4,
      "y": 4,
      "z": -4,
      "name": "Cloth_Block_Wool_Blue_Light"
    },
    {
      "x": -4,
      "y": 5,
      "z": -4,
      "name": "Cloth_Block_Wool_Blue_Light"
    },
    {
      "x": -4,
      "y": 0,
      "z": -3,
      "name": "Cloth_Block_Wool_Blue_Light"
    },
    {
      "x": -4,
      "y": 1,
      "z": -3,
      "name": "Cloth_Block_Wool_Blue_Light"
    },
    {
      "x": -4,
      "y": 2,
      "z": -3,
      "name": "Cloth_Block_Wool_Blue_Light"
    },
    {
      "x": -4,
      "y": 8,
      "z": -3,
      "name": "Cloth_Block_Wool_Orange"
    },
    {
      "x": -4,
      "y": 9,
      "z": -3,
      "name": "Cloth_Block_Wool_Orange"
    },
    {
      "x": -4,
      "y": 10,
      "z": -3,
      "name": "Cloth_Block_Wool_Orange"
    },
    {
      "x": -4,
      "y": 0,
      "z": -2,
      "name": "Cloth_Block_Wool_Blue_Light"
    },
    {
      "x": -4,
      "y": 1,
      "z": -2,
      "name": "Cloth_Block_Wool_Blue_Light"
    },
    {
      "x": -4,
      "y": 7,
      "z": -2,
      "name": "Cloth_Block_Wool_Orange"
    },
    {
      "x": -4,
      "y": 8,
      "z": -2,
      "name": "Cloth_Block_Wool_Orange"
    },
    {
      "x": -4,
      "y": 9,
      "z": -2,
      "name": "Cloth_Block_Wool_Orange"
    },
    {
      "x": -4,
      "y": 0,
      "z": -1,
      "name": "Cloth_Block_Wool_Blue_Light"
    },
    {
      "x": -4,
      "y": 6,
      "z": -1,
      "name": "Cloth_Block_Wool_Orange"
    },
    {
      "x": -4,
      "y": 7,
      "z": -1,
      "name": "Cloth_Block_Wool_Orange"
    },
    {
      "x": -4,
      "y": 8,
      "z": -1,
      "name": "Cloth_Block_Wool_Orange"
    },
    {
      "x": -4,
      "y": 9,
      "z": -1,
      "name": "Cloth_Block_Wool_Orange"
    },
    {
      "x": -4,
      "y": 10,
      "z": -1,
      "name": "Cloth_Block_Wool_Orange"
    },
    {
      "x": -4,
      "y": 0,
      "z": 0,
      "name": "Cloth_Block_Wool_Blue_Light"
    },
    {
      "x": -4,
      "y": 6,
      "z": 0,
      "name": "Cloth_Block_Wool_Orange"
    },
    {
      "x": -4,
      "y": 7,
      "z": 0,
      "name": "Cloth_Block_Wool_Orange"
    },
    {
      "x": -4,
      "y": 8,
      "z": 0,
      "name": "Cloth_Block_Wool_Orange"
    },
    {
      "x": -4,
      "y": 9,
      "z": 0,
      "name": "Cloth_Block_Wool_Orange"
    },
    {
      "x": -4,
      "y": 10,
      "z": 0,
      "name": "Cloth_Block_Wool_Orange"
    },
    {
      "x": -4,
      "y": 0,
      "z": 1,
      "name": "Cloth_Block_Wool_Blue_Light"
    },
    {
      "x": -4,
      "y": 6,
      "z": 1,
      "name": "Cloth_Block_Wool_Orange"
    },
    {
      "x": -4,
      "y": 7,
      "z": 1,
      "name": "Cloth_Block_Wool_Orange"
    },
    {
      "x": -4,
      "y": 8,
      "z": 1,
      "name": "Cloth_Block_Wool_Orange"
    },
    {
      "x": -4,
      "y": 9,
      "z": 1,
      "name": "Cloth_Block_Wool_Orange"
    },
    {
      "x": -4,
      "y": 10,
      "z": 1,
      "name": "Cloth_Block_Wool_Orange"
    },
    {
      "x": -4,
      "y": 0,
      "z": 2,
      "name": "Cloth_Block_Wool_Blue_Light"
    },
    {
      "x": -4,
      "y": 1,
      "z": 2,
      "name": "Cloth_Block_Wool_Blue_Light"
    },
    {
      "x": -4,
      "y": 7,
      "z": 2,
      "name": "Cloth_Block_Wool_Orange"
    },
    {
      "x": -4,
      "y": 8,
      "z": 2,
      "name": "Cloth_Block_Wool_Orange"
    },
    {
      "x": -4,
      "y": 9,
      "z": 2,
      "name": "Cloth_Block_Wool_Orange"
    },
    {
      "x": -4,
      "y": 10,
      "z": 2,
      "name": "Cloth_Block_Wool_Orange"
    },
    {
      "x": -4,
      "y": 0,
      "z": 3,
      "name": "Cloth_Block_Wool_Blue_Light"
    },
    {
      "x": -4,
      "y": 1,
      "z": 3,
      "name": "Cloth_Block_Wool_Blue_Light"
    },
    {
      "x": -4,
      "y": 2,
      "z": 3,
      "name": "Cloth_Block_Wool_Blue_Light"
    },
    {
      "x": -4,
      "y": 8,
      "z": 3,
      "name": "Cloth_Block_Wool_Orange"
    },
    {
      "x": -4,
      "y": 9,
      "z": 3,
      "name": "Cloth_Block_Wool_Orange"
    },
    {
      "x": -4,
      "y": 10,
      "z": 3,
      "name": "Cloth_Block_Wool_Orange"
    },
    {
      "x": -4,
      "y": 0,
      "z": 4,
      "name": "Cloth_Block_Wool_Blue_Light"
    },
    {
      "x": -4,
      "y": 1,
      "z": 4,
      "name": "Cloth_Block_Wool_Blue_Light"
    },
    {
      "x": -4,
      "y": 2,
      "z": 4,
      "name": "Cloth_Block_Wool_Blue_Light"
    },
    {
      "x": -4,
      "y": 3,
      "z": 4,
      "name": "Cloth_Block_Wool_Blue_Light"
    },
    {
      "x": -4,
      "y": 4,
      "z": 4,
      "name": "Cloth_Block_Wool_Blue_Light"
    },
    {
      "x": -4,
      "y": 5,
      "z": 4,
      "name": "Cloth_Block_Wool_Blue_Light"
    },
    {
      "x": -4,
      "y": 0,
      "z": 5,
      "name": "Cloth_Block_Wool_Blue_Light"
    },
    {
      "x": -4,
      "y": 1,
      "z": 5,
      "name": "Cloth_Block_Wool_Blue_Light"
    },
    {
      "x": -4,
      "y": 2,
      "z": 5,
      "name": "Cloth_Block_Wool_Blue_Light"
    },
    {
      "x": -4,
      "y": 3,
      "z": 5,
      "name": "Cloth_Block_Wool_Blue_Light"
    },
    {
      "x": -4,
      "y": 4,
      "z": 5,
      "name": "Cloth_Block_Wool_Blue_Light"
    },
    {
      "x": -4,
      "y": 0,
      "z": 6,
      "name": "Cloth_Block_Wool_Blue_Light"
    },
    {
      "x": -4,
      "y": 1,
      "z": 6,
      "name": "Cloth_Block_Wool_Blue_Light"
    },
    {
      "x": -4,
      "y": 2,
      "z": 6,
      "name": "Cloth_Block_Wool_Blue_Light"
    },
    {
      "x": -4,
      "y": 3,
      "z": 6,
      "name": "Cloth_Block_Wool_Blue_Light"
    },
    {
      "x": -4,
      "y": 4,
      "z": 6,
      "name": "Cloth_Block_Wool_Blue_Light"
    },
    {
      "x": -4,
      "y": 0,
      "z": 7,
      "name": "Cloth_Block_Wool_Blue_Light"
    },
    {
      "x": -4,
      "y": 1,
      "z": 7,
      "name": "Cloth_Block_Wool_Blue_Light"
    },
    {
      "x": -4,
      "y": 2,
      "z": 7,
      "name": "Cloth_Block_Wool_Blue_Light"
    },
    {
      "x": -4,
      "y": 3,
      "z": 7,
      "name": "Cloth_Block_Wool_Blue_Light"
    },
    {
      "x": -4,
      "y": 4,
      "z": 7,
      "name": "Cloth_Block_Wool_Blue_Light"
    },
    {
      "x": -4,
      "y": 0,
      "z": 8,
      "name": "Cloth_Block_Wool_Blue_Light"
    },
    {
      "x": -4,
      "y": 1,
      "z": 8,
      "name": "Cloth_Block_Wool_Blue_Light"
    },
    {
      "x": -4,
      "y": 2,
      "z": 8,
      "name": "Cloth_Block_Wool_Blue_Light"
    },
    {
      "x": -4,
      "y": 3,
      "z": 8,
      "name": "Cloth_Block_Wool_Blue_Light"
    },
    {
      "x": -4,
      "y": 0,
      "z": 9,
      "name": "Cloth_Block_Wool_Blue_Light"
    },
    {
      "x": -4,
      "y": 1,
      "z": 9,
      "name": "Cloth_Block_Wool_Blue_Light"
    },
    {
      "x": -4,
      "y": 2,
      "z": 9,
      "name": "Cloth_Block_Wool_Blue_Light"
    },
    {
      "x": -4,
      "y": 3,
      "z": 9,
      "name": "Cloth_Block_Wool_Blue_Light"
    },
    {
      "x": -3,
      "y": 0,
      "z": -8,
      "name": "Cloth_Block_Wool_Blue_Light"
    },
    {
      "x": -3,
      "y": 1,
      "z": -8,
      "name": "Cloth_Block_Wool_Blue_Light"
    },
    {
      "x": -3,
      "y": 2,
      "z": -8,
      "name": "Cloth_Block_Wool_Blue_Light"
    },
    {
      "x": -3,
      "y": 3,
      "z": -8,
      "name": "Cloth_Block_Wool_Blue_Light"
    },
    {
      "x": -3,
      "y": 0,
      "z": -7,
      "name": "Cloth_Block_Wool_Blue_Light"
    },
    {
      "x": -3,
      "y": 1,
      "z": -7,
      "name": "Cloth_Block_Wool_Blue_Light"
    },
    {
      "x": -3,
      "y": 2,
      "z": -7,
      "name": "Cloth_Block_Wool_Blue_Light"
    },
    {
      "x": -3,
      "y": 3,
      "z": -7,
      "name": "Cloth_Block_Wool_Blue_Light"
    },
    {
      "x": -3,
      "y": 0,
      "z": -6,
      "name": "Cloth_Block_Wool_Blue_Light"
    },
    {
      "x": -3,
      "y": 1,
      "z": -6,
      "name": "Cloth_Block_Wool_Blue_Light"
    },
    {
      "x": -3,
      "y": 2,
      "z": -6,
      "name": "Cloth_Block_Wool_Blue_Light"
    },
    {
      "x": -3,
      "y": 3,
      "z": -6,
      "name": "Cloth_Block_Wool_Blue_Light"
    },
    {
      "x": -3,
      "y": 4,
      "z": -6,
      "name": "Cloth_Block_Wool_Blue_Light"
    },
    {
      "x": -3,
      "y": 0,
      "z": -5,
      "name": "Cloth_Block_Wool_Blue_Light"
    },
    {
      "x": -3,
      "y": 1,
      "z": -5,
      "name": "Cloth_Block_Wool_Blue_Light"
    },
    {
      "x": -3,
      "y": 2,
      "z": -5,
      "name": "Cloth_Block_Wool_Blue_Light"
    },
    {
      "x": -3,
      "y": 3,
      "z": -5,
      "name": "Cloth_Block_Wool_Blue_Light"
    },
    {
      "x": -3,
      "y": 9,
      "z": -5,
      "name": "Cloth_Block_Wool_Orange"
    },
    {
      "x": -3,
      "y": 0,
      "z": -4,
      "name": "Cloth_Block_Wool_Blue_Light"
    },
    {
      "x": -3,
      "y": 1,
      "z": -4,
      "name": "Cloth_Block_Wool_Blue_Light"
    },
    {
      "x": -3,
      "y": 2,
      "z": -4,
      "name": "Cloth_Block_Wool_Blue_Light"
    },
    {
      "x": -3,
      "y": 8,
      "z": -4,
      "name": "Cloth_Block_Wool_Orange"
    },
    {
      "x": -3,
      "y": 9,
      "z": -4,
      "name": "Cloth_Block_Wool_Orange"
    },
    {
      "x": -3,
      "y": 10,
      "z": -4,
      "name": "Cloth_Block_Wool_Orange"
    },
    {
      "x": -3,
      "y": 0,
      "z": -3,
      "name": "Cloth_Block_Wool_Blue_Light"
    },
    {
      "x": -3,
      "y": 1,
      "z": -3,
      "name": "Cloth_Block_Wool_Blue_Light"
    },
    {
      "x": -3,
      "y": 2,
      "z": -3,
      "name": "Cloth_Block_Wool_Blue_Light"
    },
    {
      "x": -3,
      "y": 3,
      "z": -3,
      "name": "Cloth_Block_Wool_Blue_Light"
    },
    {
      "x": -3,
      "y": 9,
      "z": -3,
      "name": "Cloth_Block_Wool_Orange"
    },
    {
      "x": -3,
      "y": 10,
      "z": -3,
      "name": "Cloth_Block_Wool_Orange"
    },
    {
      "x": -3,
      "y": 0,
      "z": -2,
      "name": "Cloth_Block_Wool_Blue_Light"
    },
    {
      "x": -3,
      "y": 1,
      "z": -2,
      "name": "Cloth_Block_Wool_Blue_Light"
    },
    {
      "x": -3,
      "y": 7,
      "z": -2,
      "name": "Cloth_Block_Wool_Orange"
    },
    {
      "x": -3,
      "y": 8,
      "z": -2,
      "name": "Cloth_Block_Wool_Orange"
    },
    {
      "x": -3,
      "y": 9,
      "z": -2,
      "name": "Cloth_Block_Wool_Orange"
    },
    {
      "x": -3,
      "y": 10,
      "z": -2,
      "name": "Cloth_Block_Wool_Orange"
    },
    {
      "x": -3,
      "y": 0,
      "z": -1,
      "name": "Cloth_Block_Wool_Blue_Light"
    },
    {
      "x": -3,
      "y": 6,
      "z": -1,
      "name": "Cloth_Block_Wool_Orange"
    },
    {
      "x": -3,
      "y": 7,
      "z": -1,
      "name": "Cloth_Block_Wool_Orange"
    },
    {
      "x": -3,
      "y": 8,
      "z": -1,
      "name": "Cloth_Block_Wool_Orange"
    },
    {
      "x": -3,
      "y": 9,
      "z": -1,
      "name": "Cloth_Block_Wool_Orange"
    },
    {
      "x": -3,
      "y": 10,
      "z": -1,
      "name": "Cloth_Block_Wool_Orange"
    },
    {
      "x": -3,
      "y": 0,
      "z": 0,
      "name": "Cloth_Block_Wool_Blue_Light"
    },
    {
      "x": -3,
      "y": 6,
      "z": 0,
      "name": "Cloth_Block_Wool_Orange"
    },
    {
      "x": -3,
      "y": 7,
      "z": 0,
      "name": "Cloth_Block_Wool_Orange"
    },
    {
      "x": -3,
      "y": 8,
      "z": 0,
      "name": "Cloth_Block_Wool_Orange"
    },
    {
      "x": -3,
      "y": 9,
      "z": 0,
      "name": "Cloth_Block_Wool_Orange"
    },
    {
      "x": -3,
      "y": 10,
      "z": 0,
      "name": "Cloth_Block_Wool_Orange"
    },
    {
      "x": -3,
      "y": 0,
      "z": 1,
      "name": "Cloth_Block_Wool_Blue_Light"
    },
    {
      "x": -3,
      "y": 6,
      "z": 1,
      "name": "Cloth_Block_Wool_Orange"
    },
    {
      "x": -3,
      "y": 7,
      "z": 1,
      "name": "Cloth_Block_Wool_Orange"
    },
    {
      "x": -3,
      "y": 8,
      "z": 1,
      "name": "Cloth_Block_Wool_Orange"
    },
    {
      "x": -3,
      "y": 9,
      "z": 1,
      "name": "Cloth_Block_Wool_Orange"
    },
    {
      "x": -3,
      "y": 10,
      "z": 1,
      "name": "Cloth_Block_Wool_Orange"
    },
    {
      "x": -3,
      "y": 0,
      "z": 2,
      "name": "Cloth_Block_Wool_Blue_Light"
    },
    {
      "x": -3,
      "y": 1,
      "z": 2,
      "name": "Cloth_Block_Wool_Blue_Light"
    },
    {
      "x": -3,
      "y": 7,
      "z": 2,
      "name": "Cloth_Block_Wool_Orange"
    },
    {
      "x": -3,
      "y": 8,
      "z": 2,
      "name": "Cloth_Block_Wool_Orange"
    },
    {
      "x": -3,
      "y": 9,
      "z": 2,
      "name": "Cloth_Block_Wool_Orange"
    },
    {
      "x": -3,
      "y": 10,
      "z": 2,
      "name": "Cloth_Block_Wool_Orange"
    },
    {
      "x": -3,
      "y": 0,
      "z": 3,
      "name": "Cloth_Block_Wool_Blue_Light"
    },
    {
      "x": -3,
      "y": 1,
      "z": 3,
      "name": "Cloth_Block_Wool_Blue_Light"
    },
    {
      "x": -3,
      "y": 2,
      "z": 3,
      "name": "Cloth_Block_Wool_Blue_Light"
    },
    {
      "x": -3,
      "y": 3,
      "z": 3,
      "name": "Cloth_Block_Wool_Blue_Light"
    },
    {
      "x": -3,
      "y": 9,
      "z": 3,
      "name": "Cloth_Block_Wool_Orange"
    },
    {
      "x": -3,
      "y": 10,
      "z": 3,
      "name": "Cloth_Block_Wool_Orange"
    },
    {
      "x": -3,
      "y": 0,
      "z": 4,
      "name": "Cloth_Block_Wool_Blue_Light"
    },
    {
      "x": -3,
      "y": 1,
      "z": 4,
      "name": "Cloth_Block_Wool_Blue_Light"
    },
    {
      "x": -3,
      "y": 2,
      "z": 4,
      "name": "Cloth_Block_Wool_Blue_Light"
    },
    {
      "x": -3,
      "y": 8,
      "z": 4,
      "name": "Cloth_Block_Wool_Orange"
    },
    {
      "x": -3,
      "y": 9,
      "z": 4,
      "name": "Cloth_Block_Wool_Orange"
    },
    {
      "x": -3,
      "y": 10,
      "z": 4,
      "name": "Cloth_Block_Wool_Orange"
    },
    {
      "x": -3,
      "y": 0,
      "z": 5,
      "name": "Cloth_Block_Wool_Blue_Light"
    },
    {
      "x": -3,
      "y": 1,
      "z": 5,
      "name": "Cloth_Block_Wool_Blue_Light"
    },
    {
      "x": -3,
      "y": 2,
      "z": 5,
      "name": "Cloth_Block_Wool_Blue_Light"
    },
    {
      "x": -3,
      "y": 3,
      "z": 5,
      "name": "Cloth_Block_Wool_Blue_Light"
    },
    {
      "x": -3,
      "y": 9,
      "z": 5,
      "name": "Cloth_Block_Wool_Orange"
    },
    {
      "x": -3,
      "y": 10,
      "z": 5,
      "name": "Cloth_Block_Wool_Orange"
    },
    {
      "x": -3,
      "y": 0,
      "z": 6,
      "name": "Cloth_Block_Wool_Blue_Light"
    },
    {
      "x": -3,
      "y": 1,
      "z": 6,
      "name": "Cloth_Block_Wool_Blue_Light"
    },
    {
      "x": -3,
      "y": 2,
      "z": 6,
      "name": "Cloth_Block_Wool_Blue_Light"
    },
    {
      "x": -3,
      "y": 3,
      "z": 6,
      "name": "Cloth_Block_Wool_Blue_Light"
    },
    {
      "x": -3,
      "y": 4,
      "z": 6,
      "name": "Cloth_Block_Wool_Blue_Light"
    },
    {
      "x": -3,
      "y": 0,
      "z": 7,
      "name": "Cloth_Block_Wool_Blue_Light"
    },
    {
      "x": -3,
      "y": 1,
      "z": 7,
      "name": "Cloth_Block_Wool_Blue_Light"
    },
    {
      "x": -3,
      "y": 2,
      "z": 7,
      "name": "Cloth_Block_Wool_Blue_Light"
    },
    {
      "x": -3,
      "y": 3,
      "z": 7,
      "name": "Cloth_Block_Wool_Blue_Light"
    },
    {
      "x": -3,
      "y": 4,
      "z": 7,
      "name": "Cloth_Block_Wool_Blue_Light"
    },
    {
      "x": -3,
      "y": 0,
      "z": 8,
      "name": "Cloth_Block_Wool_Blue_Light"
    },
    {
      "x": -3,
      "y": 1,
      "z": 8,
      "name": "Cloth_Block_Wool_Blue_Light"
    },
    {
      "x": -3,
      "y": 2,
      "z": 8,
      "name": "Cloth_Block_Wool_Blue_Light"
    },
    {
      "x": -3,
      "y": 3,
      "z": 8,
      "name": "Cloth_Block_Wool_Blue_Light"
    },
    {
      "x": -3,
      "y": 4,
      "z": 8,
      "name": "Cloth_Block_Wool_Blue_Light"
    },
    {
      "x": -3,
      "y": 0,
      "z": 9,
      "name": "Cloth_Block_Wool_Blue_Light"
    },
    {
      "x": -3,
      "y": 1,
      "z": 9,
      "name": "Cloth_Block_Wool_Blue_Light"
    },
    {
      "x": -3,
      "y": 2,
      "z": 9,
      "name": "Cloth_Block_Wool_Blue_Light"
    },
    {
      "x": -3,
      "y": 3,
      "z": 9,
      "name": "Cloth_Block_Wool_Blue_Light"
    },
    {
      "x": -2,
      "y": 0,
      "z": -8,
      "name": "Cloth_Block_Wool_Blue_Light"
    },
    {
      "x": -2,
      "y": 1,
      "z": -8,
      "name": "Cloth_Block_Wool_Blue_Light"
    },
    {
      "x": -2,
      "y": 2,
      "z": -8,
      "name": "Cloth_Block_Wool_Blue_Light"
    },
    {
      "x": -2,
      "y": 3,
      "z": -8,
      "name": "Cloth_Block_Wool_Blue_Light"
    },
    {
      "x": -2,
      "y": 0,
      "z": -7,
      "name": "Cloth_Block_Wool_Blue_Light"
    },
    {
      "x": -2,
      "y": 1,
      "z": -7,
      "name": "Cloth_Block_Wool_Blue_Light"
    },
    {
      "x": -2,
      "y": 2,
      "z": -7,
      "name": "Cloth_Block_Wool_Blue_Light"
    },
    {
      "x": -2,
      "y": 3,
      "z": -7,
      "name": "Cloth_Block_Wool_Blue_Light"
    },
    {
      "x": -2,
      "y": 0,
      "z": -6,
      "name": "Cloth_Block_Wool_Blue_Light"
    },
    {
      "x": -2,
      "y": 1,
      "z": -6,
      "name": "Cloth_Block_Wool_Blue_Light"
    },
    {
      "x": -2,
      "y": 2,
      "z": -6,
      "name": "Cloth_Block_Wool_Blue_Light"
    },
    {
      "x": -2,
      "y": 8,
      "z": -6,
      "name": "Cloth_Block_Wool_Orange"
    },
    {
      "x": -2,
      "y": 0,
      "z": -5,
      "name": "Cloth_Block_Wool_Blue_Light"
    },
    {
      "x": -2,
      "y": 1,
      "z": -5,
      "name": "Cloth_Block_Wool_Blue_Light"
    },
    {
      "x": -2,
      "y": 7,
      "z": -5,
      "name": "Cloth_Block_Wool_Orange"
    },
    {
      "x": -2,
      "y": 8,
      "z": -5,
      "name": "Cloth_Block_Wool_Orange"
    },
    {
      "x": -2,
      "y": 9,
      "z": -5,
      "name": "Cloth_Block_Wool_Orange"
    },
    {
      "x": -2,
      "y": 0,
      "z": -4,
      "name": "Cloth_Block_Wool_Blue_Light"
    },
    {
      "x": -2,
      "y": 1,
      "z": -4,
      "name": "Cloth_Block_Wool_Blue_Light"
    },
    {
      "x": -2,
      "y": 7,
      "z": -4,
      "name": "Cloth_Block_Wool_Orange"
    },
    {
      "x": -2,
      "y": 8,
      "z": -4,
      "name": "Cloth_Block_Wool_Orange"
    },
    {
      "x": -2,
      "y": 9,
      "z": -4,
      "name": "Cloth_Block_Wool_Orange"
    },
    {
      "x": -2,
      "y": 0,
      "z": -3,
      "name": "Cloth_Block_Wool_Blue_Light"
    },
    {
      "x": -2,
      "y": 1,
      "z": -3,
      "name": "Cloth_Block_Wool_Blue_Light"
    },
    {
      "x": -2,
      "y": 7,
      "z": -3,
      "name": "Cloth_Block_Wool_Orange"
    },
    {
      "x": -2,
      "y": 8,
      "z": -3,
      "name": "Cloth_Block_Wool_Orange"
    },
    {
      "x": -2,
      "y": 9,
      "z": -3,
      "name": "Cloth_Block_Wool_Orange"
    },
    {
      "x": -2,
      "y": 10,
      "z": -3,
      "name": "Cloth_Block_Wool_Orange"
    },
    {
      "x": -2,
      "y": 0,
      "z": -2,
      "name": "Cloth_Block_Wool_Blue_Light"
    },
    {
      "x": -2,
      "y": 1,
      "z": -2,
      "name": "Cloth_Block_Wool_Blue_Light"
    },
    {
      "x": -2,
      "y": 2,
      "z": -2,
      "name": "Cloth_Block_Wool_Blue_Light"
    },
    {
      "x": -2,
      "y": 8,
      "z": -2,
      "name": "Cloth_Block_Wool_Orange"
    },
    {
      "x": -2,
      "y": 9,
      "z": -2,
      "name": "Cloth_Block_Wool_Orange"
    },
    {
      "x": -2,
      "y": 10,
      "z": -2,
      "name": "Cloth_Block_Wool_Orange"
    },
    {
      "x": -2,
      "y": 0,
      "z": -1,
      "name": "Cloth_Block_Wool_Blue_Light"
    },
    {
      "x": -2,
      "y": 1,
      "z": -1,
      "name": "Cloth_Block_Wool_Blue_Light"
    },
    {
      "x": -2,
      "y": 7,
      "z": -1,
      "name": "Cloth_Block_Wool_Orange"
    },
    {
      "x": -2,
      "y": 8,
      "z": -1,
      "name": "Cloth_Block_Wool_Orange"
    },
    {
      "x": -2,
      "y": 9,
      "z": -1,
      "name": "Cloth_Block_Wool_Orange"
    },
    {
      "x": -2,
      "y": 10,
      "z": -1,
      "name": "Cloth_Block_Wool_Orange"
    },
    {
      "x": -2,
      "y": 0,
      "z": 0,
      "name": "Cloth_Block_Wool_Blue_Light"
    },
    {
      "x": -2,
      "y": 1,
      "z": 0,
      "name": "Cloth_Block_Wool_Blue_Light"
    },
    {
      "x": -2,
      "y": 7,
      "z": 0,
      "name": "Cloth_Block_Wool_Orange"
    },
    {
      "x": -2,
      "y": 8,
      "z": 0,
      "name": "Cloth_Block_Wool_Orange"
    },
    {
      "x": -2,
      "y": 9,
      "z": 0,
      "name": "Cloth_Block_Wool_Orange"
    },
    {
      "x": -2,
      "y": 10,
      "z": 0,
      "name": "Cloth_Block_Wool_Orange"
    },
    {
      "x": -2,
      "y": 0,
      "z": 1,
      "name": "Cloth_Block_Wool_Blue_Light"
    },
    {
      "x": -2,
      "y": 1,
      "z": 1,
      "name": "Cloth_Block_Wool_Blue_Light"
    },
    {
      "x": -2,
      "y": 7,
      "z": 1,
      "name": "Cloth_Block_Wool_Orange"
    },
    {
      "x": -2,
      "y": 8,
      "z": 1,
      "name": "Cloth_Block_Wool_Orange"
    },
    {
      "x": -2,
      "y": 9,
      "z": 1,
      "name": "Cloth_Block_Wool_Orange"
    },
    {
      "x": -2,
      "y": 10,
      "z": 1,
      "name": "Cloth_Block_Wool_Orange"
    },
    {
      "x": -2,
      "y": 0,
      "z": 2,
      "name": "Cloth_Block_Wool_Blue_Light"
    },
    {
      "x": -2,
      "y": 1,
      "z": 2,
      "name": "Cloth_Block_Wool_Blue_Light"
    },
    {
      "x": -2,
      "y": 2,
      "z": 2,
      "name": "Cloth_Block_Wool_Blue_Light"
    },
    {
      "x": -2,
      "y": 8,
      "z": 2,
      "name": "Cloth_Block_Wool_Orange"
    },
    {
      "x": -2,
      "y": 9,
      "z": 2,
      "name": "Cloth_Block_Wool_Orange"
    },
    {
      "x": -2,
      "y": 10,
      "z": 2,
      "name": "Cloth_Block_Wool_Orange"
    },
    {
      "x": -2,
      "y": 11,
      "z": 2,
      "name": "Cloth_Block_Wool_Orange"
    },
    {
      "x": -2,
      "y": 0,
      "z": 3,
      "name": "Cloth_Block_Wool_Blue_Light"
    },
    {
      "x": -2,
      "y": 1,
      "z": 3,
      "name": "Cloth_Block_Wool_Blue_Light"
    },
    {
      "x": -2,
      "y": 7,
      "z": 3,
      "name": "Cloth_Block_Wool_Orange"
    },
    {
      "x": -2,
      "y": 8,
      "z": 3,
      "name": "Cloth_Block_Wool_Orange"
    },
    {
      "x": -2,
      "y": 9,
      "z": 3,
      "name": "Cloth_Block_Wool_Orange"
    },
    {
      "x": -2,
      "y": 10,
      "z": 3,
      "name": "Cloth_Block_Wool_Orange"
    },
    {
      "x": -2,
      "y": 11,
      "z": 3,
      "name": "Cloth_Block_Wool_Orange"
    },
    {
      "x": -2,
      "y": 0,
      "z": 4,
      "name": "Cloth_Block_Wool_Blue_Light"
    },
    {
      "x": -2,
      "y": 1,
      "z": 4,
      "name": "Cloth_Block_Wool_Blue_Light"
    },
    {
      "x": -2,
      "y": 7,
      "z": 4,
      "name": "Cloth_Block_Wool_Orange"
    },
    {
      "x": -2,
      "y": 8,
      "z": 4,
      "name": "Cloth_Block_Wool_Orange"
    },
    {
      "x": -2,
      "y": 9,
      "z": 4,
      "name": "Cloth_Block_Wool_Orange"
    },
    {
      "x": -2,
      "y": 10,
      "z": 4,
      "name": "Cloth_Block_Wool_Orange"
    },
    {
      "x": -2,
      "y": 0,
      "z": 5,
      "name": "Cloth_Block_Wool_Blue_Light"
    },
    {
      "x": -2,
      "y": 1,
      "z": 5,
      "name": "Cloth_Block_Wool_Blue_Light"
    },
    {
      "x": -2,
      "y": 7,
      "z": 5,
      "name": "Cloth_Block_Wool_Orange"
    },
    {
      "x": -2,
      "y": 8,
      "z": 5,
      "name": "Cloth_Block_Wool_Orange"
    },
    {
      "x": -2,
      "y": 9,
      "z": 5,
      "name": "Cloth_Block_Wool_Orange"
    },
    {
      "x": -2,
      "y": 10,
      "z": 5,
      "name": "Cloth_Block_Wool_Orange"
    },
    {
      "x": -2,
      "y": 0,
      "z": 6,
      "name": "Cloth_Block_Wool_Blue_Light"
    },
    {
      "x": -2,
      "y": 1,
      "z": 6,
      "name": "Cloth_Block_Wool_Blue_Light"
    },
    {
      "x": -2,
      "y": 2,
      "z": 6,
      "name": "Cloth_Block_Wool_Blue_Light"
    },
    {
      "x": -2,
      "y": 8,
      "z": 6,
      "name": "Cloth_Block_Wool_Orange"
    },
    {
      "x": -2,
      "y": 9,
      "z": 6,
      "name": "Cloth_Block_Wool_Orange"
    },
    {
      "x": -2,
      "y": 10,
      "z": 6,
      "name": "Cloth_Block_Wool_Orange"
    },
    {
      "x": -2,
      "y": 0,
      "z": 7,
      "name": "Cloth_Block_Wool_Blue_Light"
    },
    {
      "x": -2,
      "y": 1,
      "z": 7,
      "name": "Cloth_Block_Wool_Blue_Light"
    },
    {
      "x": -2,
      "y": 2,
      "z": 7,
      "name": "Cloth_Block_Wool_Blue_Light"
    },
    {
      "x": -2,
      "y": 3,
      "z": 7,
      "name": "Cloth_Block_Wool_Blue_Light"
    },
    {
      "x": -2,
      "y": 4,
      "z": 7,
      "name": "Cloth_Block_Wool_Blue_Light"
    },
    {
      "x": -2,
      "y": 0,
      "z": 8,
      "name": "Cloth_Block_Wool_Blue_Light"
    },
    {
      "x": -2,
      "y": 1,
      "z": 8,
      "name": "Cloth_Block_Wool_Blue_Light"
    },
    {
      "x": -2,
      "y": 2,
      "z": 8,
      "name": "Cloth_Block_Wool_Blue_Light"
    },
    {
      "x": -2,
      "y": 3,
      "z": 8,
      "name": "Cloth_Block_Wool_Blue_Light"
    },
    {
      "x": -2,
      "y": 4,
      "z": 8,
      "name": "Cloth_Block_Wool_Blue_Light"
    },
    {
      "x": -2,
      "y": 0,
      "z": 9,
      "name": "Cloth_Block_Wool_Blue_Light"
    },
    {
      "x": -2,
      "y": 1,
      "z": 9,
      "name": "Cloth_Block_Wool_Blue_Light"
    },
    {
      "x": -2,
      "y": 2,
      "z": 9,
      "name": "Cloth_Block_Wool_Blue_Light"
    },
    {
      "x": -2,
      "y": 3,
      "z": 9,
      "name": "Cloth_Block_Wool_Blue_Light"
    },
    {
      "x": -1,
      "y": 0,
      "z": -8,
      "name": "Cloth_Block_Wool_Blue_Light"
    },
    {
      "x": -1,
      "y": 1,
      "z": -8,
      "name": "Cloth_Block_Wool_Blue_Light"
    },
    {
      "x": -1,
      "y": 2,
      "z": -8,
      "name": "Cloth_Block_Wool_Blue_Light"
    },
    {
      "x": -1,
      "y": 3,
      "z": -8,
      "name": "Cloth_Block_Wool_Blue_Light"
    },
    {
      "x": -1,
      "y": 0,
      "z": -7,
      "name": "Cloth_Block_Wool_Blue_Light"
    },
    {
      "x": -1,
      "y": 1,
      "z": -7,
      "name": "Cloth_Block_Wool_Blue_Light"
    },
    {
      "x": -1,
      "y": 2,
      "z": -7,
      "name": "Cloth_Block_Wool_Blue_Light"
    },
    {
      "x": -1,
      "y": 3,
      "z": -7,
      "name": "Cloth_Block_Wool_Blue_Light"
    },
    {
      "x": -1,
      "y": 0,
      "z": -6,
      "name": "Cloth_Block_Wool_Blue_Light"
    },
    {
      "x": -1,
      "y": 1,
      "z": -6,
      "name": "Cloth_Block_Wool_Blue_Light"
    },
    {
      "x": -1,
      "y": 7,
      "z": -6,
      "name": "Cloth_Block_Wool_Orange"
    },
    {
      "x": -1,
      "y": 8,
      "z": -6,
      "name": "Cloth_Block_Wool_Orange"
    },
    {
      "x": -1,
      "y": 0,
      "z": -5,
      "name": "Cloth_Block_Wool_Blue_Light"
    },
    {
      "x": -1,
      "y": 6,
      "z": -5,
      "name": "Cloth_Block_Wool_Orange"
    },
    {
      "x": -1,
      "y": 7,
      "z": -5,
      "name": "Cloth_Block_Wool_Orange"
    },
    {
      "x": -1,
      "y": 8,
      "z": -5,
      "name": "Cloth_Block_Wool_Orange"
    },
    {
      "x": -1,
      "y": 0,
      "z": -4,
      "name": "Cloth_Block_Wool_Blue_Light"
    },
    {
      "x": -1,
      "y": 6,
      "z": -4,
      "name": "Cloth_Block_Wool_Orange"
    },
    {
      "x": -1,
      "y": 7,
      "z": -4,
      "name": "Cloth_Block_Wool_Orange"
    },
    {
      "x": -1,
      "y": 8,
      "z": -4,
      "name": "Cloth_Block_Wool_Orange"
    },
    {
      "x": -1,
      "y": 9,
      "z": -4,
      "name": "Cloth_Block_Wool_Orange"
    },
    {
      "x": -1,
      "y": 0,
      "z": -3,
      "name": "Cloth_Block_Wool_Blue_Light"
    },
    {
      "x": -1,
      "y": 6,
      "z": -3,
      "name": "Cloth_Block_Wool_Orange"
    },
    {
      "x": -1,
      "y": 7,
      "z": -3,
      "name": "Cloth_Block_Wool_Orange"
    },
    {
      "x": -1,
      "y": 8,
      "z": -3,
      "name": "Cloth_Block_Wool_Orange"
    },
    {
      "x": -1,
      "y": 9,
      "z": -3,
      "name": "Cloth_Block_Wool_Orange"
    },
    {
      "x": -1,
      "y": 10,
      "z": -3,
      "name": "Cloth_Block_Wool_Orange"
    },
    {
      "x": -1,
      "y": 0,
      "z": -2,
      "name": "Cloth_Block_Wool_Blue_Light"
    },
    {
      "x": -1,
      "y": 1,
      "z": -2,
      "name": "Cloth_Block_Wool_Blue_Light"
    },
    {
      "x": -1,
      "y": 7,
      "z": -2,
      "name": "Cloth_Block_Wool_Orange"
    },
    {
      "x": -1,
      "y": 8,
      "z": -2,
      "name": "Cloth_Block_Wool_Orange"
    },
    {
      "x": -1,
      "y": 9,
      "z": -2,
      "name": "Cloth_Block_Wool_Orange"
    },
    {
      "x": -1,
      "y": 10,
      "z": -2,
      "name": "Cloth_Block_Wool_Orange"
    },
    {
      "x": -1,
      "y": 0,
      "z": -1,
      "name": "Cloth_Block_Wool_Blue_Light"
    },
    {
      "x": -1,
      "y": 6,
      "z": -1,
      "name": "Cloth_Block_Wool_Orange"
    },
    {
      "x": -1,
      "y": 7,
      "z": -1,
      "name": "Cloth_Block_Wool_Orange"
    },
    {
      "x": -1,
      "y": 8,
      "z": -1,
      "name": "Cloth_Block_Wool_Orange"
    },
    {
      "x": -1,
      "y": 9,
      "z": -1,
      "name": "Cloth_Block_Wool_Orange"
    },
    {
      "x": -1,
      "y": 10,
      "z": -1,
      "name": "Cloth_Block_Wool_Orange"
    },
    {
      "x": -1,
      "y": 0,
      "z": 0,
      "name": "Cloth_Block_Wool_Blue_Light"
    },
    {
      "x": -1,
      "y": 6,
      "z": 0,
      "name": "Cloth_Block_Wool_Orange"
    },
    {
      "x": -1,
      "y": 7,
      "z": 0,
      "name": "Cloth_Block_Wool_Orange"
    },
    {
      "x": -1,
      "y": 8,
      "z": 0,
      "name": "Cloth_Block_Wool_Orange"
    },
    {
      "x": -1,
      "y": 9,
      "z": 0,
      "name": "Cloth_Block_Wool_Orange"
    },
    {
      "x": -1,
      "y": 10,
      "z": 0,
      "name": "Cloth_Block_Wool_Orange"
    },
    {
      "x": -1,
      "y": 11,
      "z": 0,
      "name": "Cloth_Block_Wool_Orange"
    },
    {
      "x": -1,
      "y": 0,
      "z": 1,
      "name": "Cloth_Block_Wool_Blue_Light"
    },
    {
      "x": -1,
      "y": 6,
      "z": 1,
      "name": "Cloth_Block_Wool_Orange"
    },
    {
      "x": -1,
      "y": 7,
      "z": 1,
      "name": "Cloth_Block_Wool_Orange"
    },
    {
      "x": -1,
      "y": 8,
      "z": 1,
      "name": "Cloth_Block_Wool_Orange"
    },
    {
      "x": -1,
      "y": 9,
      "z": 1,
      "name": "Cloth_Block_Wool_Orange"
    },
    {
      "x": -1,
      "y": 10,
      "z": 1,
      "name": "Cloth_Block_Wool_Orange"
    },
    {
      "x": -1,
      "y": 11,
      "z": 1,
      "name": "Cloth_Block_Wool_Orange"
    },
    {
      "x": -1,
      "y": 0,
      "z": 2,
      "name": "Cloth_Block_Wool_Blue_Light"
    },
    {
      "x": -1,
      "y": 1,
      "z": 2,
      "name": "Cloth_Block_Wool_Blue_Light"
    },
    {
      "x": -1,
      "y": 7,
      "z": 2,
      "name": "Cloth_Block_Wool_Orange"
    },
    {
      "x": -1,
      "y": 8,
      "z": 2,
      "name": "Cloth_Block_Wool_Orange"
    },
    {
      "x": -1,
      "y": 9,
      "z": 2,
      "name": "Cloth_Block_Wool_Orange"
    },
    {
      "x": -1,
      "y": 10,
      "z": 2,
      "name": "Cloth_Block_Wool_Orange"
    },
    {
      "x": -1,
      "y": 11,
      "z": 2,
      "name": "Cloth_Block_Wool_Orange"
    },
    {
      "x": -1,
      "y": 0,
      "z": 3,
      "name": "Cloth_Block_Wool_Blue_Light"
    },
    {
      "x": -1,
      "y": 6,
      "z": 3,
      "name": "Cloth_Block_Wool_Orange"
    },
    {
      "x": -1,
      "y": 7,
      "z": 3,
      "name": "Cloth_Block_Wool_Orange"
    },
    {
      "x": -1,
      "y": 8,
      "z": 3,
      "name": "Cloth_Block_Wool_Orange"
    },
    {
      "x": -1,
      "y": 9,
      "z": 3,
      "name": "Cloth_Block_Wool_Orange"
    },
    {
      "x": -1,
      "y": 10,
      "z": 3,
      "name": "Cloth_Block_Wool_Orange"
    },
    {
      "x": -1,
      "y": 11,
      "z": 3,
      "name": "Cloth_Block_Wool_Orange"
    },
    {
      "x": -1,
      "y": 0,
      "z": 4,
      "name": "Cloth_Block_Wool_Blue_Light"
    },
    {
      "x": -1,
      "y": 6,
      "z": 4,
      "name": "Cloth_Block_Wool_Orange"
    },
    {
      "x": -1,
      "y": 7,
      "z": 4,
      "name": "Cloth_Block_Wool_Orange"
    },
    {
      "x": -1,
      "y": 8,
      "z": 4,
      "name": "Cloth_Block_Wool_Orange"
    },
    {
      "x": -1,
      "y": 9,
      "z": 4,
      "name": "Cloth_Block_Wool_Orange"
    },
    {
      "x": -1,
      "y": 10,
      "z": 4,
      "name": "Cloth_Block_Wool_Orange"
    },
    {
      "x": -1,
      "y": 11,
      "z": 4,
      "name": "Cloth_Block_Wool_Orange"
    },
    {
      "x": -1,
      "y": 0,
      "z": 5,
      "name": "Cloth_Block_Wool_Blue_Light"
    },
    {
      "x": -1,
      "y": 6,
      "z": 5,
      "name": "Cloth_Block_Wool_Orange"
    },
    {
      "x": -1,
      "y": 7,
      "z": 5,
      "name": "Cloth_Block_Wool_Orange"
    },
    {
      "x": -1,
      "y": 8,
      "z": 5,
      "name": "Cloth_Block_Wool_Orange"
    },
    {
      "x": -1,
      "y": 9,
      "z": 5,
      "name": "Cloth_Block_Wool_Orange"
    },
    {
      "x": -1,
      "y": 10,
      "z": 5,
      "name": "Cloth_Block_Wool_Orange"
    },
    {
      "x": -1,
      "y": 0,
      "z": 6,
      "name": "Cloth_Block_Wool_Blue_Light"
    },
    {
      "x": -1,
      "y": 1,
      "z": 6,
      "name": "Cloth_Block_Wool_Blue_Light"
    },
    {
      "x": -1,
      "y": 7,
      "z": 6,
      "name": "Cloth_Block_Wool_Orange"
    },
    {
      "x": -1,
      "y": 8,
      "z": 6,
      "name": "Cloth_Block_Wool_Orange"
    },
    {
      "x": -1,
      "y": 9,
      "z": 6,
      "name": "Cloth_Block_Wool_Orange"
    },
    {
      "x": -1,
      "y": 10,
      "z": 6,
      "name": "Cloth_Block_Wool_Orange"
    },
    {
      "x": -1,
      "y": 0,
      "z": 7,
      "name": "Cloth_Block_Wool_Blue_Light"
    },
    {
      "x": -1,
      "y": 1,
      "z": 7,
      "name": "Cloth_Block_Wool_Blue_Light"
    },
    {
      "x": -1,
      "y": 2,
      "z": 7,
      "name": "Cloth_Block_Wool_Blue_Light"
    },
    {
      "x": -1,
      "y": 3,
      "z": 7,
      "name": "Cloth_Block_Wool_Blue_Light"
    },
    {
      "x": -1,
      "y": 9,
      "z": 7,
      "name": "Cloth_Block_Wool_Orange"
    },
    {
      "x": -1,
      "y": 10,
      "z": 7,
      "name": "Cloth_Block_Wool_Orange"
    },
    {
      "x": -1,
      "y": 0,
      "z": 8,
      "name": "Cloth_Block_Wool_Blue_Light"
    },
    {
      "x": -1,
      "y": 1,
      "z": 8,
      "name": "Cloth_Block_Wool_Blue_Light"
    },
    {
      "x": -1,
      "y": 2,
      "z": 8,
      "name": "Cloth_Block_Wool_Blue_Light"
    },
    {
      "x": -1,
      "y": 3,
      "z": 8,
      "name": "Cloth_Block_Wool_Blue_Light"
    },
    {
      "x": -1,
      "y": 4,
      "z": 8,
      "name": "Cloth_Block_Wool_Blue_Light"
    },
    {
      "x": -1,
      "y": 0,
      "z": 9,
      "name": "Cloth_Block_Wool_Blue_Light"
    },
    {
      "x": -1,
      "y": 1,
      "z": 9,
      "name": "Cloth_Block_Wool_Blue_Light"
    },
    {
      "x": -1,
      "y": 2,
      "z": 9,
      "name": "Cloth_Block_Wool_Blue_Light"
    },
    {
      "x": -1,
      "y": 3,
      "z": 9,
      "name": "Cloth_Block_Wool_Blue_Light"
    },
    {
      "x": 0,
      "y": 0,
      "z": -8,
      "name": "Cloth_Block_Wool_Blue_Light"
    },
    {
      "x": 0,
      "y": 1,
      "z": -8,
      "name": "Cloth_Block_Wool_Blue_Light"
    },
    {
      "x": 0,
      "y": 2,
      "z": -8,
      "name": "Cloth_Block_Wool_Blue_Light"
    },
    {
      "x": 0,
      "y": 3,
      "z": -8,
      "name": "Cloth_Block_Wool_Blue_Light"
    },
    {
      "x": 0,
      "y": 0,
      "z": -7,
      "name": "Cloth_Block_Wool_Blue_Light"
    },
    {
      "x": 0,
      "y": 1,
      "z": -7,
      "name": "Cloth_Block_Wool_Blue_Light"
    },
    {
      "x": 0,
      "y": 2,
      "z": -7,
      "name": "Cloth_Block_Wool_Blue_Light"
    },
    {
      "x": 0,
      "y": 8,
      "z": -7,
      "name": "Cloth_Block_Wool_Orange"
    },
    {
      "x": 0,
      "y": 0,
      "z": -6,
      "name": "Cloth_Block_Wool_Blue_Light"
    },
    {
      "x": 0,
      "y": 1,
      "z": -6,
      "name": "Cloth_Block_Wool_Blue_Light"
    },
    {
      "x": 0,
      "y": 7,
      "z": -6,
      "name": "Cloth_Block_Wool_Orange"
    },
    {
      "x": 0,
      "y": 8,
      "z": -6,
      "name": "Cloth_Block_Wool_Orange"
    },
    {
      "x": 0,
      "y": 0,
      "z": -5,
      "name": "Cloth_Block_Wool_Blue_Light"
    },
    {
      "x": 0,
      "y": 6,
      "z": -5,
      "name": "Cloth_Block_Wool_Orange"
    },
    {
      "x": 0,
      "y": 7,
      "z": -5,
      "name": "Cloth_Block_Wool_Orange"
    },
    {
      "x": 0,
      "y": 8,
      "z": -5,
      "name": "Cloth_Block_Wool_Orange"
    },
    {
      "x": 0,
      "y": 0,
      "z": -4,
      "name": "Cloth_Block_Wool_Blue_Light"
    },
    {
      "x": 0,
      "y": 6,
      "z": -4,
      "name": "Cloth_Block_Wool_Orange"
    },
    {
      "x": 0,
      "y": 7,
      "z": -4,
      "name": "Cloth_Block_Wool_Orange"
    },
    {
      "x": 0,
      "y": 8,
      "z": -4,
      "name": "Cloth_Block_Wool_Orange"
    },
    {
      "x": 0,
      "y": 9,
      "z": -4,
      "name": "Cloth_Block_Wool_Orange"
    },
    {
      "x": 0,
      "y": 0,
      "z": -3,
      "name": "Cloth_Block_Wool_Blue_Light"
    },
    {
      "x": 0,
      "y": 6,
      "z": -3,
      "name": "Cloth_Block_Wool_Orange"
    },
    {
      "x": 0,
      "y": 7,
      "z": -3,
      "name": "Cloth_Block_Wool_Orange"
    },
    {
      "x": 0,
      "y": 8,
      "z": -3,
      "name": "Cloth_Block_Wool_Orange"
    },
    {
      "x": 0,
      "y": 9,
      "z": -3,
      "name": "Cloth_Block_Wool_Orange"
    },
    {
      "x": 0,
      "y": 10,
      "z": -3,
      "name": "Cloth_Block_Wool_Orange"
    },
    {
      "x": 0,
      "y": 0,
      "z": -2,
      "name": "Cloth_Block_Wool_Blue_Light"
    },
    {
      "x": 0,
      "y": 1,
      "z": -2,
      "name": "Cloth_Block_Wool_Blue_Light"
    },
    {
      "x": 0,
      "y": 7,
      "z": -2,
      "name": "Cloth_Block_Wool_Orange"
    },
    {
      "x": 0,
      "y": 8,
      "z": -2,
      "name": "Cloth_Block_Wool_Orange"
    },
    {
      "x": 0,
      "y": 9,
      "z": -2,
      "name": "Cloth_Block_Wool_Orange"
    },
    {
      "x": 0,
      "y": 10,
      "z": -2,
      "name": "Cloth_Block_Wool_Orange"
    },
    {
      "x": 0,
      "y": 0,
      "z": -1,
      "name": "Cloth_Block_Wool_Blue_Light"
    },
    {
      "x": 0,
      "y": 6,
      "z": -1,
      "name": "Cloth_Block_Wool_Orange"
    },
    {
      "x": 0,
      "y": 7,
      "z": -1,
      "name": "Cloth_Block_Wool_Orange"
    },
    {
      "x": 0,
      "y": 8,
      "z": -1,
      "name": "Cloth_Block_Wool_Orange"
    },
    {
      "x": 0,
      "y": 9,
      "z": -1,
      "name": "Cloth_Block_Wool_Orange"
    },
    {
      "x": 0,
      "y": 10,
      "z": -1,
      "name": "Cloth_Block_Wool_Orange"
    },
    {
      "x": 0,
      "y": 11,
      "z": -1,
      "name": "Cloth_Block_Wool_Orange"
    },
    {
      "x": 0,
      "y": 0,
      "z": 0,
      "name": "Cloth_Block_Wool_Blue_Light"
    },
    {
      "x": 0,
      "y": 6,
      "z": 0,
      "name": "Cloth_Block_Wool_Orange"
    },
    {
      "x": 0,
      "y": 7,
      "z": 0,
      "name": "Cloth_Block_Wool_Orange"
    },
    {
      "x": 0,
      "y": 8,
      "z": 0,
      "name": "Cloth_Block_Wool_Orange"
    },
    {
      "x": 0,
      "y": 9,
      "z": 0,
      "name": "Cloth_Block_Wool_Orange"
    },
    {
      "x": 0,
      "y": 10,
      "z": 0,
      "name": "Cloth_Block_Wool_Orange"
    },
    {
      "x": 0,
      "y": 11,
      "z": 0,
      "name": "Cloth_Block_Wool_Orange"
    },
    {
      "x": 0,
      "y": 0,
      "z": 1,
      "name": "Cloth_Block_Wool_Blue_Light"
    },
    {
      "x": 0,
      "y": 6,
      "z": 1,
      "name": "Cloth_Block_Wool_Orange"
    },
    {
      "x": 0,
      "y": 7,
      "z": 1,
      "name": "Cloth_Block_Wool_Orange"
    },
    {
      "x": 0,
      "y": 8,
      "z": 1,
      "name": "Cloth_Block_Wool_Orange"
    },
    {
      "x": 0,
      "y": 9,
      "z": 1,
      "name": "Cloth_Block_Wool_Orange"
    },
    {
      "x": 0,
      "y": 10,
      "z": 1,
      "name": "Cloth_Block_Wool_Orange"
    },
    {
      "x": 0,
      "y": 11,
      "z": 1,
      "name": "Cloth_Block_Wool_Orange"
    },
    {
      "x": 0,
      "y": 0,
      "z": 2,
      "name": "Cloth_Block_Wool_Blue_Light"
    },
    {
      "x": 0,
      "y": 1,
      "z": 2,
      "name": "Cloth_Block_Wool_Blue_Light"
    },
    {
      "x": 0,
      "y": 7,
      "z": 2,
      "name": "Cloth_Block_Wool_Orange"
    },
    {
      "x": 0,
      "y": 8,
      "z": 2,
      "name": "Cloth_Block_Wool_Orange"
    },
    {
      "x": 0,
      "y": 9,
      "z": 2,
      "name": "Cloth_Block_Wool_Orange"
    },
    {
      "x": 0,
      "y": 10,
      "z": 2,
      "name": "Cloth_Block_Wool_Orange"
    },
    {
      "x": 0,
      "y": 11,
      "z": 2,
      "name": "Cloth_Block_Wool_Orange"
    },
    {
      "x": 0,
      "y": 0,
      "z": 3,
      "name": "Cloth_Block_Wool_Blue_Light"
    },
    {
      "x": 0,
      "y": 6,
      "z": 3,
      "name": "Cloth_Block_Wool_Orange"
    },
    {
      "x": 0,
      "y": 7,
      "z": 3,
      "name": "Cloth_Block_Wool_Orange"
    },
    {
      "x": 0,
      "y": 8,
      "z": 3,
      "name": "Cloth_Block_Wool_Orange"
    },
    {
      "x": 0,
      "y": 9,
      "z": 3,
      "name": "Cloth_Block_Wool_Orange"
    },
    {
      "x": 0,
      "y": 10,
      "z": 3,
      "name": "Cloth_Block_Wool_Orange"
    },
    {
      "x": 0,
      "y": 11,
      "z": 3,
      "name": "Cloth_Block_Wool_Orange"
    },
    {
      "x": 0,
      "y": 0,
      "z": 4,
      "name": "Cloth_Block_Wool_Blue_Light"
    },
    {
      "x": 0,
      "y": 6,
      "z": 4,
      "name": "Cloth_Block_Wool_Orange"
    },
    {
      "x": 0,
      "y": 7,
      "z": 4,
      "name": "Cloth_Block_Wool_Orange"
    },
    {
      "x": 0,
      "y": 8,
      "z": 4,
      "name": "Cloth_Block_Wool_Orange"
    },
    {
      "x": 0,
      "y": 9,
      "z": 4,
      "name": "Cloth_Block_Wool_Orange"
    },
    {
      "x": 0,
      "y": 10,
      "z": 4,
      "name": "Cloth_Block_Wool_Orange"
    },
    {
      "x": 0,
      "y": 0,
      "z": 5,
      "name": "Cloth_Block_Wool_Blue_Light"
    },
    {
      "x": 0,
      "y": 6,
      "z": 5,
      "name": "Cloth_Block_Wool_Orange"
    },
    {
      "x": 0,
      "y": 7,
      "z": 5,
      "name": "Cloth_Block_Wool_Orange"
    },
    {
      "x": 0,
      "y": 8,
      "z": 5,
      "name": "Cloth_Block_Wool_Orange"
    },
    {
      "x": 0,
      "y": 9,
      "z": 5,
      "name": "Cloth_Block_Wool_Orange"
    },
    {
      "x": 0,
      "y": 10,
      "z": 5,
      "name": "Cloth_Block_Wool_Orange"
    },
    {
      "x": 0,
      "y": 0,
      "z": 6,
      "name": "Cloth_Block_Wool_Blue_Light"
    },
    {
      "x": 0,
      "y": 1,
      "z": 6,
      "name": "Cloth_Block_Wool_Blue_Light"
    },
    {
      "x": 0,
      "y": 7,
      "z": 6,
      "name": "Cloth_Block_Wool_Orange"
    },
    {
      "x": 0,
      "y": 8,
      "z": 6,
      "name": "Cloth_Block_Wool_Orange"
    },
    {
      "x": 0,
      "y": 9,
      "z": 6,
      "name": "Cloth_Block_Wool_Orange"
    },
    {
      "x": 0,
      "y": 10,
      "z": 6,
      "name": "Cloth_Block_Wool_Orange"
    },
    {
      "x": 0,
      "y": 0,
      "z": 7,
      "name": "Cloth_Block_Wool_Blue_Light"
    },
    {
      "x": 0,
      "y": 1,
      "z": 7,
      "name": "Cloth_Block_Wool_Blue_Light"
    },
    {
      "x": 0,
      "y": 2,
      "z": 7,
      "name": "Cloth_Block_Wool_Blue_Light"
    },
    {
      "x": 0,
      "y": 8,
      "z": 7,
      "name": "Cloth_Block_Wool_Orange"
    },
    {
      "x": 0,
      "y": 9,
      "z": 7,
      "name": "Cloth_Block_Wool_Orange"
    },
    {
      "x": 0,
      "y": 10,
      "z": 7,
      "name": "Cloth_Block_Wool_Orange"
    },
    {
      "x": 0,
      "y": 0,
      "z": 8,
      "name": "Cloth_Block_Wool_Blue_Light"
    },
    {
      "x": 0,
      "y": 1,
      "z": 8,
      "name": "Cloth_Block_Wool_Blue_Light"
    },
    {
      "x": 0,
      "y": 2,
      "z": 8,
      "name": "Cloth_Block_Wool_Blue_Light"
    },
    {
      "x": 0,
      "y": 3,
      "z": 8,
      "name": "Cloth_Block_Wool_Blue_Light"
    },
    {
      "x": 0,
      "y": 4,
      "z": 8,
      "name": "Cloth_Block_Wool_Blue_Light"
    },
    {
      "x": 0,
      "y": 0,
      "z": 9,
      "name": "Cloth_Block_Wool_Blue_Light"
    },
    {
      "x": 0,
      "y": 1,
      "z": 9,
      "name": "Cloth_Block_Wool_Blue_Light"
    },
    {
      "x": 0,
      "y": 2,
      "z": 9,
      "name": "Cloth_Block_Wool_Blue_Light"
    },
    {
      "x": 0,
      "y": 3,
      "z": 9,
      "name": "Cloth_Block_Wool_Blue_Light"
    },
    {
      "x": 1,
      "y": 0,
      "z": -8,
      "name": "Cloth_Block_Wool_Blue_Light"
    },
    {
      "x": 1,
      "y": 1,
      "z": -8,
      "name": "Cloth_Block_Wool_Blue_Light"
    },
    {
      "x": 1,
      "y": 2,
      "z": -8,
      "name": "Cloth_Block_Wool_Blue_Light"
    },
    {
      "x": 1,
      "y": 3,
      "z": -8,
      "name": "Cloth_Block_Wool_Blue_Light"
    },
    {
      "x": 1,
      "y": 0,
      "z": -7,
      "name": "Cloth_Block_Wool_Blue_Light"
    },
    {
      "x": 1,
      "y": 1,
      "z": -7,
      "name": "Cloth_Block_Wool_Blue_Light"
    },
    {
      "x": 1,
      "y": 2,
      "z": -7,
      "name": "Cloth_Block_Wool_Blue_Light"
    },
    {
      "x": 1,
      "y": 3,
      "z": -7,
      "name": "Cloth_Block_Wool_Blue_Light"
    },
    {
      "x": 1,
      "y": 0,
      "z": -6,
      "name": "Cloth_Block_Wool_Blue_Light"
    },
    {
      "x": 1,
      "y": 1,
      "z": -6,
      "name": "Cloth_Block_Wool_Blue_Light"
    },
    {
      "x": 1,
      "y": 7,
      "z": -6,
      "name": "Cloth_Block_Wool_Orange"
    },
    {
      "x": 1,
      "y": 8,
      "z": -6,
      "name": "Cloth_Block_Wool_Orange"
    },
    {
      "x": 1,
      "y": 0,
      "z": -5,
      "name": "Cloth_Block_Wool_Blue_Light"
    },
    {
      "x": 1,
      "y": 6,
      "z": -5,
      "name": "Cloth_Block_Wool_Orange"
    },
    {
      "x": 1,
      "y": 7,
      "z": -5,
      "name": "Cloth_Block_Wool_Orange"
    },
    {
      "x": 1,
      "y": 8,
      "z": -5,
      "name": "Cloth_Block_Wool_Orange"
    },
    {
      "x": 1,
      "y": 9,
      "z": -5,
      "name": "Cloth_Block_Wool_Orange"
    },
    {
      "x": 1,
      "y": 0,
      "z": -4,
      "name": "Cloth_Block_Wool_Blue_Light"
    },
    {
      "x": 1,
      "y": 6,
      "z": -4,
      "name": "Cloth_Block_Wool_Orange"
    },
    {
      "x": 1,
      "y": 7,
      "z": -4,
      "name": "Cloth_Block_Wool_Orange"
    },
    {
      "x": 1,
      "y": 8,
      "z": -4,
      "name": "Cloth_Block_Wool_Orange"
    },
    {
      "x": 1,
      "y": 9,
      "z": -4,
      "name": "Cloth_Block_Wool_Orange"
    },
    {
      "x": 1,
      "y": 10,
      "z": -4,
      "name": "Cloth_Block_Wool_Orange"
    },
    {
      "x": 1,
      "y": 0,
      "z": -3,
      "name": "Cloth_Block_Wool_Blue_Light"
    },
    {
      "x": 1,
      "y": 6,
      "z": -3,
      "name": "Cloth_Block_Wool_Orange"
    },
    {
      "x": 1,
      "y": 7,
      "z": -3,
      "name": "Cloth_Block_Wool_Orange"
    },
    {
      "x": 1,
      "y": 8,
      "z": -3,
      "name": "Cloth_Block_Wool_Orange"
    },
    {
      "x": 1,
      "y": 9,
      "z": -3,
      "name": "Cloth_Block_Wool_Orange"
    },
    {
      "x": 1,
      "y": 10,
      "z": -3,
      "name": "Cloth_Block_Wool_Orange"
    },
    {
      "x": 1,
      "y": 0,
      "z": -2,
      "name": "Cloth_Block_Wool_Blue_Light"
    },
    {
      "x": 1,
      "y": 1,
      "z": -2,
      "name": "Cloth_Block_Wool_Blue_Light"
    },
    {
      "x": 1,
      "y": 7,
      "z": -2,
      "name": "Cloth_Block_Wool_Orange"
    },
    {
      "x": 1,
      "y": 8,
      "z": -2,
      "name": "Cloth_Block_Wool_Orange"
    },
    {
      "x": 1,
      "y": 9,
      "z": -2,
      "name": "Cloth_Block_Wool_Orange"
    },
    {
      "x": 1,
      "y": 10,
      "z": -2,
      "name": "Cloth_Block_Wool_Orange"
    },
    {
      "x": 1,
      "y": 0,
      "z": -1,
      "name": "Cloth_Block_Wool_Blue_Light"
    },
    {
      "x": 1,
      "y": 6,
      "z": -1,
      "name": "Cloth_Block_Wool_Orange"
    },
    {
      "x": 1,
      "y": 7,
      "z": -1,
      "name": "Cloth_Block_Wool_Orange"
    },
    {
      "x": 1,
      "y": 8,
      "z": -1,
      "name": "Cloth_Block_Wool_Orange"
    },
    {
      "x": 1,
      "y": 9,
      "z": -1,
      "name": "Cloth_Block_Wool_Orange"
    },
    {
      "x": 1,
      "y": 10,
      "z": -1,
      "name": "Cloth_Block_Wool_Orange"
    },
    {
      "x": 1,
      "y": 0,
      "z": 0,
      "name": "Cloth_Block_Wool_Blue_Light"
    },
    {
      "x": 1,
      "y": 6,
      "z": 0,
      "name": "Cloth_Block_Wool_Orange"
    },
    {
      "x": 1,
      "y": 7,
      "z": 0,
      "name": "Cloth_Block_Wool_Orange"
    },
    {
      "x": 1,
      "y": 8,
      "z": 0,
      "name": "Cloth_Block_Wool_Orange"
    },
    {
      "x": 1,
      "y": 9,
      "z": 0,
