{
  "version": 8,
  "blockIdVersion": 11,
  "anchorX": 0,
  "anchorY": 0,
  "anchorZ": 0,
  "blocks": [
    {
      "x": -39,
      "y": 1,
      "z": -40,
      "name": "Wood_Blackwood_Planks",
      "rotation": 3
    },
    {
      "x": -39,
      "y": 2,
      "z": -40,
      "name": "Cloth_Roof_White_Flat"
    },
    {
      "x": -39,
      "y": 3,
      "z": -40,
      "name": "Transparent_Light"
    },
    {
      "x": -39,
      "y": 1,
      "z": -39,
      "name": "Wood_Deadwood_Planks",
      "rotation": 3
    },
    {
      "x": -39,
      "y": 2,
      "z": -39,
      "name": "Cloth_Roof_White_Flat"
    },
    {
      "x": -39,
      "y": 1,
      "z": -38,
      "name": "Wood_Deadwood_Planks",
      "rotation": 3
    },
    {
      "x": -39,
      "y": 2,
      "z": -38,
      "name": "Cloth_Roof_White_Flat"
    },
    {
      "x": -39,
      "y": 1,
      "z": -37,
      "name": "Wood_Deadwood_Planks",
      "rotation": 3
    },
    {
      "x": -39,
      "y": 2,
      "z": -37,
      "name": "Cloth_Roof_White_Flat"
    },
    {
      "x": -39,
      "y": 1,
      "z": -36,
      "name": "Wood_Blackwood_Planks",
      "rotation": 3
    },
    {
      "x": -39,
      "y": 2,
      "z": -36,
      "name": "Cloth_Roof_White_Flat"
    },
    {
      "x": -39,
      "y": 1,
      "z": -35,
      "name": "Wood_Deadwood_Planks",
      "rotation": 3
    },
    {
      "x": -39,
      "y": 2,
      "z": -35,
      "name": "Cloth_Roof_White_Flat"
    },
    {
      "x": -39,
      "y": 1,
      "z": -34,
      "name": "Wood_Deadwood_Planks",
      "rotation": 3
    },
    {
      "x": -39,
      "y": 2,
      "z": -34,
      "name": "Cloth_Roof_White_Flat"
    },
    {
      "x": -39,
      "y": 1,
      "z": -33,
      "name": "Wood_Deadwood_Planks",
      "rotation": 3
    },
    {
      "x": -39,
      "y": 2,
      "z": -33,
      "name": "Cloth_Roof_White_Flat"
    },
    {
      "x": -39,
      "y": 1,
      "z": -32,
      "name": "Wood_Blackwood_Planks",
      "rotation": 3
    },
    {
      "x": -39,
      "y": 2,
      "z": -32,
      "name": "Cloth_Roof_White_Flat"
    },
    {
      "x": -39,
      "y": 3,
      "z": -32,
      "name": "Transparent_Light"
    },
    {
      "x": -39,
      "y": 1,
      "z": -31,
      "name": "Wood_Deadwood_Planks",
      "rotation": 3
    },
    {
      "x": -39,
      "y": 2,
      "z": -31,
      "name": "Cloth_Roof_White_Flat"
    },
    {
      "x": -39,
      "y": 1,
      "z": -30,
      "name": "Wood_Deadwood_Planks",
      "rotation": 3
    },
    {
      "x": -39,
      "y": 2,
      "z": -30,
      "name": "Cloth_Roof_White_Flat"
    },
    {
      "x": -39,
      "y": 1,
      "z": -29,
      "name": "Wood_Deadwood_Planks",
      "rotation": 3
    },
    {
      "x": -39,
      "y": 2,
      "z": -29,
      "name": "Cloth_Roof_White_Flat"
    },
    {
      "x": -39,
      "y": 1,
      "z": -28,
      "name": "Wood_Blackwood_Planks",
      "rotation": 3
    },
    {
      "x": -39,
      "y": 2,
      "z": -28,
      "name": "Cloth_Roof_White_Flat"
    },
    {
      "x": -39,
      "y": 1,
      "z": -27,
      "name": "Wood_Deadwood_Planks",
      "rotation": 3
    },
    {
      "x": -39,
      "y": 2,
      "z": -27,
      "name": "Cloth_Roof_White_Flat"
    },
    {
      "x": -39,
      "y": 1,
      "z": -26,
      "name": "Wood_Deadwood_Planks",
      "rotation": 3
    },
    {
      "x": -39,
      "y": 2,
      "z": -26,
      "name": "Cloth_Roof_White_Flat"
    },
    {
      "x": -39,
      "y": 1,
      "z": -25,
      "name": "Wood_Deadwood_Planks",
      "rotation": 3
    },
    {
      "x": -39,
      "y": 2,
      "z": -25,
      "name": "Cloth_Roof_White_Flat"
    },
    {
      "x": -39,
      "y": 1,
      "z": -24,
      "name": "Wood_Blackwood_Planks",
      "rotation": 3
    },
    {
      "x": -39,
      "y": 2,
      "z": -24,
      "name": "Cloth_Roof_White_Flat"
    },
    {
      "x": -39,
      "y": 3,
      "z": -24,
      "name": "Transparent_Light"
    },
    {
      "x": -39,
      "y": 1,
      "z": -23,
      "name": "Wood_Deadwood_Planks",
      "rotation": 3
    },
    {
      "x": -39,
      "y": 2,
      "z": -23,
      "name": "Cloth_Roof_White_Flat"
    },
    {
      "x": -39,
      "y": 1,
      "z": -22,
      "name": "Wood_Deadwood_Planks",
      "rotation": 3
    },
    {
      "x": -39,
      "y": 2,
      "z": -22,
      "name": "Cloth_Roof_White_Flat"
    },
    {
      "x": -39,
      "y": 1,
      "z": -21,
      "name": "Wood_Deadwood_Planks",
      "rotation": 3
    },
    {
      "x": -39,
      "y": 2,
      "z": -21,
      "name": "Cloth_Roof_White_Flat"
    },
    {
      "x": -39,
      "y": 1,
      "z": -20,
      "name": "Wood_Blackwood_Planks",
      "rotation": 3
    },
    {
      "x": -39,
      "y": 2,
      "z": -20,
      "name": "Cloth_Roof_White_Flat"
    },
    {
      "x": -39,
      "y": 1,
      "z": -19,
      "name": "Wood_Deadwood_Planks",
      "rotation": 3
    },
    {
      "x": -39,
      "y": 2,
      "z": -19,
      "name": "Cloth_Roof_White_Flat"
    },
    {
      "x": -39,
      "y": 1,
      "z": -18,
      "name": "Wood_Deadwood_Planks",
      "rotation": 3
    },
    {
      "x": -39,
      "y": 2,
      "z": -18,
      "name": "Cloth_Roof_White_Flat"
    },
    {
      "x": -39,
      "y": 1,
      "z": -17,
      "name": "Wood_Deadwood_Planks",
      "rotation": 3
    },
    {
      "x": -39,
      "y": 2,
      "z": -17,
      "name": "Cloth_Roof_White_Flat"
    },
    {
      "x": -39,
      "y": 1,
      "z": -16,
      "name": "Wood_Blackwood_Planks",
      "rotation": 3
    },
    {
      "x": -39,
      "y": 2,
      "z": -16,
      "name": "Cloth_Roof_White_Flat"
    },
    {
      "x": -39,
      "y": 3,
      "z": -16,
      "name": "Transparent_Light"
    },
    {
      "x": -39,
      "y": 1,
      "z": -15,
      "name": "Wood_Deadwood_Planks",
      "rotation": 3
    },
    {
      "x": -39,
      "y": 2,
      "z": -15,
      "name": "Cloth_Roof_White_Flat"
    },
    {
      "x": -39,
      "y": 1,
      "z": -14,
      "name": "Wood_Deadwood_Planks",
      "rotation": 3
    },
    {
      "x": -39,
      "y": 2,
      "z": -14,
      "name": "Cloth_Roof_White_Flat"
    },
    {
      "x": -39,
      "y": 1,
      "z": -13,
      "name": "Wood_Deadwood_Planks",
      "rotation": 3
    },
    {
      "x": -39,
      "y": 2,
      "z": -13,
      "name": "Cloth_Roof_White_Flat"
    },
    {
      "x": -39,
      "y": 1,
      "z": -12,
      "name": "Wood_Blackwood_Planks",
      "rotation": 3
    },
    {
      "x": -39,
      "y": 2,
      "z": -12,
      "name": "Cloth_Roof_White_Flat"
    },
    {
      "x": -39,
      "y": 1,
      "z": -11,
      "name": "Wood_Deadwood_Planks",
      "rotation": 3
    },
    {
      "x": -39,
      "y": 2,
      "z": -11,
      "name": "Cloth_Roof_White_Flat"
    },
    {
      "x": -39,
      "y": 1,
      "z": -10,
      "name": "Wood_Deadwood_Planks",
      "rotation": 3
    },
    {
      "x": -39,
      "y": 2,
      "z": -10,
      "name": "Cloth_Roof_White_Flat"
    },
    {
      "x": -39,
      "y": 1,
      "z": -9,
      "name": "Wood_Deadwood_Planks",
      "rotation": 3
    },
    {
      "x": -39,
      "y": 2,
      "z": -9,
      "name": "Cloth_Roof_White_Flat"
    },
    {
      "x": -39,
      "y": 1,
      "z": -8,
      "name": "Soil_Dirt_Burnt"
    },
    {
      "x": -39,
      "y": 3,
      "z": -8,
      "name": "Transparent_Light"
    },
    {
      "x": -39,
      "y": 1,
      "z": -7,
      "name": "Soil_Dirt_Burnt"
    },
    {
      "x": -39,
      "y": 2,
      "z": -7,
      "name": "Plant_Moss_Green_Dark",
      "support": 15
    },
    {
      "x": -39,
      "y": 1,
      "z": -6,
      "name": "Soil_Dirt_Burnt"
    },
    {
      "x": -39,
      "y": 3,
      "z": -6,
      "name": "Plant_Leaves_Oak",
      "support": 15
    },
    {
      "x": -39,
      "y": 4,
      "z": -6,
      "name": "Plant_Leaves_Oak",
      "support": 15
    },
    {
      "x": -39,
      "y": 1,
      "z": -5,
      "name": "Soil_Dirt_Burnt"
    },
    {
      "x": -39,
      "y": 2,
      "z": -5,
      "name": "Wood_Darkwood_Beam"
    },
    {
      "x": -39,
      "y": 3,
      "z": -5,
      "name": "Wood_Darkwood_Beam"
    },
    {
      "x": -39,
      "y": 4,
      "z": -5,
      "name": "Wood_Darkwood_Beam"
    },
    {
      "x": -39,
      "y": 5,
      "z": -5,
      "name": "Wood_Darkwood_Beam"
    },
    {
      "x": -39,
      "y": 6,
      "z": -5,
      "name": "Plant_Leaves_Oak",
      "support": 15
    },
    {
      "x": -39,
      "y": 1,
      "z": -4,
      "name": "Wood_Blackwood_Planks",
      "rotation": 3
    },
    {
      "x": -39,
      "y": 3,
      "z": -4,
      "name": "Plant_Leaves_Oak",
      "support": 15
    },
    {
      "x": -39,
      "y": 4,
      "z": -4,
      "name": "Plant_Leaves_Oak",
      "support": 15
    },
    {
      "x": -39,
      "y": 1,
      "z": -3,
      "name": "Wood_Deadwood_Planks",
      "rotation": 3
    },
    {
      "x": -39,
      "y": 2,
      "z": -3,
      "name": "Cloth_Roof_White_Flat"
    },
    {
      "x": -39,
      "y": 1,
      "z": -2,
      "name": "Wood_Deadwood_Planks",
      "rotation": 3
    },
    {
      "x": -39,
      "y": 2,
      "z": -2,
      "name": "Cloth_Roof_White_Flat"
    },
    {
      "x": -39,
      "y": 1,
      "z": -1,
      "name": "Wood_Deadwood_Planks",
      "rotation": 3
    },
    {
      "x": -39,
      "y": 2,
      "z": -1,
      "name": "Cloth_Roof_White_Flat"
    },
    {
      "x": -39,
      "y": 1,
      "z": 0,
      "name": "Wood_Blackwood_Planks",
      "rotation": 3
    },
    {
      "x": -39,
      "y": 2,
      "z": 0,
      "name": "Cloth_Roof_White_Flat"
    },
    {
      "x": -39,
      "y": 1,
      "z": 1,
      "name": "Wood_Deadwood_Planks",
      "rotation": 3
    },
    {
      "x": -39,
      "y": 2,
      "z": 1,
      "name": "Cloth_Roof_White_Flat"
    },
    {
      "x": -39,
      "y": 3,
      "z": 1,
      "name": "Transparent_Light"
    },
    {
      "x": -39,
      "y": 1,
      "z": 2,
      "name": "Wood_Deadwood_Planks",
      "rotation": 3
    },
    {
      "x": -39,
      "y": 2,
      "z": 2,
      "name": "Cloth_Roof_White_Flat"
    },
    {
      "x": -39,
      "y": 1,
      "z": 3,
      "name": "Wood_Deadwood_Planks",
      "rotation": 3
    },
    {
      "x": -39,
      "y": 2,
      "z": 3,
      "name": "Cloth_Roof_White_Flat"
    },
    {
      "x": -39,
      "y": 1,
      "z": 4,
      "name": "Wood_Blackwood_Planks",
      "rotation": 3
    },
    {
      "x": -39,
      "y": 2,
      "z": 4,
      "name": "Cloth_Roof_White_Flat"
    },
    {
      "x": -39,
      "y": 1,
      "z": 5,
      "name": "Wood_Deadwood_Planks",
      "rotation": 3
    },
    {
      "x": -39,
      "y": 2,
      "z": 5,
      "name": "Cloth_Roof_White_Flat"
    },
    {
      "x": -39,
      "y": 1,
      "z": 6,
      "name": "Wood_Deadwood_Planks",
      "rotation": 3
    },
    {
      "x": -39,
      "y": 2,
      "z": 6,
      "name": "Cloth_Roof_White_Flat"
    },
    {
      "x": -39,
      "y": 1,
      "z": 7,
      "name": "Wood_Deadwood_Planks",
      "rotation": 3
    },
    {
      "x": -39,
      "y": 2,
      "z": 7,
      "name": "Cloth_Roof_White_Flat"
    },
    {
      "x": -39,
      "y": 1,
      "z": 8,
      "name": "Wood_Blackwood_Planks",
      "rotation": 3
    },
    {
      "x": -39,
      "y": 2,
      "z": 8,
      "name": "Cloth_Roof_White_Flat"
    },
    {
      "x": -39,
      "y": 3,
      "z": 8,
      "name": "Transparent_Light"
    },
    {
      "x": -39,
      "y": 1,
      "z": 9,
      "name": "Wood_Deadwood_Planks",
      "rotation": 3
    },
    {
      "x": -39,
      "y": 2,
      "z": 9,
      "name": "Cloth_Roof_White_Flat"
    },
    {
      "x": -39,
      "y": 1,
      "z": 10,
      "name": "Wood_Deadwood_Planks",
      "rotation": 3
    },
    {
      "x": -39,
      "y": 2,
      "z": 10,
      "name": "Cloth_Roof_White_Flat"
    },
    {
      "x": -39,
      "y": 1,
      "z": 11,
      "name": "Wood_Deadwood_Planks",
      "rotation": 3
    },
    {
      "x": -39,
      "y": 2,
      "z": 11,
      "name": "Cloth_Roof_White_Flat"
    },
    {
      "x": -39,
      "y": 1,
      "z": 12,
      "name": "Wood_Blackwood_Planks",
      "rotation": 3
    },
    {
      "x": -39,
      "y": 2,
      "z": 12,
      "name": "Cloth_Roof_White_Flat"
    },
    {
      "x": -39,
      "y": 1,
      "z": 13,
      "name": "Wood_Deadwood_Planks",
      "rotation": 3
    },
    {
      "x": -39,
      "y": 2,
      "z": 13,
      "name": "Cloth_Roof_White_Flat"
    },
    {
      "x": -39,
      "y": 1,
      "z": 14,
      "name": "Wood_Deadwood_Planks",
      "rotation": 3
    },
    {
      "x": -39,
      "y": 2,
      "z": 14,
      "name": "Cloth_Roof_White_Flat"
    },
    {
      "x": -39,
      "y": 1,
      "z": 15,
      "name": "Wood_Deadwood_Planks",
      "rotation": 3
    },
    {
      "x": -39,
      "y": 2,
      "z": 15,
      "name": "Cloth_Roof_White_Flat"
    },
    {
      "x": -39,
      "y": 1,
      "z": 16,
      "name": "Wood_Blackwood_Planks",
      "rotation": 3
    },
    {
      "x": -39,
      "y": 2,
      "z": 16,
      "name": "Cloth_Roof_White_Flat"
    },
    {
      "x": -39,
      "y": 3,
      "z": 16,
      "name": "Transparent_Light"
    },
    {
      "x": -39,
      "y": 1,
      "z": 17,
      "name": "Wood_Deadwood_Planks",
      "rotation": 3
    },
    {
      "x": -39,
      "y": 2,
      "z": 17,
      "name": "Cloth_Roof_White_Flat"
    },
    {
      "x": -39,
      "y": 1,
      "z": 18,
      "name": "Wood_Deadwood_Planks",
      "rotation": 3
    },
    {
      "x": -39,
      "y": 2,
      "z": 18,
      "name": "Cloth_Roof_White_Flat"
    },
    {
      "x": -39,
      "y": 22,
      "z": 18,
      "name": "Rock_Basalt_Brick_Smooth_Half",
      "rotation": 11
    },
    {
      "x": -39,
      "y": 1,
      "z": 19,
      "name": "Wood_Deadwood_Planks",
      "rotation": 3
    },
    {
      "x": -39,
      "y": 2,
      "z": 19,
      "name": "Cloth_Roof_White_Flat"
    },
    {
      "x": -39,
      "y": 22,
      "z": 19,
      "name": "Rock_Basalt_Brick_Smooth",
      "rotation": 3
    },
    {
      "x": -39,
      "y": 1,
      "z": 20,
      "name": "Wood_Blackwood_Planks",
      "rotation": 3
    },
    {
      "x": -39,
      "y": 2,
      "z": 20,
      "name": "Cloth_Roof_White_Flat"
    },
    {
      "x": -39,
      "y": 20,
      "z": 20,
      "name": "Rock_Basalt_Brick_Smooth",
      "rotation": 3
    },
    {
      "x": -39,
      "y": 21,
      "z": 20,
      "name": "Rock_Basalt_Brick_Smooth",
      "rotation": 3
    },
    {
      "x": -39,
      "y": 22,
      "z": 20,
      "name": "Rock_Basalt_Brick_Smooth",
      "rotation": 3
    },
    {
      "x": -39,
      "y": 1,
      "z": 21,
      "name": "Wood_Deadwood_Planks",
      "rotation": 3
    },
    {
      "x": -39,
      "y": 2,
      "z": 21,
      "name": "Cloth_Roof_White_Flat"
    },
    {
      "x": -39,
      "y": 18,
      "z": 21,
      "name": "Rock_Basalt_Brick_Smooth",
      "rotation": 3
    },
    {
      "x": -39,
      "y": 19,
      "z": 21,
      "name": "Rock_Basalt_Brick_Smooth",
      "rotation": 3
    },
    {
      "x": -39,
      "y": 20,
      "z": 21,
      "name": "Rock_Stone_Brick_Smooth",
      "rotation": 3
    },
    {
      "x": -39,
      "y": 21,
      "z": 21,
      "name": "Rock_Stone_Brick_Smooth",
      "rotation": 3
    },
    {
      "x": -39,
      "y": 22,
      "z": 21,
      "name": "Rock_Stone",
      "rotation": 3
    },
    {
      "x": -39,
      "y": 23,
      "z": 21,
      "name": "Rock_Basalt_Brick",
      "rotation": 3
    },
    {
      "x": -39,
      "y": 24,
      "z": 21,
      "name": "Rock_Basalt_Brick",
      "rotation": 3
    },
    {
      "x": -39,
      "y": 25,
      "z": 21,
      "name": "Rock_Basalt_Brick",
      "rotation": 3
    },
    {
      "x": -39,
      "y": 1,
      "z": 22,
      "name": "Wood_Deadwood_Planks",
      "rotation": 3
    },
    {
      "x": -39,
      "y": 2,
      "z": 22,
      "name": "Cloth_Roof_White_Flat"
    },
    {
      "x": -39,
      "y": 18,
      "z": 22,
      "name": "Rock_Stone_Brick_Smooth",
      "rotation": 3
    },
    {
      "x": -39,
      "y": 19,
      "z": 22,
      "name": "Rock_Stone_Brick_Smooth",
      "rotation": 3
    },
    {
      "x": -39,
      "y": 20,
      "z": 22,
      "name": "Wood_Hardwood_Planks",
      "rotation": 3
    },
    {
      "x": -39,
      "y": 21,
      "z": 22,
      "name": "Rock_Basalt_Brick_Smooth",
      "rotation": 3
    },
    {
      "x": -39,
      "y": 22,
      "z": 22,
      "name": "Rock_Basalt_Brick_Smooth",
      "rotation": 3
    },
    {
      "x": -39,
      "y": 23,
      "z": 22,
      "name": "Rock_Basalt_Brick_Smooth",
      "rotation": 3
    },
    {
      "x": -39,
      "y": 24,
      "z": 22,
      "name": "Rock_Basalt_Brick_Smooth",
      "rotation": 3
    },
    {
      "x": -39,
      "y": 25,
      "z": 22,
      "name": "Rock_Basalt_Brick_Smooth",
      "rotation": 3
    },
    {
      "x": -39,
      "y": 1,
      "z": 23,
      "name": "Wood_Deadwood_Planks",
      "rotation": 3
    },
    {
      "x": -39,
      "y": 2,
      "z": 23,
      "name": "Cloth_Roof_White_Flat"
    },
    {
      "x": -39,
      "y": 18,
      "z": 23,
      "name": "Rock_Stone",
      "rotation": 3
    },
    {
      "x": -39,
      "y": 19,
      "z": 23,
      "name": "Rock_Stone",
      "rotation": 3
    },
    {
      "x": -39,
      "y": 20,
      "z": 23,
      "name": "Wood_Hardwood_Stairs"
    },
    {
      "x": -39,
      "y": 1,
      "z": 24,
      "name": "Rock_Stone_Brick_Smooth"
    },
    {
      "x": -39,
      "y": 18,
      "z": 24,
      "name": "Rock_Stone",
      "rotation": 3
    },
    {
      "x": -39,
      "y": 19,
      "z": 24,
      "name": "Rock_Stone",
      "rotation": 3
    },
    {
      "x": -39,
      "y": 20,
      "z": 24,
      "name": "Wood_Hardwood_Planks",
      "rotation": 3
    },
    {
      "x": -39,
      "y": 1,
      "z": 25,
      "name": "Rock_Stone_Brick_Half"
    },
    {
      "x": -39,
      "y": 18,
      "z": 25,
      "name": "Rock_Stone",
      "rotation": 3
    },
    {
      "x": -39,
      "y": 19,
      "z": 25,
      "name": "Rock_Stone",
      "rotation": 3
    },
    {
      "x": -39,
      "y": 20,
      "z": 25,
      "name": "Wood_Hardwood_Planks",
      "rotation": 3
    },
    {
      "x": -39,
      "y": 1,
      "z": 26,
      "name": "Rock_Stone_Brick_Half"
    },
    {
      "x": -39,
      "y": 12,
      "z": 26,
      "name": "Wood_Darkwood_Planks_Half",
      "rotation": 11
    },
    {
      "x": -39,
      "y": 14,
      "z": 26,
      "name": "Wood_Darkwood_Planks_Half",
      "rotation": 3
    },
    {
      "x": -39,
      "y": 15,
      "z": 26,
      "name": "Wood_Darkwood_Planks_Half",
      "rotation": 11
    },
    {
      "x": -39,
      "y": 17,
      "z": 26,
      "name": "Wood_Darkwood_Planks_Half",
      "rotation": 3
    },
    {
      "x": -39,
      "y": 18,
      "z": 26,
      "name": "Rock_Stone",
      "rotation": 3
    },
    {
      "x": -39,
      "y": 19,
      "z": 26,
      "name": "Rock_Stone",
      "rotation": 3
    },
    {
      "x": -39,
      "y": 20,
      "z": 26,
      "name": "Wood_Hardwood_Planks",
      "rotation": 3
    },
    {
      "x": -39,
      "y": 0,
      "z": 27,
      "name": "Rock_Stone_Brick_Half",
      "rotation": 8
    },
    {
      "x": -39,
      "y": 18,
      "z": 27,
      "name": "Soil_Clay_Grey",
      "rotation": 3
    },
    {
      "x": -39,
      "y": 19,
      "z": 27,
      "name": "Soil_Clay_Grey",
      "rotation": 3
    },
    {
      "x": -39,
      "y": 20,
      "z": 27,
      "name": "Wood_Hardwood_Planks",
      "rotation": 3
    },
    {
      "x": -39,
      "y": 0,
      "z": 28,
      "name": "Rock_Stone_Brick_Half",
      "rotation": 8
    },
    {
      "x": -39,
      "y": 18,
      "z": 28,
      "name": "Rock_Stone_Brick_Smooth",
      "rotation": 3
    },
    {
      "x": -39,
      "y": 19,
      "z": 28,
      "name": "Soil_Clay_Grey",
      "rotation": 3
    },
    {
      "x": -39,
      "y": 20,
      "z": 28,
      "name": "Wood_Hardwood_Planks",
      "rotation": 3
    },
    {
      "x": -39,
      "y": 0,
      "z": 29,
      "name": "Rock_Stone_Brick_Half"
    },
    {
      "x": -39,
      "y": 18,
      "z": 29,
      "name": "Soil_Clay_Grey",
      "rotation": 3
    },
    {
      "x": -39,
      "y": 19,
      "z": 29,
      "name": "Soil_Clay_Grey",
      "rotation": 3
    },
    {
      "x": -39,
      "y": 20,
      "z": 29,
      "name": "Wood_Hardwood_Planks",
      "rotation": 3
    },
    {
      "x": -39,
      "y": 0,
      "z": 30,
      "name": "Rock_Stone_Brick_Half"
    },
    {
      "x": -39,
      "y": 18,
      "z": 30,
      "name": "Soil_Clay_Grey",
      "rotation": 3
    },
    {
      "x": -39,
      "y": 19,
      "z": 30,
      "name": "Soil_Clay_Grey",
      "rotation": 3
    },
    {
      "x": -39,
      "y": 20,
      "z": 30,
      "name": "Wood_Hardwood_Planks",
      "rotation": 3
    },
    {
      "x": -39,
      "y": 18,
      "z": 31,
      "name": "Soil_Clay_Grey",
      "rotation": 3
    },
    {
      "x": -39,
      "y": 19,
      "z": 31,
      "name": "Soil_Clay_Grey",
      "rotation": 3
    },
    {
      "x": -39,
      "y": 20,
      "z": 31,
      "name": "Wood_Hardwood_Stairs"
    },
    {
      "x": -39,
      "y": 18,
      "z": 32,
      "name": "Soil_Clay_Grey",
      "rotation": 3
    },
    {
      "x": -39,
      "y": 19,
      "z": 32,
      "name": "Rock_Stone_Brick_Smooth",
      "rotation": 3
    },
    {
      "x": -39,
      "y": 20,
      "z": 32,
      "name": "Wood_Hardwood_Planks",
      "rotation": 3
    },
    {
      "x": -39,
      "y": 21,
      "z": 32,
      "name": "Rock_Basalt_Brick_Smooth",
      "rotation": 3
    },
    {
      "x": -39,
      "y": 22,
      "z": 32,
      "name": "Rock_Basalt_Brick_Smooth",
      "rotation": 3
    },
    {
      "x": -39,
      "y": 23,
      "z": 32,
      "name": "Rock_Basalt_Brick_Smooth",
      "rotation": 3
    },
    {
      "x": -39,
      "y": 24,
      "z": 32,
      "name": "Rock_Basalt_Brick_Smooth",
      "rotation": 3
    },
    {
      "x": -39,
      "y": 25,
      "z": 32,
      "name": "Rock_Basalt_Brick_Smooth",
      "rotation": 3
    },
    {
      "x": -39,
      "y": 18,
      "z": 33,
      "name": "Rock_Stone_Brick_Smooth",
      "rotation": 3
    },
    {
      "x": -39,
      "y": 19,
      "z": 33,
      "name": "Rock_Stone",
      "rotation": 3
    },
    {
      "x": -39,
      "y": 20,
      "z": 33,
      "name": "Rock_Stone_Brick_Smooth",
      "rotation": 3
    },
    {
      "x": -39,
      "y": 21,
      "z": 33,
      "name": "Rock_Stone_Brick_Smooth",
      "rotation": 3
    },
    {
      "x": -39,
      "y": 22,
      "z": 33,
      "name": "Rock_Stone",
      "rotation": 3
    },
    {
      "x": -39,
      "y": 23,
      "z": 33,
      "name": "Rock_Stone",
      "rotation": 3
    },
    {
      "x": -39,
      "y": 24,
      "z": 33,
      "name": "Rock_Stone",
      "rotation": 3
    },
    {
      "x": -39,
      "y": 25,
      "z": 33,
      "name": "Rock_Stone",
      "rotation": 3
    },
    {
      "x": -39,
      "y": 20,
      "z": 34,
      "name": "*Rock_Stone_Brick_Smooth_Half_State_Definitions_Block",
      "rotation": 11
    },
    {
      "x": -39,
      "y": 21,
      "z": 34,
      "name": "Rock_Stone_Brick_Smooth_Half",
      "rotation": 11
    },
    {
      "x": -39,
      "y": 22,
      "z": 34,
      "name": "Rock_Stone_Brick_Smooth",
      "rotation": 3
    },
    {
      "x": -39,
      "y": 23,
      "z": 34,
      "name": "Rock_Stone_Brick_Smooth",
      "rotation": 3
    },
    {
      "x": -39,
      "y": 24,
      "z": 34,
      "name": "Rock_Stone_Brick_Smooth",
      "rotation": 3
    },
    {
      "x": -39,
      "y": 25,
      "z": 34,
      "name": "Rock_Stone_Brick_Smooth",
      "rotation": 3
    },
    {
      "x": -38,
      "y": 1,
      "z": -40,
      "name": "Wood_Blackwood_Planks",
      "rotation": 3
    },
    {
      "x": -38,
      "y": 2,
      "z": -40,
      "name": "Cloth_Roof_White_Flat"
    },
    {
      "x": -38,
      "y": 1,
      "z": -39,
      "name": "Wood_Blackwood_Planks",
      "rotation": 3
    },
    {
      "x": -38,
      "y": 2,
      "z": -39,
      "name": "Cloth_Roof_Red_Flat"
    },
    {
      "x": -38,
      "y": 1,
      "z": -38,
      "name": "Wood_Blackwood_Planks",
      "rotation": 3
    },
    {
      "x": -38,
      "y": 2,
      "z": -38,
      "name": "Cloth_Roof_Red_Flat"
    },
    {
      "x": -38,
      "y": 1,
      "z": -37,
      "name": "Wood_Blackwood_Planks",
      "rotation": 3
    },
    {
      "x": -38,
      "y": 2,
      "z": -37,
      "name": "Cloth_Roof_Red_Flat"
    },
    {
      "x": -38,
      "y": 1,
      "z": -36,
      "name": "Wood_Blackwood_Planks",
      "rotation": 3
    },
    {
      "x": -38,
      "y": 2,
      "z": -36,
      "name": "Cloth_Roof_Red_Flat"
    },
    {
      "x": -38,
      "y": 1,
      "z": -35,
      "name": "Wood_Blackwood_Planks",
      "rotation": 3
    },
    {
      "x": -38,
      "y": 2,
      "z": -35,
      "name": "Cloth_Roof_Red_Flat"
    },
    {
      "x": -38,
      "y": 1,
      "z": -34,
      "name": "Wood_Blackwood_Planks",
      "rotation": 3
    },
    {
      "x": -38,
      "y": 2,
      "z": -34,
      "name": "Cloth_Roof_Red_Flat"
    },
    {
      "x": -38,
      "y": 1,
      "z": -33,
      "name": "Wood_Blackwood_Planks",
      "rotation": 3
    },
    {
      "x": -38,
      "y": 2,
      "z": -33,
      "name": "Cloth_Roof_Red_Flat"
    },
    {
      "x": -38,
      "y": 1,
      "z": -32,
      "name": "Wood_Blackwood_Planks",
      "rotation": 3
    },
    {
      "x": -38,
      "y": 2,
      "z": -32,
      "name": "Cloth_Roof_Red_Flat"
    },
    {
      "x": -38,
      "y": 1,
      "z": -31,
      "name": "Wood_Blackwood_Planks",
      "rotation": 3
    },
    {
      "x": -38,
      "y": 2,
      "z": -31,
      "name": "Cloth_Roof_Red_Flat"
    },
    {
      "x": -38,
      "y": 1,
      "z": -30,
      "name": "Wood_Blackwood_Planks",
      "rotation": 3
    },
    {
      "x": -38,
      "y": 2,
      "z": -30,
      "name": "Cloth_Roof_Red_Flat"
    },
    {
      "x": -38,
      "y": 1,
      "z": -29,
      "name": "Wood_Blackwood_Planks",
      "rotation": 3
    },
    {
      "x": -38,
      "y": 2,
      "z": -29,
      "name": "Cloth_Roof_Red_Flat"
    },
    {
      "x": -38,
      "y": 1,
      "z": -28,
      "name": "Wood_Blackwood_Planks",
      "rotation": 3
    },
    {
      "x": -38,
      "y": 2,
      "z": -28,
      "name": "Cloth_Roof_Red_Flat"
    },
    {
      "x": -38,
      "y": 1,
      "z": -27,
      "name": "Wood_Blackwood_Planks",
      "rotation": 3
    },
    {
      "x": -38,
      "y": 2,
      "z": -27,
      "name": "Cloth_Roof_Red_Flat"
    },
    {
      "x": -38,
      "y": 1,
      "z": -26,
      "name": "Wood_Blackwood_Planks",
      "rotation": 3
    },
    {
      "x": -38,
      "y": 2,
      "z": -26,
      "name": "Cloth_Roof_Red_Flat"
    },
    {
      "x": -38,
      "y": 1,
      "z": -25,
      "name": "Wood_Blackwood_Planks",
      "rotation": 3
    },
    {
      "x": -38,
      "y": 2,
      "z": -25,
      "name": "Cloth_Roof_Red_Flat"
    },
    {
      "x": -38,
      "y": 1,
      "z": -24,
      "name": "Wood_Blackwood_Planks",
      "rotation": 3
    },
    {
      "x": -38,
      "y": 2,
      "z": -24,
      "name": "Cloth_Roof_Red_Flat"
    },
    {
      "x": -38,
      "y": 1,
      "z": -23,
      "name": "Wood_Blackwood_Planks",
      "rotation": 3
    },
    {
      "x": -38,
      "y": 2,
      "z": -23,
      "name": "Cloth_Roof_Red_Flat"
    },
    {
      "x": -38,
      "y": 1,
      "z": -22,
      "name": "Wood_Blackwood_Planks",
      "rotation": 3
    },
    {
      "x": -38,
      "y": 2,
      "z": -22,
      "name": "Cloth_Roof_Red_Flat"
    },
    {
      "x": -38,
      "y": 1,
      "z": -21,
      "name": "Wood_Blackwood_Planks",
      "rotation": 3
    },
    {
      "x": -38,
      "y": 2,
      "z": -21,
      "name": "Cloth_Roof_Red_Flat"
    },
    {
      "x": -38,
      "y": 1,
      "z": -20,
      "name": "Wood_Blackwood_Planks",
      "rotation": 3
    },
    {
      "x": -38,
      "y": 2,
      "z": -20,
      "name": "Cloth_Roof_Red_Flat"
    },
    {
      "x": -38,
      "y": 1,
      "z": -19,
      "name": "Wood_Blackwood_Planks",
      "rotation": 3
    },
    {
      "x": -38,
      "y": 2,
      "z": -19,
      "name": "Cloth_Roof_Red_Flat"
    },
    {
      "x": -38,
      "y": 1,
      "z": -18,
      "name": "Wood_Blackwood_Planks",
      "rotation": 3
    },
    {
      "x": -38,
      "y": 2,
      "z": -18,
      "name": "Cloth_Roof_Red_Flat"
    },
    {
      "x": -38,
      "y": 1,
      "z": -17,
      "name": "Wood_Blackwood_Planks",
      "rotation": 3
    },
    {
      "x": -38,
      "y": 2,
      "z": -17,
      "name": "Cloth_Roof_Red_Flat"
    },
    {
      "x": -38,
      "y": 1,
      "z": -16,
      "name": "Wood_Blackwood_Planks",
      "rotation": 3
    },
    {
      "x": -38,
      "y": 2,
      "z": -16,
      "name": "Cloth_Roof_Red_Flat"
    },
    {
      "x": -38,
      "y": 1,
      "z": -15,
      "name": "Wood_Blackwood_Planks",
      "rotation": 3
    },
    {
      "x": -38,
      "y": 2,
      "z": -15,
      "name": "Cloth_Roof_Red_Flat"
    },
    {
      "x": -38,
      "y": 1,
      "z": -14,
      "name": "Wood_Blackwood_Planks",
      "rotation": 3
    },
    {
      "x": -38,
      "y": 2,
      "z": -14,
      "name": "Cloth_Roof_Red_Flat"
    },
    {
      "x": -38,
      "y": 1,
      "z": -13,
      "name": "Wood_Blackwood_Planks",
      "rotation": 3
    },
    {
      "x": -38,
      "y": 2,
      "z": -13,
      "name": "Cloth_Roof_Red_Flat"
    },
    {
      "x": -38,
      "y": 1,
      "z": -12,
      "name": "Wood_Blackwood_Planks",
      "rotation": 3
    },
    {
      "x": -38,
      "y": 2,
      "z": -12,
      "name": "Cloth_Roof_Red_Flat"
    },
    {
      "x": -38,
      "y": 1,
      "z": -11,
      "name": "Wood_Blackwood_Planks",
      "rotation": 3
    },
    {
      "x": -38,
      "y": 2,
      "z": -11,
      "name": "Cloth_Roof_Red_Flat"
    },
    {
      "x": -38,
      "y": 1,
      "z": -10,
      "name": "Wood_Blackwood_Planks",
      "rotation": 3
    },
    {
      "x": -38,
      "y": 2,
      "z": -10,
      "name": "Cloth_Roof_Red_Flat"
    },
    {
      "x": -38,
      "y": 1,
      "z": -9,
      "name": "Wood_Blackwood_Planks",
      "rotation": 3
    },
    {
      "x": -38,
      "y": 2,
      "z": -9,
      "name": "Cloth_Roof_Red_Flat"
    },
    {
      "x": -38,
      "y": 1,
      "z": -8,
      "name": "Wood_Blackwood_Planks",
      "rotation": 3
    },
    {
      "x": -38,
      "y": 2,
      "z": -8,
      "name": "Cloth_Roof_Red_Flat"
    },
    {
      "x": -38,
      "y": 1,
      "z": -7,
      "name": "Wood_Blackwood_Planks",
      "rotation": 3
    },
    {
      "x": -38,
      "y": 2,
      "z": -7,
      "name": "Cloth_Roof_Red_Flat"
    },
    {
      "x": -38,
      "y": 1,
      "z": -6,
      "name": "Soil_Dirt_Burnt"
    },
    {
      "x": -38,
      "y": 2,
      "z": -6,
      "name": "Plant_Moss_Rug_Green_Dark",
      "support": 15
    },
    {
      "x": -38,
      "y": 4,
      "z": -6,
      "name": "Plant_Leaves_Oak",
      "support": 15
    },
    {
      "x": -38,
      "y": 1,
      "z": -5,
      "name": "Soil_Dirt_Burnt"
    },
    {
      "x": -38,
      "y": 2,
      "z": -5,
      "name": "Plant_Moss_Rug_Green_Dark",
      "support": 15
    },
    {
      "x": -38,
      "y": 4,
      "z": -5,
      "name": "Plant_Leaves_Oak",
      "support": 15
    },
    {
      "x": -38,
      "y": 5,
      "z": -5,
      "name": "Plant_Leaves_Oak",
      "support": 15
    },
    {
      "x": -38,
      "y": 1,
      "z": -4,
      "name": "Soil_Dirt_Burnt"
    },
    {
      "x": -38,
      "y": 1,
      "z": -3,
      "name": "Wood_Blackwood_Planks",
      "rotation": 3
    },
    {
      "x": -38,
      "y": 2,
      "z": -3,
      "name": "Cloth_Roof_Red_Flat"
    },
    {
      "x": -38,
      "y": 1,
      "z": -2,
      "name": "Wood_Blackwood_Planks",
      "rotation": 3
    },
    {
      "x": -38,
      "y": 2,
      "z": -2,
      "name": "Cloth_Roof_Red_Flat"
    },
    {
      "x": -38,
      "y": 1,
      "z": -1,
      "name": "Wood_Blackwood_Planks",
      "rotation": 3
    },
    {
      "x": -38,
      "y": 2,
      "z": -1,
      "name": "Cloth_Roof_Red_Flat"
    },
    {
      "x": -38,
      "y": 1,
      "z": 0,
      "name": "Wood_Blackwood_Planks",
      "rotation": 3
    },
    {
      "x": -38,
      "y": 2,
      "z": 0,
      "name": "Cloth_Roof_Red_Flat"
    },
    {
      "x": -38,
      "y": 1,
      "z": 1,
      "name": "Wood_Blackwood_Planks",
      "rotation": 3
    },
    {
      "x": -38,
      "y": 2,
      "z": 1,
      "name": "Cloth_Roof_Red_Flat"
    },
    {
      "x": -38,
      "y": 1,
      "z": 2,
      "name": "Wood_Blackwood_Planks",
      "rotation": 3
    },
    {
      "x": -38,
      "y": 2,
      "z": 2,
      "name": "Cloth_Roof_Red_Flat"
    },
    {
      "x": -38,
      "y": 1,
      "z": 3,
      "name": "Wood_Blackwood_Planks",
      "rotation": 3
    },
    {
      "x": -38,
      "y": 2,
      "z": 3,
      "name": "Cloth_Roof_Red_Flat"
    },
    {
      "x": -38,
      "y": 1,
      "z": 4,
      "name": "Wood_Blackwood_Planks",
      "rotation": 3
    },
    {
      "x": -38,
      "y": 2,
      "z": 4,
      "name": "Cloth_Roof_Red_Flat"
    },
    {
      "x": -38,
      "y": 1,
      "z": 5,
      "name": "Wood_Blackwood_Planks",
      "rotation": 3
    },
    {
      "x": -38,
      "y": 2,
      "z": 5,
      "name": "Cloth_Roof_Red_Flat"
    },
    {
      "x": -38,
      "y": 1,
      "z": 6,
      "name": "Wood_Blackwood_Planks",
      "rotation": 3
    },
    {
      "x": -38,
      "y": 2,
      "z": 6,
      "name": "Cloth_Roof_Red_Flat"
    },
    {
      "x": -38,
      "y": 1,
      "z": 7,
      "name": "Wood_Blackwood_Planks",
      "rotation": 3
    },
    {
      "x": -38,
      "y": 2,
      "z": 7,
      "name": "Cloth_Roof_Red_Flat"
    },
    {
      "x": -38,
      "y": 1,
      "z": 8,
      "name": "Wood_Blackwood_Planks",
      "rotation": 3
    },
    {
      "x": -38,
      "y": 2,
      "z": 8,
      "name": "Cloth_Roof_Red_Flat"
    },
    {
      "x": -38,
      "y": 1,
      "z": 9,
      "name": "Wood_Blackwood_Planks",
      "rotation": 3
    },
    {
      "x": -38,
      "y": 2,
      "z": 9,
      "name": "Cloth_Roof_Red_Flat"
    },
    {
      "x": -38,
      "y": 1,
      "z": 10,
      "name": "Wood_Blackwood_Planks",
      "rotation": 3
    },
    {
      "x": -38,
      "y": 2,
      "z": 10,
      "name": "Cloth_Roof_Red_Flat"
    },
    {
      "x": -38,
      "y": 1,
      "z": 11,
      "name": "Wood_Blackwood_Planks",
      "rotation": 3
    },
    {
      "x": -38,
      "y": 2,
      "z": 11,
      "name": "Cloth_Roof_Red_Flat"
    },
    {
      "x": -38,
      "y": 1,
      "z": 12,
      "name": "Wood_Blackwood_Planks",
      "rotation": 3
    },
    {
      "x": -38,
      "y": 2,
      "z": 12,
      "name": "Cloth_Roof_Red_Flat"
    },
    {
      "x": -38,
      "y": 1,
      "z": 13,
      "name": "Wood_Blackwood_Planks",
      "rotation": 3
    },
    {
      "x": -38,
      "y": 2,
      "z": 13,
      "name": "Cloth_Roof_Red_Flat"
    },
    {
      "x": -38,
      "y": 1,
      "z": 14,
      "name": "Wood_Blackwood_Planks",
      "rotation": 3
    },
    {
      "x": -38,
      "y": 2,
      "z": 14,
      "name": "Cloth_Roof_Red_Flat"
    },
    {
      "x": -38,
      "y": 1,
      "z": 15,
      "name": "Wood_Blackwood_Planks",
      "rotation": 3
    },
    {
      "x": -38,
      "y": 2,
      "z": 15,
      "name": "Cloth_Roof_Red_Flat"
    },
    {
      "x": -38,
      "y": 1,
      "z": 16,
      "name": "Wood_Blackwood_Planks",
      "rotation": 3
    },
    {
      "x": -38,
      "y": 2,
      "z": 16,
      "name": "Cloth_Roof_Red_Flat"
    },
    {
      "x": -38,
      "y": 1,
      "z": 17,
      "name": "Wood_Blackwood_Planks",
      "rotation": 3
    },
    {
      "x": -38,
      "y": 2,
      "z": 17,
      "name": "Cloth_Roof_Red_Flat"
    },
    {
      "x": -38,
      "y": 1,
      "z": 18,
      "name": "Wood_Blackwood_Planks",
      "rotation": 3
    },
    {
      "x": -38,
      "y": 2,
      "z": 18,
      "name": "Cloth_Roof_Red_Flat"
    },
    {
      "x": -38,
      "y": 22,
      "z": 18,
      "name": "Rock_Basalt_Brick_Smooth_Half",
      "rotation": 11
    },
    {
      "x": -38,
      "y": 1,
      "z": 19,
      "name": "Wood_Blackwood_Planks",
      "rotation": 3
    },
    {
      "x": -38,
      "y": 2,
      "z": 19,
      "name": "Cloth_Roof_Red_Flat"
    },
    {
      "x": -38,
      "y": 22,
      "z": 19,
      "name": "Rock_Basalt_Brick_Smooth",
      "rotation": 3
    },
    {
      "x": -38,
      "y": 1,
      "z": 20,
      "name": "Wood_Blackwood_Planks",
      "rotation": 3
    },
    {
      "x": -38,
      "y": 2,
      "z": 20,
      "name": "Cloth_Roof_Red_Flat"
    },
    {
      "x": -38,
      "y": 20,
      "z": 20,
      "name": "Rock_Basalt_Brick_Smooth",
      "rotation": 3
    },
    {
      "x": -38,
      "y": 21,
      "z": 20,
      "name": "Rock_Basalt_Brick_Smooth",
      "rotation": 3
    },
    {
      "x": -38,
      "y": 22,
      "z": 20,
      "name": "Rock_Basalt_Brick_Smooth",
      "rotation": 3
    },
    {
      "x": -38,
      "y": 1,
      "z": 21,
      "name": "Wood_Blackwood_Planks",
      "rotation": 3
    },
    {
      "x": -38,
      "y": 2,
      "z": 21,
      "name": "Cloth_Roof_Red_Flat"
    },
    {
      "x": -38,
      "y": 19,
      "z": 21,
      "name": "Rock_Basalt_Brick_Smooth",
      "rotation": 3
    },
    {
      "x": -38,
      "y": 20,
      "z": 21,
      "name": "Rock_Stone_Brick_Smooth",
      "rotation": 3
    },
    {
      "x": -38,
      "y": 21,
      "z": 21,
      "name": "Rock_Stone_Brick_Smooth",
      "rotation": 3
    },
    {
      "x": -38,
      "y": 22,
      "z": 21,
      "name": "Rock_Stone_Brick_Half",
      "rotation": 7
    },
    {
      "x": -38,
      "y": 23,
      "z": 21,
      "name": "Rock_Basalt_Brick",
      "rotation": 3
    },
    {
      "x": -38,
      "y": 24,
      "z": 21,
      "name": "Rock_Basalt_Brick",
      "rotation": 3
    },
    {
      "x": -38,
      "y": 25,
      "z": 21,
      "name": "Rock_Basalt_Brick",
      "rotation": 3
    },
    {
      "x": -38,
      "y": 1,
      "z": 22,
      "name": "Wood_Blackwood_Planks",
      "rotation": 3
    },
    {
      "x": -38,
      "y": 2,
      "z": 22,
      "name": "Cloth_Roof_Red_Flat"
    },
    {
      "x": -38,
      "y": 19,
      "z": 22,
      "name": "Rock_Stone_Brick_Smooth",
      "rotation": 3
    },
    {
      "x": -38,
      "y": 20,
      "z": 22,
      "name": "Wood_Hardwood_Planks",
      "rotation": 3
    },
    {
      "x": -38,
      "y": 21,
      "z": 22,
      "name": "Rock_Basalt_Brick_Half",
      "rotation": 4
    },
    {
      "x": -38,
      "y": 22,
      "z": 22,
      "name": "Rock_Basalt_Brick_Half",
      "rotation": 4
    },
    {
      "x": -38,
      "y": 23,
      "z": 22,
      "name": "Rock_Basalt_Brick_Half",
      "rotation": 4
    },
    {
      "x": -38,
      "y": 24,
      "z": 22,
      "name": "Rock_Basalt_Brick_Half",
      "rotation": 4
    },
    {
      "x": -38,
      "y": 25,
      "z": 22,
      "name": "Rock_Basalt_Brick_Half",
      "rotation": 4
    },
    {
      "x": -38,
      "y": 1,
      "z": 23,
      "name": "Wood_Blackwood_Planks",
      "rotation": 3
    },
    {
      "x": -38,
      "y": 2,
      "z": 23,
      "name": "Cloth_Roof_White_Flat"
    },
    {
      "x": -38,
      "y": 19,
      "z": 23,
      "name": "Rock_Stone",
      "rotation": 3
    },
    {
      "x": -38,
      "y": 20,
      "z": 23,
      "name": "Wood_Hardwood_Stairs"
    },
    {
      "x": -38,
      "y": 1,
      "z": 24,
      "name": "Rock_Stone_Brick_Smooth"
    },
    {
      "x": -38,
      "y": 19,
      "z": 24,
      "name": "Rock_Stone",
      "rotation": 3
    },
    {
      "x": -38,
      "y": 20,
      "z": 24,
      "name": "Wood_Hardwood_Planks",
      "rotation": 3
    },
    {
      "x": -38,
      "y": 1,
      "z": 25,
      "name": "Rock_Stone_Brick_Half"
    },
    {
      "x": -38,
      "y": 19,
      "z": 25,
      "name": "Rock_Stone",
      "rotation": 3
    },
    {
      "x": -38,
      "y": 20,
      "z": 25,
      "name": "Wood_Hardwood_Planks",
      "rotation": 3
    },
    {
      "x": -38,
      "y": 1,
      "z": 26,
      "name": "Rock_Stone_Brick_Half"
    },
    {
      "x": -38,
      "y": 11,
      "z": 26,
      "name": "Wood_Ash_Trunk",
      "support": 15,
      "rotation": 3
    },
    {
      "x": -38,
      "y": 12,
      "z": 26,
      "name": "Wood_Ash_Trunk_Full",
      "rotation": 1
    },
    {
      "x": -38,
      "y": 13,
      "z": 26,
      "name": "Wood_Ash_Trunk_Full",
      "rotation": 1
    },
    {
      "x": -38,
      "y": 14,
      "z": 26,
      "name": "Wood_Ash_Trunk_Full",
      "rotation": 1
    },
    {
      "x": -38,
      "y": 15,
      "z": 26,
      "name": "Wood_Ash_Trunk_Full",
      "rotation": 1
    },
    {
      "x": -38,
      "y": 16,
      "z": 26,
      "name": "Wood_Ash_Trunk_Full",
      "rotation": 1
    },
    {
      "x": -38,
      "y": 17,
      "z": 26,
      "name": "Wood_Ash_Trunk_Full",
      "rotation": 1
    },
    {
      "x": -38,
      "y": 18,
      "z": 26,
      "name": "Wood_Ash_Trunk_Full",
      "rotation": 1
    },
    {
      "x": -38,
      "y": 19,
      "z": 26,
      "name": "Rock_Stone",
      "rotation": 3
    },
    {
      "x": -38,
      "y": 20,
      "z": 26,
      "name": "Wood_Hardwood_Planks",
      "rotation": 3
    },
    {
      "x": -38,
      "y": 0,
      "z": 27,
      "name": "Rock_Stone_Brick_Half",
      "rotation": 8
    },
    {
      "x": -38,
      "y": 19,
      "z": 27,
      "name": "Rock_Stone",
      "rotation": 3
    },
    {
      "x": -38,
      "y": 20,
      "z": 27,
      "name": "Wood_Hardwood_Planks",
      "rotation": 3
    },
    {
      "x": -38,
      "y": 0,
      "z": 28,
      "name": "Rock_Stone_Brick_Half",
      "rotation": 8
    },
    {
      "x": -38,
      "y": 19,
      "z": 28,
      "name": "Rock_Stone_Brick_Smooth",
      "rotation": 3
    },
    {
      "x": -38,
      "y": 20,
      "z": 28,
      "name": "Wood_Hardwood_Planks",
      "rotation": 3
    },
    {
      "x": -38,
      "y": 0,
      "z": 29,
      "name": "Rock_Stone_Brick_Half"
    },
    {
      "x": -38,
      "y": 19,
      "z": 29,
      "name": "Soil_Clay_Grey",
      "rotation": 3
    },
    {
      "x": -38,
      "y": 20,
      "z": 29,
      "name": "Wood_Hardwood_Planks",
      "rotation": 3
    },
    {
      "x": -38,
      "y": 0,
      "z": 30,
      "name": "Rock_Stone_Brick_Half"
    },
    {
      "x": -38,
      "y": 19,
      "z": 30,
      "name": "Soil_Clay_Grey",
      "rotation": 3
    },
    {
      "x": -38,
      "y": 20,
      "z": 30,
      "name": "Wood_Hardwood_Planks",
      "rotation": 3
    },
    {
      "x": -38,
      "y": 19,
      "z": 31,
      "name": "Soil_Clay_Grey",
      "rotation": 3
    },
    {
      "x": -38,
      "y": 20,
      "z": 31,
      "name": "Wood_Hardwood_Stairs"
    },
    {
      "x": -38,
      "y": 19,
      "z": 32,
      "name": "Rock_Stone",
      "rotation": 3
    },
    {
      "x": -38,
      "y": 20,
      "z": 32,
      "name": "Wood_Hardwood_Planks",
      "rotation": 3
    },
    {
      "x": -38,
      "y": 21,
      "z": 32,
      "name": "Rock_Basalt_Brick_Half",
      "rotation": 6
    },
    {
      "x": -38,
      "y": 22,
      "z": 32,
      "name": "Rock_Basalt_Brick_Half",
      "rotation": 6
    },
    {
      "x": -38,
      "y": 23,
      "z": 32,
      "name": "Rock_Basalt_Brick_Half",
      "rotation": 6
    },
    {
      "x": -38,
      "y": 24,
      "z": 32,
      "name": "Rock_Basalt_Brick_Half",
      "rotation": 6
    },
    {
      "x": -38,
      "y": 25,
      "z": 32,
      "name": "Rock_Basalt_Brick_Half",
      "rotation": 6
    },
    {
      "x": -38,
      "y": 19,
      "z": 33,
      "name": "Rock_Stone_Brick_Smooth",
      "rotation": 3
    },
    {
      "x": -38,
      "y": 20,
      "z": 33,
      "name": "Rock_Stone_Brick_Smooth",
      "rotation": 3
    },
    {
      "x": -38,
      "y": 21,
      "z": 33,
      "name": "Rock_Stone_Brick_Smooth",
      "rotation": 3
    },
    {
      "x": -38,
      "y": 22,
      "z": 33,
      "name": "Rock_Stone_Brick_Half",
      "rotation": 5
    },
    {
      "x": -38,
      "y": 23,
      "z": 33,
      "name": "Rock_Stone_Brick_Half",
      "rotation": 5
    },
    {
      "x": -38,
      "y": 24,
      "z": 33,
      "name": "Rock_Stone_Brick_Half",
      "rotation": 5
    },
    {
      "x": -38,
      "y": 25,
      "z": 33,
      "name": "Rock_Stone_Brick",
      "rotation": 3
    },
    {
      "x": -38,
      "y": 20,
      "z": 34,
      "name": "Rock_Stone_Brick_Smooth_Half",
      "rotation": 11
    },
    {
      "x": -38,
      "y": 21,
      "z": 34,
      "name": "Rock_Stone_Brick_Smooth_Half",
      "rotation": 11
    },
    {
      "x": -37,
      "y": 1,
      "z": -40,
      "name": "Wood_Blackwood_Planks",
      "rotation": 3
    },
    {
      "x": -37,
      "y": 2,
      "z": -40,
      "name": "Cloth_Roof_White_Flat"
    },
    {
      "x": -37,
      "y": 1,
      "z": -39,
      "name": "Wood_Deadwood_Planks",
      "rotation": 3
    },
    {
      "x": -37,
      "y": 2,
      "z": -39,
      "name": "Cloth_Roof_Red_Flat"
    },
    {
      "x": -37,
      "y": 1,
      "z": -38,
      "name": "Wood_Deadwood_Planks",
      "rotation": 3
    },
    {
      "x": -37,
      "y": 2,
      "z": -38,
      "name": "Cloth_Roof_Red_Flat"
    },
    {
      "x": -37,
      "y": 1,
      "z": -37,
      "name": "Wood_Deadwood_Planks",
      "rotation": 3
    },
    {
      "x": -37,
      "y": 2,
      "z": -37,
      "name": "Cloth_Roof_Red_Flat"
    },
    {
      "x": -37,
      "y": 1,
      "z": -36,
      "name": "Wood_Blackwood_Planks",
      "rotation": 3
    },
    {
      "x": -37,
      "y": 2,
      "z": -36,
      "name": "Cloth_Roof_Red_Flat"
    },
    {
      "x": -37,
      "y": 1,
      "z": -35,
      "name": "Wood_Deadwood_Planks",
      "rotation": 3
    },
    {
      "x": -37,
      "y": 2,
      "z": -35,
      "name": "Cloth_Roof_Red_Flat"
    },
    {
      "x": -37,
      "y": 1,
      "z": -34,
      "name": "Wood_Deadwood_Planks",
      "rotation": 3
    },
    {
      "x": -37,
      "y": 2,
      "z": -34,
      "name": "Cloth_Roof_Red_Flat"
    },
    {
      "x": -37,
      "y": 1,
      "z": -33,
      "name": "Wood_Deadwood_Planks",
      "rotation": 3
    },
    {
      "x": -37,
      "y": 2,
      "z": -33,
      "name": "Cloth_Roof_Red_Flat"
    },
    {
      "x": -37,
      "y": 1,
      "z": -32,
      "name": "Wood_Blackwood_Planks",
      "rotation": 3
    },
    {
      "x": -37,
      "y": 2,
      "z": -32,
      "name": "Cloth_Roof_Red_Flat"
    },
    {
      "x": -37,
      "y": 1,
      "z": -31,
      "name": "Wood_Deadwood_Planks",
      "rotation": 3
    },
    {
      "x": -37,
      "y": 2,
      "z": -31,
      "name": "Cloth_Roof_Red_Flat"
    },
    {
      "x": -37,
      "y": 1,
      "z": -30,
      "name": "Wood_Deadwood_Planks",
      "rotation": 3
    },
    {
      "x": -37,
      "y": 2,
      "z": -30,
      "name": "Cloth_Roof_Red_Flat"
    },
    {
      "x": -37,
      "y": 1,
      "z": -29,
      "name": "Wood_Deadwood_Planks",
      "rotation": 3
    },
    {
      "x": -37,
      "y": 2,
      "z": -29,
      "name": "Cloth_Roof_Red_Flat"
    },
    {
      "x": -37,
      "y": 1,
      "z": -28,
      "name": "Wood_Blackwood_Planks",
      "rotation": 3
    },
    {
      "x": -37,
      "y": 2,
      "z": -28,
      "name": "Cloth_Roof_Red_Flat"
    },
    {
      "x": -37,
      "y": 1,
      "z": -27,
      "name": "Wood_Deadwood_Planks",
      "rotation": 3
    },
    {
      "x": -37,
      "y": 2,
      "z": -27,
      "name": "Cloth_Roof_Red_Flat"
    },
    {
      "x": -37,
      "y": 1,
      "z": -26,
      "name": "Wood_Deadwood_Planks",
      "rotation": 3
    },
    {
      "x": -37,
      "y": 2,
      "z": -26,
      "name": "Cloth_Roof_Red_Flat"
    },
    {
      "x": -37,
      "y": 1,
      "z": -25,
      "name": "Wood_Deadwood_Planks",
      "rotation": 3
    },
    {
      "x": -37,
      "y": 2,
      "z": -25,
      "name": "Cloth_Roof_Red_Flat"
    },
    {
      "x": -37,
      "y": 1,
      "z": -24,
      "name": "Wood_Blackwood_Planks",
      "rotation": 3
    },
    {
      "x": -37,
      "y": 2,
      "z": -24,
      "name": "Cloth_Roof_Red_Flat"
    },
    {
      "x": -37,
      "y": 1,
      "z": -23,
      "name": "Wood_Deadwood_Planks",
      "rotation": 3
    },
    {
      "x": -37,
      "y": 2,
      "z": -23,
      "name": "Cloth_Roof_Red_Flat"
    },
    {
      "x": -37,
      "y": 1,
      "z": -22,
      "name": "Wood_Deadwood_Planks",
      "rotation": 3
    },
    {
      "x": -37,
      "y": 2,
      "z": -22,
      "name": "Cloth_Roof_Red_Flat"
    },
    {
      "x": -37,
      "y": 1,
      "z": -21,
      "name": "Wood_Deadwood_Planks",
      "rotation": 3
    },
    {
      "x": -37,
      "y": 2,
      "z": -21,
      "name": "Cloth_Roof_Red_Flat"
    },
    {
      "x": -37,
      "y": 1,
      "z": -20,
      "name": "Wood_Blackwood_Planks",
      "rotation": 3
    },
    {
      "x": -37,
      "y": 2,
      "z": -20,
      "name": "Cloth_Roof_Red_Flat"
    },
    {
      "x": -37,
      "y": 1,
      "z": -19,
      "name": "Wood_Deadwood_Planks",
      "rotation": 3
    },
    {
      "x": -37,
      "y": 2,
      "z": -19,
      "name": "Cloth_Roof_Red_Flat"
    },
    {
      "x": -37,
      "y": 1,
      "z": -18,
      "name": "Wood_Deadwood_Planks",
      "rotation": 3
    },
    {
      "x": -37,
      "y": 2,
      "z": -18,
      "name": "Cloth_Roof_Red_Flat"
    },
    {
      "x": -37,
      "y": 1,
      "z": -17,
      "name": "Wood_Deadwood_Planks",
      "rotation": 3
    },
    {
      "x": -37,
      "y": 2,
      "z": -17,
      "name": "Cloth_Roof_Red_Flat"
    },
    {
      "x": -37,
      "y": 1,
      "z": -16,
      "name": "Wood_Blackwood_Planks",
      "rotation": 3
    },
    {
      "x": -37,
      "y": 2,
      "z": -16,
      "name": "Cloth_Roof_Red_Flat"
    },
    {
      "x": -37,
      "y": 1,
      "z": -15,
      "name": "Wood_Deadwood_Planks",
      "rotation": 3
    },
    {
      "x": -37,
      "y": 2,
      "z": -15,
      "name": "Cloth_Roof_Red_Flat"
    },
    {
      "x": -37,
      "y": 1,
      "z": -14,
      "name": "Wood_Deadwood_Planks",
      "rotation": 3
    },
    {
      "x": -37,
      "y": 2,
      "z": -14,
      "name": "Cloth_Roof_Red_Flat"
    },
    {
      "x": -37,
      "y": 1,
      "z": -13,
      "name": "Wood_Deadwood_Planks",
      "rotation": 3
    },
    {
      "x": -37,
      "y": 2,
      "z": -13,
      "name": "Cloth_Roof_Red_Flat"
    },
    {
      "x": -37,
      "y": 1,
      "z": -12,
      "name": "Wood_Blackwood_Planks",
      "rotation": 3
    },
    {
      "x": -37,
      "y": 2,
      "z": -12,
      "name": "Cloth_Roof_Red_Flat"
    },
    {
      "x": -37,
      "y": 1,
      "z": -11,
      "name": "Wood_Deadwood_Planks",
      "rotation": 3
    },
    {
      "x": -37,
      "y": 2,
      "z": -11,
      "name": "Cloth_Roof_Red_Flat"
    },
    {
      "x": -37,
      "y": 1,
      "z": -10,
      "name": "Wood_Deadwood_Planks",
      "rotation": 3
    },
    {
      "x": -37,
      "y": 2,
      "z": -10,
      "name": "Cloth_Roof_Red_Flat"
    },
    {
      "x": -37,
      "y": 1,
      "z": -9,
      "name": "Wood_Deadwood_Planks",
      "rotation": 3
    },
    {
      "x": -37,
      "y": 2,
      "z": -9,
      "name": "Cloth_Roof_Red_Flat"
    },
    {
      "x": -37,
      "y": 1,
      "z": -8,
      "name": "Wood_Blackwood_Planks",
      "rotation": 3
    },
    {
      "x": -37,
      "y": 2,
      "z": -8,
      "name": "Cloth_Roof_Red_Flat"
    },
    {
      "x": -37,
      "y": 1,
      "z": -7,
      "name": "Soil_Dirt_Burnt"
    },
    {
      "x": -37,
      "y": 2,
      "z": -7,
      "name": "Plant_Moss_Rug_Green_Dark",
      "support": 15
    },
    {
      "x": -37,
      "y": 1,
      "z": -6,
      "name": "Wood_Deadwood_Planks",
      "rotation": 3
    },
    {
      "x": -37,
      "y": 2,
      "z": -6,
      "name": "Cloth_Roof_Red_Flat"
    },
    {
      "x": -37,
      "y": 1,
      "z": -5,
      "name": "Wood_Deadwood_Planks",
      "rotation": 3
    },
    {
      "x": -37,
      "y": 2,
      "z": -5,
      "name": "Cloth_Roof_Red_Flat"
    },
    {
      "x": -37,
      "y": 1,
      "z": -4,
      "name": "Soil_Dirt_Burnt"
    },
    {
      "x": -37,
      "y": 2,
      "z": -4,
      "name": "Plant_Moss_Green_Dark",
      "support": 15
    },
    {
      "x": -37,
      "y": 1,
      "z": -3,
      "name": "Wood_Deadwood_Planks",
      "rotation": 3
    },
    {
      "x": -37,
      "y": 2,
      "z": -3,
      "name": "Cloth_Roof_Red_Flat"
    },
    {
      "x": -37,
      "y": 1,
      "z": -2,
      "name": "Wood_Deadwood_Planks",
      "rotation": 3
    },
    {
      "x": -37,
      "y": 2,
      "z": -2,
      "name": "Cloth_Roof_Red_Flat"
    },
    {
      "x": -37,
      "y": 1,
      "z": -1,
      "name": "Wood_Deadwood_Planks",
      "rotation": 3
    },
    {
      "x": -37,
      "y": 2,
      "z": -1,
      "name": "Cloth_Roof_Red_Flat"
    },
    {
      "x": -37,
      "y": 1,
      "z": 0,
      "name": "Wood_Blackwood_Planks",
      "rotation": 3
    },
    {
      "x": -37,
      "y": 2,
      "z": 0,
      "name": "Cloth_Roof_Red_Flat"
    },
    {
      "x": -37,
      "y": 1,
      "z": 1,
      "name": "Wood_Deadwood_Planks",
      "rotation": 3
    },
    {
      "x": -37,
      "y": 2,
      "z": 1,
      "name": "Cloth_Roof_Red_Flat"
    },
    {
      "x": -37,
      "y": 1,
      "z": 2,
      "name": "Wood_Deadwood_Planks",
      "rotation": 3
    },
    {
      "x": -37,
      "y": 2,
      "z": 2,
      "name": "Cloth_Roof_Red_Flat"
    },
    {
      "x": -37,
      "y": 1,
      "z": 3,
      "name": "Wood_Deadwood_Planks",
      "rotation": 3
    },
    {
      "x": -37,
      "y": 2,
      "z": 3,
      "name": "Cloth_Roof_Red_Flat"
    },
    {
      "x": -37,
      "y": 1,
      "z": 4,
      "name": "Wood_Blackwood_Planks",
      "rotation": 3
    },
    {
      "x": -37,
      "y": 2,
      "z": 4,
      "name": "Cloth_Roof_Red_Flat"
    },
    {
      "x": -37,
      "y": 1,
      "z": 5,
      "name": "Wood_Deadwood_Planks",
      "rotation": 3
    },
    {
      "x": -37,
      "y": 2,
      "z": 5,
      "name": "Cloth_Roof_Red_Flat"
    },
    {
      "x": -37,
      "y": 1,
      "z": 6,
      "name": "Wood_Deadwood_Planks",
      "rotation": 3
    },
    {
      "x": -37,
      "y": 2,
      "z": 6,
      "name": "Cloth_Roof_Red_Flat"
    },
    {
      "x": -37,
      "y": 1,
      "z": 7,
      "name": "Wood_Deadwood_Planks",
      "rotation": 3
    },
    {
      "x": -37,
      "y": 2,
      "z": 7,
      "name": "Cloth_Roof_Red_Flat"
    },
    {
      "x": -37,
      "y": 1,
      "z": 8,
      "name": "Wood_Blackwood_Planks",
      "rotation": 3
    },
    {
      "x": -37,
      "y": 2,
      "z": 8,
      "name": "Cloth_Roof_Red_Flat"
    },
    {
      "x": -37,
      "y": 1,
      "z": 9,
      "name": "Wood_Deadwood_Planks",
      "rotation": 3
    },
    {
      "x": -37,
      "y": 2,
      "z": 9,
      "name": "Cloth_Roof_Red_Flat"
    },
    {
      "x": -37,
      "y": 1,
      "z": 10,
      "name": "Wood_Deadwood_Planks",
      "rotation": 3
    },
    {
      "x": -37,
      "y": 2,
      "z": 10,
      "name": "Cloth_Roof_Red_Flat"
    },
    {
      "x": -37,
      "y": 1,
      "z": 11,
      "name": "Wood_Deadwood_Planks",
      "rotation": 3
    },
    {
      "x": -37,
      "y": 2,
      "z": 11,
      "name": "Cloth_Roof_Red_Flat"
    },
    {
      "x": -37,
      "y": 1,
      "z": 12,
      "name": "Wood_Blackwood_Planks",
      "rotation": 3
    },
    {
      "x": -37,
      "y": 2,
      "z": 12,
      "name": "Cloth_Roof_Red_Flat"
    },
    {
      "x": -37,
      "y": 1,
      "z": 13,
      "name": "Wood_Deadwood_Planks",
      "rotation": 3
    },
    {
      "x": -37,
      "y": 2,
      "z": 13,
      "name": "Cloth_Roof_Red_Flat"
    },
    {
      "x": -37,
      "y": 1,
      "z": 14,
      "name": "Wood_Deadwood_Planks",
      "rotation": 3
    },
    {
      "x": -37,
      "y": 2,
      "z": 14,
      "name": "Cloth_Roof_Red_Flat"
    },
    {
      "x": -37,
      "y": 1,
      "z": 15,
      "name": "Wood_Deadwood_Planks",
      "rotation": 3
    },
    {
      "x": -37,
      "y": 2,
      "z": 15,
      "name": "Cloth_Roof_Red_Flat"
    },
    {
      "x": -37,
      "y": 1,
      "z": 16,
      "name": "Wood_Blackwood_Planks",
      "rotation": 3
    },
    {
      "x": -37,
      "y": 2,
      "z": 16,
      "name": "Cloth_Roof_Red_Flat"
    },
    {
      "x": -37,
      "y": 1,
      "z": 17,
      "name": "Wood_Deadwood_Planks",
      "rotation": 3
    },
    {
      "x": -37,
      "y": 2,
      "z": 17,
      "name": "Cloth_Roof_Red_Flat"
    },
    {
      "x": -37,
      "y": 1,
      "z": 18,
      "name": "Wood_Deadwood_Planks",
      "rotation": 3
    },
    {
      "x": -37,
      "y": 2,
      "z": 18,
      "name": "Cloth_Roof_Red_Flat"
    },
    {
      "x": -37,
      "y": 22,
      "z": 18,
      "name": "Rock_Basalt_Brick_Smooth_Half",
      "rotation": 11
    },
    {
      "x": -37,
      "y": 1,
      "z": 19,
      "name": "Wood_Deadwood_Planks",
      "rotation": 3
    },
    {
      "x": -37,
      "y": 2,
      "z": 19,
      "name": "Cloth_Roof_Red_Flat"
    },
    {
      "x": -37,
      "y": 22,
      "z": 19,
      "name": "Rock_Basalt_Brick_Smooth",
      "rotation": 3
    },
    {
      "x": -37,
      "y": 1,
      "z": 20,
      "name": "Wood_Blackwood_Planks",
      "rotation": 3
    },
    {
      "x": -37,
      "y": 2,
      "z": 20,
      "name": "Cloth_Roof_Red_Flat"
    },
    {
      "x": -37,
      "y": 20,
      "z": 20,
      "name": "Rock_Basalt_Brick_Smooth_Half",
      "rotation": 6
    },
    {
      "x": -37,
      "y": 21,
      "z": 20,
      "name": "Rock_Basalt_Brick_Smooth",
      "rotation": 3
    },
    {
      "x": -37,
      "y": 22,
      "z": 20,
      "name": "Rock_Basalt_Brick_Smooth",
      "rotation": 3
    },
    {
      "x": -37,
      "y": 1,
      "z": 21,
      "name": "Wood_Deadwood_Planks",
      "rotation": 3
    },
    {
      "x": -37,
      "y": 2,
      "z": 21,
      "name": "Cloth_Roof_Red_Flat"
    },
    {
      "x": -37,
      "y": 19,
      "z": 21,
      "name": "Rock_Basalt_Brick_Smooth",
      "rotation": 3
    },
    {
      "x": -37,
      "y": 20,
      "z": 21,
      "name": "Rock_Stone_Brick_Smooth",
      "rotation": 3
    },
    {
      "x": -37,
      "y": 21,
      "z": 21,
      "name": "Rock_Stone_Brick_Smooth",
      "rotation": 3
    },
    {
      "x": -37,
      "y": 23,
      "z": 21,
      "name": "Rock_Basalt_Brick",
      "rotation": 3
    },
    {
      "x": -37,
      "y": 24,
      "z": 21,
      "name": "Rock_Basalt_Brick",
      "rotation": 3
    },
    {
      "x": -37,
      "y": 25,
      "z": 21,
      "name": "Rock_Basalt_Brick",
      "rotation": 3
    },
    {
      "x": -37,
      "y": 1,
      "z": 22,
      "name": "Wood_Deadwood_Planks",
      "rotation": 3
    },
    {
      "x": -37,
      "y": 2,
      "z": 22,
      "name": "Cloth_Roof_Red_Flat"
    },
    {
      "x": -37,
      "y": 19,
      "z": 22,
      "name": "Rock_Stone_Brick_Smooth",
      "rotation": 3
    },
    {
      "x": -37,
      "y": 20,
      "z": 22,
      "name": "Wood_Hardwood_Planks",
      "rotation": 3
    },
    {
      "x": -37,
      "y": 21,
      "z": 22,
      "name": "Rock_Basalt_Brick_Half",
      "rotation": 4
    },
    {
      "x": -37,
      "y": 1,
      "z": 23,
      "name": "Wood_Deadwood_Planks",
      "rotation": 3
    },
    {
      "x": -37,
      "y": 2,
      "z": 23,
      "name": "Cloth_Roof_White_Flat"
    },
    {
      "x": -37,
      "y": 19,
      "z": 23,
      "name": "Rock_Stone",
      "rotation": 3
    },
    {
      "x": -37,
      "y": 20,
      "z": 23,
      "name": "Wood_Hardwood_Stairs"
    },
    {
      "x": -37,
      "y": 1,
      "z": 24,
      "name": "Rock_Stone_Brick_Smooth"
    },
    {
      "x": -37,
      "y": 19,
      "z": 24,
      "name": "Rock_Stone",
      "rotation": 3
    },
    {
      "x": -37,
      "y": 20,
      "z": 24,
      "name": "Wood_Hardwood_Planks",
      "rotation": 3
    },
    {
      "x": -37,
      "y": 1,
      "z": 25,
      "name": "Rock_Stone_Brick_Half"
    },
    {
      "x": -37,
      "y": 19,
      "z": 25,
      "name": "Rock_Stone",
      "rotation": 3
    },
    {
      "x": -37,
      "y": 20,
      "z": 25,
      "name": "Wood_Hardwood_Planks",
      "rotation": 3
    },
    {
      "x": -37,
      "y": 1,
      "z": 26,
      "name": "Rock_Stone_Brick_Half"
    },
    {
      "x": -37,
      "y": 12,
      "z": 26,
      "name": "Wood_Darkwood_Planks_Half",
      "rotation": 11
    },
    {
      "x": -37,
      "y": 14,
      "z": 26,
      "name": "Wood_Darkwood_Planks_Half",
      "rotation": 3
    },
    {
      "x": -37,
      "y": 15,
      "z": 26,
      "name": "Wood_Darkwood_Planks_Half",
      "rotation": 11
    },
    {
      "x": -37,
      "y": 17,
      "z": 26,
      "name": "Wood_Darkwood_Planks_Half",
      "rotation": 3
    },
    {
      "x": -37,
      "y": 19,
      "z": 26,
      "name": "Rock_Stone",
      "rotation": 3
    },
    {
      "x": -37,
      "y": 20,
      "z": 26,
      "name": "Wood_Hardwood_Planks",
      "rotation": 3
    },
    {
      "x": -37,
      "y": 0,
      "z": 27,
      "name": "Rock_Stone_Brick_Half",
      "rotation": 8
    },
    {
      "x": -37,
      "y": 19,
      "z": 27,
      "name": "Soil_Clay_Grey",
      "rotation": 3
    },
    {
      "x": -37,
      "y": 20,
      "z": 27,
      "name": "Wood_Hardwood_Planks",
      "rotation": 3
    },
    {
      "x": -37,
      "y": 0,
      "z": 28,
      "name": "Rock_Stone_Brick_Half",
      "rotation": 8
    },
    {
      "x": -37,
      "y": 19,
      "z": 28,
      "name": "Rock_Stone_Brick_Smooth",
      "rotation": 3
    },
    {
      "x": -37,
      "y": 20,
      "z": 28,
      "name": "Wood_Hardwood_Planks",
      "rotation": 3
    },
    {
      "x": -37,
      "y": 0,
      "z": 29,
      "name": "Rock_Stone_Brick_Half"
    },
    {
      "x": -37,
      "y": 19,
      "z": 29,
      "name": "Rock_Stone",
      "rotation": 3
    },
    {
      "x": -37,
      "y": 20,
      "z": 29,
      "name": "Wood_Hardwood_Planks",
      "rotation": 3
    },
    {
      "x": -37,
      "y": 0,
      "z": 30,
      "name": "Rock_Stone_Brick_Half"
    },
    {
      "x": -37,
      "y": 19,
      "z": 30,
      "name": "Rock_Stone",
      "rotation": 3
    },
    {
      "x": -37,
      "y": 20,
      "z": 30,
      "name": "Wood_Hardwood_Planks",
      "rotation": 3
    },
    {
      "x": -37,
      "y": 19,
      "z": 31,
      "name": "Soil_Clay_Grey",
      "rotation": 3
    },
    {
      "x": -37,
      "y": 20,
      "z": 31,
      "name": "Wood_Hardwood_Stairs"
    },
    {
      "x": -37,
      "y": 19,
      "z": 32,
      "name": "Soil_Clay_Grey",
      "rotation": 3
    },
    {
      "x": -37,
      "y": 20,
      "z": 32,
      "name": "Wood_Hardwood_Planks",
      "rotation": 3
    },
    {
      "x": -37,
      "y": 21,
      "z": 32,
      "name": "Rock_Basalt_Brick_Half",
      "rotation": 6
    },
    {
      "x": -37,
      "y": 19,
      "z": 33,
      "name": "Rock_Stone_Brick_Smooth",
      "rotation": 3
    },
    {
      "x": -37,
      "y": 20,
      "z": 33,
      "name": "Rock_Stone_Brick_Smooth",
      "rotation": 3
    },
    {
      "x": -37,
      "y": 21,
      "z": 33,
      "name": "Rock_Stone_Brick_Smooth",
      "rotation": 3
    },
    {
      "x": -37,
      "y": 25,
      "z": 33,
      "name": "Rock_Stone_Brick_Half",
      "rotation": 11
    },
    {
      "x": -37,
      "y": 20,
      "z": 34,
      "name": "Rock_Stone_Brick_Smooth_Half",
      "rotation": 11
    },
    {
      "x": -37,
      "y": 21,
      "z": 34,
      "name": "Rock_Stone_Brick_Smooth_Half",
      "rotation": 11
    },
    {
      "x": -36,
      "y": 1,
      "z": -40,
      "name": "Wood_Blackwood_Planks",
      "rotation": 3
    },
    {
      "x": -36,
      "y": 2,
      "z": -40,
      "name": "Cloth_Roof_White_Flat"
    },
    {
      "x": -36,
      "y": 1,
      "z": -39,
      "name": "Wood_Deadwood_Planks",
      "rotation": 3
    },
    {
      "x": -36,
      "y": 2,
      "z": -39,
      "name": "Cloth_Roof_Red_Flat"
    },
    {
      "x": -36,
      "y": 1,
      "z": -38,
      "name": "Wood_Deadwood_Planks",
      "rotation": 3
    },
    {
      "x": -36,
      "y": 2,
      "z": -38,
      "name": "Cloth_Roof_Red_Flat"
    },
    {
      "x": -36,
      "y": 1,
      "z": -37,
      "name": "Wood_Deadwood_Planks",
      "rotation": 3
    },
    {
      "x": -36,
      "y": 2,
      "z": -37,
      "name": "Cloth_Roof_Red_Flat"
    },
    {
      "x": -36,
      "y": 1,
      "z": -36,
      "name": "Wood_Blackwood_Planks",
      "rotation": 3
    },
    {
      "x": -36,
      "y": 2,
      "z": -36,
      "name": "Cloth_Roof_Red_Flat"
    },
    {
      "x": -36,
      "y": 1,
      "z": -35,
      "name": "Wood_Deadwood_Planks",
      "rotation": 3
    },
    {
      "x": -36,
      "y": 2,
      "z": -35,
      "name": "Cloth_Roof_Red_Flat"
    },
    {
      "x": -36,
      "y": 1,
      "z": -34,
      "name": "Wood_Deadwood_Planks",
      "rotation": 3
    },
    {
      "x": -36,
      "y": 2,
      "z": -34,
      "name": "Cloth_Roof_Red_Flat"
    },
    {
      "x": -36,
      "y": 1,
      "z": -33,
      "name": "Wood_Deadwood_Planks",
      "rotation": 3
    },
    {
      "x": -36,
      "y": 2,
      "z": -33,
      "name": "Cloth_Roof_Red_Flat"
    },
    {
      "x": -36,
      "y": 1,
      "z": -32,
      "name": "Wood_Blackwood_Planks",
      "rotation": 3
    },
    {
      "x": -36,
      "y": 2,
      "z": -32,
      "name": "Cloth_Roof_Red_Flat"
    },
    {
      "x": -36,
      "y": 1,
      "z": -31,
      "name": "Wood_Deadwood_Planks",
      "rotation": 3
    },
    {
      "x": -36,
      "y": 2,
      "z": -31,
      "name": "Cloth_Roof_Red_Flat"
    },
    {
      "x": -36,
      "y": 1,
      "z": -30,
      "name": "Wood_Deadwood_Planks",
      "rotation": 3
    },
    {
      "x": -36,
      "y": 2,
      "z": -30,
      "name": "Cloth_Roof_Red_Flat"
    },
    {
      "x": -36,
      "y": 1,
      "z": -29,
      "name": "Wood_Deadwood_Planks",
      "rotation": 3
    },
    {
      "x": -36,
      "y": 2,
      "z": -29,
      "name": "Cloth_Roof_Red_Flat"
    },
    {
      "x": -36,
      "y": 1,
      "z": -28,
      "name": "Wood_Blackwood_Planks",
      "rotation": 3
    },
    {
      "x": -36,
      "y": 2,
      "z": -28,
      "name": "Cloth_Roof_Red_Flat"
    },
    {
      "x": -36,
      "y": 1,
      "z": -27,
      "name": "Wood_Deadwood_Planks",
      "rotation": 3
    },
    {
      "x": -36,
      "y": 2,
      "z": -27,
      "name": "Cloth_Roof_Red_Flat"
    },
    {
      "x": -36,
      "y": 1,
      "z": -26,
      "name": "Wood_Deadwood_Planks",
      "rotation": 3
    },
    {
      "x": -36,
      "y": 2,
      "z": -26,
      "name": "Cloth_Roof_Red_Flat"
    },
    {
      "x": -36,
      "y": 1,
      "z": -25,
      "name": "Wood_Deadwood_Planks",
      "rotation": 3
    },
    {
      "x": -36,
      "y": 2,
      "z": -25,
      "name": "Cloth_Roof_Red_Flat"
    },
    {
      "x": -36,
      "y": 1,
      "z": -24,
      "name": "Wood_Blackwood_Planks",
      "rotation": 3
    },
    {
      "x": -36,
      "y": 2,
      "z": -24,
      "name": "Cloth_Roof_Red_Flat"
    },
    {
      "x": -36,
      "y": 1,
      "z": -23,
      "name": "Wood_Deadwood_Planks",
      "rotation": 3
    },
    {
      "x": -36,
      "y": 2,
      "z": -23,
      "name": "Cloth_Roof_Red_Flat"
    },
    {
      "x": -36,
      "y": 1,
      "z": -22,
      "name": "Wood_Deadwood_Planks",
      "rotation": 3
    },
    {
      "x": -36,
      "y": 2,
      "z": -22,
      "name": "Cloth_Roof_Red_Flat"
    },
    {
      "x": -36,
      "y": 1,
      "z": -21,
      "name": "Wood_Deadwood_Planks",
      "rotation": 3
    },
    {
      "x": -36,
      "y": 2,
      "z": -21,
      "name": "Cloth_Roof_Red_Flat"
    },
    {
      "x": -36,
      "y": 1,
      "z": -20,
      "name": "Wood_Blackwood_Planks",
      "rotation": 3
    },
    {
      "x": -36,
      "y": 2,
      "z": -20,
      "name": "Cloth_Roof_Red_Flat"
    },
    {
      "x": -36,
      "y": 1,
      "z": -19,
      "name": "Wood_Deadwood_Planks",
      "rotation": 3
    },
    {
      "x": -36,
      "y": 2,
      "z": -19,
      "name": "Cloth_Roof_Red_Flat"
    },
    {
      "x": -36,
      "y": 1,
      "z": -18,
      "name": "Wood_Deadwood_Planks",
      "rotation": 3
    },
    {
      "x": -36,
      "y": 2,
      "z": -18,
      "name": "Cloth_Roof_Red_Flat"
    },
    {
      "x": -36,
      "y": 1,
      "z": -17,
      "name": "Wood_Deadwood_Planks",
      "rotation": 3
    },
    {
      "x": -36,
      "y": 2,
      "z": -17,
      "name": "Cloth_Roof_Red_Flat"
    },
    {
      "x": -36,
      "y": 1,
      "z": -16,
      "name": "Wood_Blackwood_Planks",
      "rotation": 3
    },
    {
      "x": -36,
      "y": 2,
      "z": -16,
      "name": "Cloth_Roof_Red_Flat"
    },
    {
      "x": -36,
      "y": 1,
      "z": -15,
      "name": "Wood_Deadwood_Planks",
      "rotation": 3
    },
    {
      "x": -36,
      "y": 2,
      "z": -15,
      "name": "Cloth_Roof_Red_Flat"
    },
    {
      "x": -36,
      "y": 1,
      "z": -14,
      "name": "Wood_Deadwood_Planks",
      "rotation": 3
    },
    {
      "x": -36,
      "y": 2,
      "z": -14,
      "name": "Cloth_Roof_Red_Flat"
    },
    {
      "x": -36,
      "y": 1,
      "z": -13,
      "name": "Wood_Deadwood_Planks",
      "rotation": 3
    },
    {
      "x": -36,
      "y": 2,
      "z": -13,
      "name": "Cloth_Roof_Red_Flat"
    },
    {
      "x": -36,
      "y": 1,
      "z": -12,
      "name": "Wood_Blackwood_Planks",
      "rotation": 3
    },
    {
      "x": -36,
      "y": 2,
      "z": -12,
      "name": "Cloth_Roof_Red_Flat"
    },
    {
      "x": -36,
      "y": 1,
      "z": -11,
      "name": "Wood_Deadwood_Planks",
      "rotation": 3
    },
    {
      "x": -36,
      "y": 2,
      "z": -11,
      "name": "Cloth_Roof_Red_Flat"
    },
    {
      "x": -36,
      "y": 1,
      "z": -10,
      "name": "Wood_Deadwood_Planks",
      "rotation": 3
    },
    {
      "x": -36,
      "y": 2,
      "z": -10,
      "name": "Cloth_Roof_Red_Flat"
    },
    {
      "x": -36,
      "y": 1,
      "z": -9,
      "name": "Wood_Deadwood_Planks",
      "rotation": 3
    },
    {
      "x": -36,
      "y": 2,
      "z": -9,
      "name": "Cloth_Roof_Red_Flat"
    },
    {
      "x": -36,
      "y": 1,
      "z": -8,
      "name": "Wood_Blackwood_Planks",
      "rotation": 3
    },
    {
      "x": -36,
      "y": 2,
      "z": -8,
      "name": "Cloth_Roof_Red_Flat"
    },
    {
      "x": -36,
      "y": 1,
      "z": -7,
      "name": "Wood_Deadwood_Planks",
      "rotation": 3
    },
    {
      "x": -36,
      "y": 2,
      "z": -7,
      "name": "Cloth_Roof_Red_Flat"
    },
    {
      "x": -36,
      "y": 1,
      "z": -6,
      "name": "Wood_Deadwood_Planks",
      "rotation": 3
    },
    {
      "x": -36,
      "y": 2,
      "z": -6,
      "name": "Cloth_Roof_Red_Flat"
    },
    {
      "x": -36,
      "y": 1,
      "z": -5,
      "name": "Wood_Deadwood_Planks",
      "rotation": 3
    },
    {
      "x": -36,
      "y": 2,
      "z": -5,
      "name": "Cloth_Roof_Red_Flat"
    },
    {
      "x": -36,
      "y": 1,
      "z": -4,
      "name": "Wood_Blackwood_Planks",
      "rotation": 3
    },
    {
      "x": -36,
      "y": 2,
      "z": -4,
      "name": "Cloth_Roof_Red_Flat"
    },
    {
      "x": -36,
      "y": 1,
      "z": -3,
      "name": "Wood_Deadwood_Planks",
      "rotation": 3
    },
    {
      "x": -36,
      "y": 2,
      "z": -3,
      "name": "Cloth_Roof_Red_Flat"
    },
    {
      "x": -36,
      "y": 1,
      "z": -2,
      "name": "Wood_Deadwood_Planks",
      "rotation": 3
    },
    {
      "x": -36,
      "y": 2,
      "z": -2,
      "name": "Cloth_Roof_Red_Flat"
    },
    {
      "x": -36,
      "y": 1,
      "z": -1,
      "name": "Wood_Deadwood_Planks",
      "rotation": 3
    },
    {
      "x": -36,
      "y": 2,
      "z": -1,
      "name": "Cloth_Roof_Red_Flat"
    },
    {
      "x": -36,
      "y": 1,
      "z": 0,
      "name": "Wood_Blackwood_Planks",
      "rotation": 3
    },
    {
      "x": -36,
      "y": 2,
      "z": 0,
      "name": "Cloth_Roof_Red_Flat"
    },
    {
      "x": -36,
      "y": 1,
      "z": 1,
      "name": "Wood_Deadwood_Planks",
      "rotation": 3
    },
    {
      "x": -36,
      "y": 2,
      "z": 1,
      "name": "Cloth_Roof_Red_Flat"
    },
    {
      "x": -36,
      "y": 1,
      "z": 2,
      "name": "Wood_Deadwood_Planks",
      "rotation": 3
    },
    {
      "x": -36,
      "y": 2,
      "z": 2,
      "name": "Cloth_Roof_Red_Flat"
    },
    {
      "x": -36,
      "y": 1,
      "z": 3,
      "name": "Wood_Deadwood_Planks",
      "rotation": 3
    },
    {
      "x": -36,
      "y": 2,
      "z": 3,
      "name": "Cloth_Roof_Red_Flat"
    },
    {
      "x": -36,
      "y": 1,
      "z": 4,
      "name": "Wood_Blackwood_Planks",
      "rotation": 3
    },
    {
      "x": -36,
      "y": 2,
      "z": 4,
      "name": "Cloth_Roof_Red_Flat"
    },
    {
      "x": -36,
      "y": 1,
      "z": 5,
      "name": "Wood_Deadwood_Planks",
      "rotation": 3
    },
    {
      "x": -36,
      "y": 2,
      "z": 5,
      "name": "Cloth_Roof_Red_Flat"
    },
    {
      "x": -36,
      "y": 1,
      "z": 6,
      "name": "Wood_Deadwood_Planks",
      "rotation": 3
    },
    {
      "x": -36,
      "y": 2,
      "z": 6,
      "name": "Cloth_Roof_Red_Flat"
    },
    {
      "x": -36,
      "y": 1,
      "z": 7,
      "name": "Wood_Deadwood_Planks",
      "rotation": 3
    },
    {
      "x": -36,
      "y": 2,
      "z": 7,
      "name": "Cloth_Roof_Red_Flat"
    },
    {
      "x": -36,
      "y": 1,
      "z": 8,
      "name": "Wood_Blackwood_Planks",
      "rotation": 3
    },
    {
      "x": -36,
      "y": 2,
      "z": 8,
      "name": "Cloth_Roof_Red_Flat"
    },
    {
      "x": -36,
      "y": 1,
      "z": 9,
      "name": "Wood_Deadwood_Planks",
      "rotation": 3
    },
    {
      "x": -36,
      "y": 2,
      "z": 9,
      "name": "Cloth_Roof_Red_Flat"
    },
    {
      "x": -36,
      "y": 1,
      "z": 10,
      "name": "Wood_Deadwood_Planks",
      "rotation": 3
    },
    {
      "x": -36,
      "y": 2,
      "z": 10,
      "name": "Cloth_Roof_Red_Flat"
    },
    {
      "x": -36,
      "y": 1,
      "z": 11,
      "name": "Wood_Deadwood_Planks",
      "rotation": 3
    },
    {
      "x": -36,
      "y": 2,
      "z": 11,
      "name": "Cloth_Roof_Red_Flat"
    },
    {
      "x": -36,
      "y": 1,
      "z": 12,
      "name": "Wood_Blackwood_Planks",
      "rotation": 3
    },
    {
      "x": -36,
      "y": 2,
      "z": 12,
      "name": "Cloth_Roof_Red_Flat"
    },
    {
      "x": -36,
      "y": 1,
      "z": 13,
      "name": "Wood_Deadwood_Planks",
      "rotation": 3
    },
    {
      "x": -36,
      "y": 2,
      "z": 13,
      "name": "Cloth_Roof_Red_Flat"
    },
    {
      "x": -36,
      "y": 1,
      "z": 14,
      "name": "Wood_Deadwood_Planks",
      "rotation": 3
    },
    {
      "x": -36,
      "y": 2,
      "z": 14,
      "name": "Cloth_Roof_Red_Flat"
    },
    {
      "x": -36,
      "y": 1,
      "z": 15,
      "name": "Wood_Deadwood_Planks",
      "rotation": 3
    },
    {
      "x": -36,
      "y": 2,
      "z": 15,
      "name": "Cloth_Roof_Red_Flat"
    },
    {
      "x": -36,
      "y": 1,
      "z": 16,
      "name": "Wood_Blackwood_Planks",
      "rotation": 3
    },
    {
      "x": -36,
      "y": 2,
      "z": 16,
      "name": "Cloth_Roof_Red_Flat"
    },
    {
      "x": -36,
      "y": 1,
      "z": 17,
      "name": "Wood_Deadwood_Planks",
      "rotation": 3
    },
    {
      "x": -36,
      "y": 2,
      "z": 17,
      "name": "Cloth_Roof_Red_Flat"
    },
    {
      "x": -36,
      "y": 1,
      "z": 18,
      "name": "Wood_Deadwood_Planks",
      "rotation": 3
    },
    {
      "x": -36,
      "y": 2,
      "z": 18,
      "name": "Cloth_Roof_Red_Flat"
    },
    {
      "x": -36,
      "y": 22,
      "z": 18,
      "name": "Rock_Basalt_Brick_Smooth_Half",
      "rotation": 11
    },
    {
      "x": -36,
      "y": 1,
      "z": 19,
      "name": "Wood_Deadwood_Planks",
      "rotation": 3
    },
    {
      "x": -36,
      "y": 2,
      "z": 19,
      "name": "Cloth_Roof_Red_Flat"
    },
    {
      "x": -36,
      "y": 22,
      "z": 19,
      "name": "Rock_Basalt_Brick_Smooth",
      "rotation": 3
    },
    {
      "x": -36,
      "y": 1,
      "z": 20,
      "name": "Wood_Blackwood_Planks",
      "rotation": 3
    },
    {
      "x": -36,
      "y": 2,
      "z": 20,
      "name": "Cloth_Roof_Red_Flat"
    },
    {
      "x": -36,
      "y": 20,
      "z": 20,
      "name": "Rock_Basalt_Brick_Smooth_Half",
      "rotation": 6
    },
    {
      "x": -36,
      "y": 21,
      "z": 20,
      "name": "Rock_Basalt_Brick_Smooth",
      "rotation": 3
    },
    {
      "x": -36,
      "y": 22,
      "z": 20,
      "name": "Rock_Basalt_Brick_Smooth",
      "rotation": 3
    },
    {
      "x": -36,
      "y": 23,
      "z": 20,
      "name": "Rock_Basalt_Brick_Smooth",
      "rotation": 3
    },
    {
      "x": -36,
      "y": 24,
      "z": 20,
      "name": "Rock_Basalt_Brick_Smooth",
      "rotation": 3
    },
    {
      "x": -36,
      "y": 25,
      "z": 20,
      "name": "Rock_Basalt_Brick_Smooth",
      "rotation": 3
    },
    {
      "x": -36,
      "y": 1,
      "z": 21,
      "name": "Wood_Deadwood_Planks",
      "rotation": 3
    },
    {
      "x": -36,
      "y": 2,
      "z": 21,
      "name": "Cloth_Roof_Red_Flat"
    },
    {
      "x": -36,
      "y": 19,
      "z": 21,
      "name": "Rock_Basalt_Brick_Smooth",
      "rotation": 3
    },
    {
      "x": -36,
      "y": 20,
      "z": 21,
      "name": "Rock_Stone_Brick_Smooth",
      "rotation": 3
    },
    {
      "x": -36,
      "y": 21,
      "z": 21,
      "name": "Rock_Stone_Brick_Smooth",
      "rotation": 3
    },
    {
      "x": -36,
      "y": 22,
      "z": 21,
      "name": "Rock_Stone_Brick",
      "rotation": 3
    },
    {
      "x": -36,
      "y": 23,
      "z": 21,
      "name": "Rock_Basalt_Brick_Smooth",
      "rotation": 3
    },
    {
      "x": -36,
      "y": 24,
      "z": 21,
      "name": "Rock_Basalt_Brick_Smooth",
      "rotation": 3
    },
    {
      "x": -36,
      "y": 25,
      "z": 21,
      "name": "Rock_Basalt_Brick_Smooth",
      "rotation": 3
    },
    {
      "x": -36,
      "y": 1,
      "z": 22,
      "name": "Wood_Deadwood_Planks",
      "rotation": 3
    },
    {
      "x": -36,
      "y": 2,
      "z": 22,
      "name": "Cloth_Roof_Red_Flat"
    },
    {
      "x": -36,
      "y": 19,
      "z": 22,
      "name": "Rock_Stone_Brick_Smooth",
      "rotation": 3
    },
    {
      "x": -36,
      "y": 20,
      "z": 22,
      "name": "Wood_Hardwood_Planks",
      "rotation": 3
    },
    {
      "x": -36,
      "y": 21,
      "z": 22,
      "name": "Rock_Basalt_Brick_Half",
      "rotation": 4
    },
    {
      "x": -36,
      "y": 1,
      "z": 23,
      "name": "Wood_Deadwood_Planks",
      "rotation": 3
    },
    {
      "x": -36,
      "y": 2,
      "z": 23,
      "name": "Cloth_Roof_White_Flat"
    },
    {
      "x": -36,
      "y": 19,
      "z": 23,
      "name": "Rock_Stone",
      "rotation": 3
    },
    {
      "x": -36,
      "y": 20,
      "z": 23,
      "name": "*Wood_Hardwood_Stairs_State_Definitions_Inverted_Corner_Right",
      "rotation": 1
    },
    {
      "x": -36,
      "y": 1,
      "z": 24,
      "name": "Rock_Stone_Brick_Smooth"
    },
    {
      "x": -36,
      "y": 19,
      "z": 24,
      "name": "Rock_Stone",
      "rotation": 3
    },
    {
      "x": -36,
      "y": 20,
      "z": 24,
      "name": "Wood_Hardwood_Stairs",
      "rotation": 1
    },
    {
      "x": -36,
      "y": 1,
      "z": 25,
      "name": "Rock_Stone_Brick_Half"
    },
    {
      "x": -36,
      "y": 19,
      "z": 25,
      "name": "Rock_Stone",
      "rotation": 3
    },
    {
      "x": -36,
      "y": 20,
      "z": 25,
      "name": "Wood_Hardwood_Stairs",
      "rotation": 1
    },
    {
      "x": -36,
      "y": 1,
      "z": 26,
      "name": "Rock_Stone_Brick_Half"
    },
    {
      "x": -36,
      "y": 11,
      "z": 26,
      "name": "Wood_Ash_Trunk",
      "support": 15,
      "rotation": 3
    },
    {
      "x": -36,
      "y": 12,
      "z": 26,
      "name": "Wood_Ash_Trunk_Full",
      "rotation": 1
    },
    {
      "x": -36,
      "y": 13,
      "z": 26,
      "name": "Wood_Ash_Trunk_Full",
      "rotation": 1
    },
    {
      "x": -36,
      "y": 14,
      "z": 26,
      "name": "Wood_Ash_Trunk_Full",
      "rotation": 1
    },
    {
      "x": -36,
      "y": 15,
      "z": 26,
      "name": "Wood_Ash_Trunk_Full",
      "rotation": 1
    },
    {
      "x": -36,
      "y": 16,
      "z": 26,
      "name": "Wood_Ash_Trunk_Full",
      "rotation": 1
    },
    {
      "x": -36,
      "y": 17,
      "z": 26,
      "name": "Wood_Ash_Trunk_Full",
      "rotation": 1
    },
    {
      "x": -36,
      "y": 18,
      "z": 26,
      "name": "Wood_Ash_Trunk_Full",
      "rotation": 1
    },
    {
      "x": -36,
      "y": 19,
      "z": 26,
      "name": "Rock_Stone",
      "rotation": 3
    },
    {
      "x": -36,
      "y": 20,
      "z": 26,
      "name": "Wood_Hardwood_Stairs",
      "rotation": 1
    },
    {
      "x": -36,
      "y": 0,
      "z": 27,
      "name": "Rock_Stone_Brick_Half",
      "rotation": 8
    },
    {
      "x": -36,
      "y": 19,
      "z": 27,
      "name": "Rock_Stone",
      "rotation": 3
    },
    {
      "x": -36,
      "y": 20,
      "z": 27,
      "name": "Wood_Hardwood_Stairs",
      "rotation": 1
    },
    {
      "x": -36,
      "y": 0,
      "z": 28,
      "name": "Rock_Stone_Brick_Half",
      "rotation": 8
    },
    {
      "x": -36,
      "y": 19,
      "z": 28,
      "name": "Rock_Stone_Brick_Smooth",
      "rotation": 3
    },
    {
      "x": -36,
      "y": 20,
      "z": 28,
      "name": "Wood_Hardwood_Planks",
      "rotation": 3
    },
    {
      "x": -36,
      "y": 0,
      "z": 29,
      "name": "Rock_Stone_Brick_Half"
    },
    {
      "x": -36,
      "y": 19,
      "z": 29,
      "name": "Rock_Stone",
      "rotation": 3
    },
    {
      "x": -36,
      "y": 20,
      "z": 29,
      "name": "Wood_Hardwood_Planks",
      "rotation": 3
    },
    {
      "x": -36,
      "y": 0,
      "z": 30,
      "name": "Rock_Stone_Brick_Half"
    },
    {
      "x": -36,
      "y": 19,
      "z": 30,
      "name": "Soil_Clay_Grey",
      "rotation": 3
    },
    {
      "x": -36,
      "y": 20,
      "z": 30,
      "name": "Wood_Hardwood_Stairs",
      "rotation": 1
    },
    {
      "x": -36,
      "y": 19,
      "z": 31,
      "name": "Soil_Clay_Grey",
      "rotation": 3
    },
    {
      "x": -36,
      "y": 20,
      "z": 31,
      "name": "*Wood_Hardwood_Stairs_State_Definitions_Inverted_Corner_Right",
      "rotation": 1
    },
    {
      "x": -36,
      "y": 19,
      "z": 32,
      "name": "Rock_Stone",
      "rotation": 3
    },
    {
      "x": -36,
      "y": 20,
      "z": 32,
      "name": "Wood_Hardwood_Planks",
      "rotation": 3
    },
    {
      "x": -36,
      "y": 21,
      "z": 32,
      "name": "Rock_Basalt_Brick_Half",
      "rotation": 6
    },
    {
      "x": -36,
      "y": 22,
      "z": 32,
      "name": "Rock_Basalt_Brick_Half",
      "rotation": 6
    },
    {
      "x": -36,
      "y": 19,
      "z": 33,
      "name": "Rock_Stone_Brick_Smooth",
      "rotation": 3
    },
    {
      "x": -36,
      "y": 20,
      "z": 33,
      "name": "Rock_Stone_Brick_Smooth",
      "rotation": 3
    },
    {
      "x": -36,
      "y": 21,
      "z": 33,
      "name": "Rock_Stone_Brick_Smooth",
      "rotation": 3
    },
    {
      "x": -36,
      "y": 22,
      "z": 33,
      "name": "Rock_Stone_Brick",
      "rotation": 3
    },
    {
      "x": -36,
      "y": 23,
      "z": 33,
      "name": "Rock_Stone_Brick_Beam",
      "rotation": 3
    },
    {
      "x": -36,
      "y": 24,
      "z": 33,
      "name": "Rock_Stone_Brick_Beam",
      "rotation": 3
    },
    {
      "x": -36,
      "y": 25,
      "z": 33,
      "name": "Rock_Stone_Brick_Beam",
      "rotation": 3
    },
    {
      "x": -36,
      "y": 20,
      "z": 34,
      "name": "*Rock_Stone_Brick_Smooth_Half_State_Definitions_Block",
      "rotation": 11
    },
    {
      "x": -36,
      "y": 21,
      "z": 34,
      "name": "Rock_Stone_Brick_Smooth_Half",
      "rotation": 11
    },
    {
      "x": -35,
      "y": 1,
      "z": -40,
      "name": "Wood_Blackwood_Planks",
      "rotation": 3
    },
    {
      "x": -35,
      "y": 2,
      "z": -40,
      "name": "Cloth_Roof_White_Flat"
    },
    {
      "x": -35,
      "y": 1,
      "z": -39,
      "name": "Wood_Deadwood_Planks",
      "rotation": 3
    },
    {
      "x": -35,
      "y": 2,
      "z": -39,
      "name": "Cloth_Roof_Red_Flat"
    },
    {
      "x": -35,
      "y": 1,
      "z": -38,
      "name": "Wood_Deadwood_Planks",
      "rotation": 3
    },
    {
      "x": -35,
      "y": 2,
      "z": -38,
      "name": "Cloth_Roof_Red_Flat"
    },
    {
      "x": -35,
      "y": 1,
      "z": -37,
      "name": "Wood_Deadwood_Planks",
      "rotation": 3
    },
    {
      "x": -35,
      "y": 2,
      "z": -37,
      "name": "Cloth_Roof_Red_Flat"
    },
    {
      "x": -35,
      "y": 1,
      "z": -36,
      "name": "Wood_Blackwood_Planks",
      "rotation": 3
    },
    {
      "x": -35,
      "y": 2,
      "z": -36,
      "name": "Cloth_Roof_Red_Flat"
    },
    {
      "x": -35,
      "y": 1,
      "z": -35,
      "name": "Wood_Deadwood_Planks",
      "rotation": 3
    },
    {
      "x": -35,
      "y": 2,
      "z": -35,
      "name": "Cloth_Roof_Red_Flat"
    },
    {
      "x": -35,
      "y": 1,
      "z": -34,
      "name": "Wood_Deadwood_Planks",
      "rotation": 3
    },
    {
      "x": -35,
      "y": 2,
      "z": -34,
      "name": "Cloth_Roof_Red_Flat"
    },
    {
      "x": -35,
      "y": 1,
      "z": -33,
      "name": "Wood_Deadwood_Planks",
      "rotation": 3
    },
    {
      "x": -35,
      "y": 2,
      "z": -33,
      "name": "Cloth_Roof_Red_Flat"
    },
    {
      "x": -35,
      "y": 1,
      "z": -32,
      "name": "Wood_Blackwood_Planks",
      "rotation": 3
    },
    {
      "x": -35,
      "y": 2,
      "z": -32,
      "name": "Cloth_Roof_Red_Flat"
    },
    {
      "x": -35,
      "y": 1,
      "z": -31,
      "name": "Wood_Deadwood_Planks",
      "rotation": 3
    },
    {
      "x": -35,
      "y": 2,
      "z": -31,
      "name": "Cloth_Roof_Red_Flat"
    },
    {
      "x": -35,
      "y": 1,
      "z": -30,
      "name": "Wood_Deadwood_Planks",
      "rotation": 3
    },
    {
      "x": -35,
      "y": 2,
      "z": -30,
      "name": "Cloth_Roof_Red_Flat"
    },
    {
      "x": -35,
      "y": 3,
      "z": -30,
      "name": "Plant_Leaves_Oak",
      "support": 15
    },
    {
      "x": -35,
      "y": 1,
      "z": -29,
      "name": "Soil_Dirt_Burnt"
    },
    {
      "x": -35,
      "y": 2,
      "z": -29,
      "name": "Plant_Moss_Green_Dark",
      "support": 15
    },
    {
      "x": -35,
      "y": 1,
      "z": -28,
      "name": "Soil_Dirt_Burnt"
    },
    {
      "x": -35,
      "y": 1,
      "z": -27,
      "name": "Wood_Deadwood_Planks",
      "rotation": 3
    },
    {
      "x": -35,
      "y": 2,
      "z": -27,
      "name": "Plant_Moss_Rug_Green_Dark",
      "support": 15
    },
    {
      "x": -35,
      "y": 1,
      "z": -26,
      "name": "Soil_Dirt_Burnt"
    },
    {
      "x": -35,
      "y": 2,
      "z": -26,
      "name": "Plant_Moss_Rug_Green_Dark",
      "support": 15
    },
    {
      "x": -35,
      "y": 1,
      "z": -25,
      "name": "Wood_Deadwood_Planks",
      "rotation": 3
    },
    {
      "x": -35,
      "y": 2,
      "z": -25,
      "name": "Cloth_Roof_Red_Flat"
    },
    {
      "x": -35,
      "y": 1,
      "z": -24,
      "name": "Wood_Blackwood_Planks",
      "rotation": 3
    },
    {
      "x": -35,
      "y": 2,
      "z": -24,
      "name": "Cloth_Roof_Red_Flat"
    },
    {
      "x": -35,
      "y": 1,
      "z": -23,
      "name": "Wood_Deadwood_Planks",
      "rotation": 3
    },
    {
      "x": -35,
      "y": 2,
      "z": -23,
      "name": "Cloth_Roof_Red_Flat"
    },
    {
      "x": -35,
      "y": 1,
      "z": -22,
      "name": "Wood_Deadwood_Planks",
      "rotation": 3
    },
    {
      "x": -35,
      "y": 2,
      "z": -22,
      "name": "Cloth_Roof_Red_Flat"
    },
    {
      "x": -35,
      "y": 1,
      "z": -21,
      "name": "Wood_Deadwood_Planks",
      "rotation": 3
    },
    {
      "x": -35,
      "y": 2,
      "z": -21,
      "name": "Cloth_Roof_Red_Flat"
    },
    {
      "x": -35,
      "y": 1,
      "z": -20,
      "name": "Wood_Blackwood_Planks",
      "rotation": 3
    },
    {
      "x": -35,
      "y": 2,
      "z": -20,
      "name": "Cloth_Roof_Red_Flat"
    },
    {
      "x": -35,
      "y": 1,
      "z": -19,
      "name": "Wood_Deadwood_Planks",
      "rotation": 3
    },
    {
      "x": -35,
      "y": 2,
      "z": -19,
      "name": "Cloth_Roof_Red_Flat"
    },
    {
      "x": -35,
      "y": 1,
      "z": -18,
      "name": "Wood_Deadwood_Planks",
      "rotation": 3
    },
    {
      "x": -35,
      "y": 2,
      "z": -18,
      "name": "Cloth_Roof_Red_Flat"
    },
    {
      "x": -35,
      "y": 1,
      "z": -17,
      "name": "Wood_Deadwood_Planks",
      "rotation": 3
    },
    {
      "x": -35,
      "y": 2,
      "z": -17,
      "name": "Cloth_Roof_Red_Flat"
    },
    {
      "x": -35,
      "y": 1,
      "z": -16,
      "name": "Wood_Blackwood_Planks",
      "rotation": 3
    },
    {
      "x": -35,
      "y": 2,
      "z": -16,
      "name": "Cloth_Roof_Red_Flat"
    },
    {
      "x": -35,
      "y": 1,
      "z": -15,
      "name": "Wood_Deadwood_Planks",
      "rotation": 3
    },
    {
      "x": -35,
      "y": 2,
      "z": -15,
      "name": "Cloth_Roof_Red_Flat"
    },
    {
      "x": -35,
      "y": 1,
      "z": -14,
      "name": "Wood_Deadwood_Planks",
      "rotation": 3
    },
    {
      "x": -35,
      "y": 2,
      "z": -14,
      "name": "Cloth_Roof_Red_Flat"
    },
    {
      "x": -35,
      "y": 1,
      "z": -13,
      "name": "Wood_Deadwood_Planks",
      "rotation": 3
    },
    {
      "x": -35,
      "y": 2,
      "z": -13,
      "name": "Cloth_Roof_Red_Flat"
    },
    {
      "x": -35,
      "y": 1,
      "z": -12,
      "name": "Wood_Blackwood_Planks",
      "rotation": 3
    },
    {
      "x": -35,
      "y": 2,
      "z": -12,
      "name": "Cloth_Roof_Red_Flat"
    },
    {
      "x": -35,
      "y": 1,
      "z": -11,
      "name": "Wood_Deadwood_Planks",
      "rotation": 3
    },
    {
      "x": -35,
      "y": 2,
      "z": -11,
      "name": "Cloth_Roof_Red_Flat"
    },
    {
      "x": -35,
      "y": 1,
      "z": -10,
      "name": "Wood_Deadwood_Planks",
      "rotation": 3
    },
    {
      "x": -35,
      "y": 2,
      "z": -10,
      "name": "Cloth_Roof_Red_Flat"
    },
    {
      "x": -35,
      "y": 1,
      "z": -9,
      "name": "Wood_Deadwood_Planks",
      "rotation": 3
    },
    {
      "x": -35,
      "y": 2,
      "z": -9,
      "name": "Cloth_Roof_Red_Flat"
    },
    {
      "x": -35,
      "y": 1,
      "z": -8,
      "name": "Wood_Blackwood_Planks",
      "rotation": 3
    },
    {
      "x": -35,
      "y": 2,
      "z": -8,
      "name": "Cloth_Roof_Red_Flat"
    },
    {
      "x": -35,
      "y": 1,
      "z": -7,
      "name": "Wood_Deadwood_Planks",
      "rotation": 3
    },
    {
      "x": -35,
      "y": 2,
      "z": -7,
      "name": "Cloth_Roof_Red_Flat"
    },
    {
      "x": -35,
      "y": 1,
      "z": -6,
      "name": "Wood_Deadwood_Planks",
      "rotation": 3
    },
    {
      "x": -35,
      "y": 2,
      "z": -6,
      "name": "Cloth_Roof_Red_Flat"
    },
    {
      "x": -35,
      "y": 1,
      "z": -5,
      "name": "Wood_Deadwood_Planks",
      "rotation": 3
    },
    {
      "x": -35,
      "y": 2,
      "z": -5,
      "name": "Cloth_Roof_Red_Flat"
    },
    {
      "x": -35,
      "y": 1,
      "z": -4,
      "name": "Wood_Blackwood_Planks",
      "rotation": 3
    },
    {
      "x": -35,
      "y": 2,
      "z": -4,
      "name": "Cloth_Roof_Red_Flat"
    },
    {
      "x": -35,
      "y": 1,
      "z": -3,
      "name": "Wood_Deadwood_Planks",
      "rotation": 3
    },
    {
      "x": -35,
      "y": 2,
      "z": -3,
      "name": "Cloth_Roof_Red_Flat"
    },
    {
      "x": -35,
      "y": 1,
      "z": -2,
      "name": "Wood_Deadwood_Planks",
      "rotation": 3
    },
    {
      "x": -35,
      "y": 2,
      "z": -2,
      "name": "Cloth_Roof_Red_Flat"
    },
    {
      "x": -35,
      "y": 1,
      "z": -1,
      "name": "Wood_Deadwood_Planks",
      "rotation": 3
    },
    {
      "x": -35,
      "y": 2,
      "z": -1,
      "name": "Cloth_Roof_Red_Flat"
    },
    {
      "x": -35,
      "y": 1,
      "z": 0,
      "name": "Wood_Blackwood_Planks",
      "rotation": 3
    },
    {
      "x": -35,
      "y": 2,
      "z": 0,
      "name": "Cloth_Roof_Red_Flat"
    },
    {
      "x": -35,
      "y": 1,
      "z": 1,
      "name": "Wood_Deadwood_Planks",
      "rotation": 3
    },
    {
      "x": -35,
      "y": 2,
      "z": 1,
      "name": "Cloth_Roof_Red_Flat"
    },
    {
      "x": -35,
      "y": 1,
      "z": 2,
      "name": "Wood_Deadwood_Planks",
      "rotation": 3
    },
    {
      "x": -35,
      "y": 2,
      "z": 2,
      "name": "Cloth_Roof_Red_Flat"
    },
    {
      "x": -35,
      "y": 1,
      "z": 3,
      "name": "Wood_Deadwood_Planks",
      "rotation": 3
    },
    {
      "x": -35,
      "y": 2,
      "z": 3,
      "name": "Cloth_Roof_Red_Flat"
    },
    {
      "x": -35,
      "y": 1,
      "z": 4,
      "name": "Wood_Blackwood_Planks",
      "rotation": 3
    },
    {
      "x": -35,
      "y": 2,
      "z": 4,
      "name": "Cloth_Roof_Red_Flat"
    },
    {
      "x": -35,
      "y": 1,
      "z": 5,
      "name": "Wood_Deadwood_Planks",
      "rotation": 3
    },
    {
      "x": -35,
      "y": 2,
      "z": 5,
      "name": "Cloth_Roof_Red_Flat"
    },
    {
      "x": -35,
      "y": 1,
      "z": 6,
      "name": "Wood_Deadwood_Planks",
      "rotation": 3
    },
    {
      "x": -35,
      "y": 2,
      "z": 6,
      "name": "Cloth_Roof_Red_Flat"
    },
    {
      "x": -35,
      "y": 1,
      "z": 7,
      "name": "Wood_Deadwood_Planks",
      "rotation": 3
    },
    {
      "x": -35,
      "y": 2,
      "z": 7,
      "name": "Cloth_Roof_Red_Flat"
    },
    {
      "x": -35,
      "y": 1,
      "z": 8,
      "name": "Wood_Blackwood_Planks",
      "rotation": 3
    },
    {
      "x": -35,
      "y": 2,
      "z": 8,
      "name": "Cloth_Roof_Red_Flat"
    },
    {
      "x": -35,
      "y": 1,
      "z": 9,
      "name": "Wood_Deadwood_Planks",
      "rotation": 3
    },
    {
      "x": -35,
      "y": 2,
      "z": 9,
      "name": "Cloth_Roof_Red_Flat"
    },
    {
      "x": -35,
      "y": 1,
      "z": 10,
      "name": "Wood_Deadwood_Planks",
      "rotation": 3
    },
    {
      "x": -35,
      "y": 2,
      "z": 10,
      "name": "Cloth_Roof_Red_Flat"
    },
    {
      "x": -35,
      "y": 1,
      "z": 11,
      "name": "Wood_Deadwood_Planks",
      "rotation": 3
    },
    {
      "x": -35,
      "y": 2,
      "z": 11,
      "name": "Cloth_Roof_Red_Flat"
    },
    {
      "x": -35,
      "y": 1,
      "z": 12,
      "name": "Wood_Blackwood_Planks",
      "rotation": 3
    },
    {
      "x": -35,
      "y": 2,
      "z": 12,
      "name": "Cloth_Roof_Red_Flat"
    },
    {
      "x": -35,
      "y": 1,
      "z": 13,
      "name": "Wood_Deadwood_Planks",
      "rotation": 3
    },
    {
      "x": -35,
      "y": 2,
      "z": 13,
      "name": "Cloth_Roof_Red_Flat"
    },
    {
      "x": -35,
      "y": 1,
      "z": 14,
      "name": "Wood_Deadwood_Planks",
      "rotation": 3
    },
    {
      "x": -35,
      "y": 2,
      "z": 14,
      "name": "Cloth_Roof_Red_Flat"
    },
    {
      "x": -35,
      "y": 1,
      "z": 15,
      "name": "Wood_Deadwood_Planks",
      "rotation": 3
    },
    {
      "x": -35,
      "y": 2,
      "z": 15,
      "name": "Cloth_Roof_Red_Flat"
    },
    {
      "x": -35,
      "y": 1,
      "z": 16,
      "name": "Wood_Blackwood_Planks",
      "rotation": 3
    },
    {
      "x": -35,
      "y": 2,
      "z": 16,
      "name": "Cloth_Roof_Red_Flat"
    },
    {
      "x": -35,
      "y": 1,
      "z": 17,
      "name": "Wood_Deadwood_Planks",
      "rotation": 3
    },
    {
      "x": -35,
      "y": 2,
      "z": 17,
      "name": "Cloth_Roof_Red_Flat"
    },
    {
      "x": -35,
      "y": 1,
      "z": 18,
      "name": "Wood_Deadwood_Planks",
      "rotation": 3
    },
    {
      "x": -35,
      "y": 2,
      "z": 18,
      "name": "Cloth_Roof_Red_Flat"
    },
    {
      "x": -35,
      "y": 22,
      "z": 18,
      "name": "Rock_Basalt_Brick_Smooth_Half",
      "rotation": 11
    },
    {
      "x": -35,
      "y": 1,
      "z": 19,
      "name": "Wood_Deadwood_Planks",
      "rotation": 3
    },
    {
      "x": -35,
      "y": 2,
      "z": 19,
      "name": "Cloth_Roof_Red_Flat"
    },
    {
      "x": -35,
      "y": 22,
      "z": 19,
      "name": "Rock_Basalt_Brick_Smooth",
      "rotation": 3
    },
    {
      "x": -35,
      "y": 1,
      "z": 20,
      "name": "Wood_Blackwood_Planks",
      "rotation": 3
    },
    {
      "x": -35,
      "y": 2,
      "z": 20,
      "name": "Cloth_Roof_Red_Flat"
    },
    {
      "x": -35,
      "y": 20,
      "z": 20,
      "name": "Rock_Basalt_Brick_Smooth_Half",
      "rotation": 6
    },
    {
      "x": -35,
      "y": 21,
      "z": 20,
      "name": "Rock_Basalt_Brick_Smooth",
      "rotation": 3
    },
    {
      "x": -35,
      "y": 22,
      "z": 20,
      "name": "Rock_Basalt_Brick_Smooth",
      "rotation": 3
    },
    {
      "x": -35,
      "y": 1,
      "z": 21,
      "name": "Wood_Deadwood_Planks",
      "rotation": 3
    },
    {
      "x": -35,
      "y": 2,
      "z": 21,
      "name": "Cloth_Roof_Red_Flat"
